Workbook
Name Estratégias: [1]Estratégias!$A$2:$A$5
Name Estratégias: [1]Estratégias!$A$2:$A$5
Name Estratégias: [1]Estratégias!$A$2:$A$5
Name Estratégias: [1]Estratégias!$A$2:$A$5
Name Estratégias: 'Estratégias (legenda)'!$A$2:$A$5
Name EstrategiasOport: [1]Estratégias!$D$2:$D$5
Name EstrategiasOport: [1]Estratégias!$D$2:$D$5
Name EstrategiasOport: [1]Estratégias!$D$2:$D$5
Name EstrategiasOport: [1]Estratégias!$D$2:$D$5
Name EstrategiasOport: 'Estratégias (legenda)'!$D$2:$D$5

Sheet Riscos-CANTU
E1: Matriz de Avaliação e Gestão de Riscos
E4: CANTU
B6: Item | C6: Riscos | E6: Avaliação de Impacto | W6: Avaliação do Controle (Probabilidade) | AS6: Significância | AU6: Estratégia
B7: Item | E7: Financeiro | F7: Pontos | G7: Inf. Média | H7: Legal | I7: Pontos | J7: Inf. Média | K7: Imagem | L7: Pontos | M7: Inf. Média | N7: Direcionamento Estratégico | O7: Pontos | P7: Inf. Média | Q7: Operação | R7: Pontos | S7: Inf. Média | W7: Características | AA7: Pontos | AC7: Tipo | AF7: Pontos | AH7: Histórico de Ocorrência | AN7: Pontos
U8: Impacto | W8: Controle-chave efetivo | X8: Controle Compensatório efetivo | Y8: Controle compensatório Não Efetivo | Z8: Controle Inexistente | AC8: Automatizado | AD8: Manual | AE8: Nenhum | AH8: Anual | AI8: Trimestral | AJ8: Mensal | AK8: Semanal | AL8: Diário | AM8: Mais de uma vez ao dia | AP8: Probabilidade | AQ8: Média | AX8: Desprezível | AY8: Administrável | AZ8: Indesejável | BA8: Intolerável
B10: 1. | C10: Comercial - Vacância | E10: Alto | F10: =IF(E10="N.A.",0)+IF(E10="Baixo",1)+IF(E10="Moderado",2)+IF(E10="Significativo",4)+IF(E10="Alto",6) -> 6 | G10: =IF(F10>0,1,0) -> 1 | H10: Baixo | I10: =IF(H10="N.A.",0)+IF(H10="Baixo",1)+IF(H10="Moderado",2)+IF(H10="Significativo",4)+IF(H10="Alto",6) -> 1 | J10: =IF(I10>0,1,0) -> 1 | K10: Baixo | L10: =IF(K10="N.A.",0)+IF(K10="Baixo",1)+IF(K10="Moderado",2)+IF(K10="Significativo",4)+IF(K10="Alto",6) -> 1 | M10: =IF(L10>0,1,0) -> 1 | N10: Significativo | O10: =IF(N10="N.A.",0)+IF(N10="Baixo",1)+IF(N10="Moderado",2)+IF(N10="Significativo",4)+IF(N10="Alto",6) -> 4 | P10: =IF(O10>0,1,0) -> 1 | Q10: Moderado | R10: =IF(Q10="N.A.",0)+IF(Q10="Baixo",1)+IF(Q10="Moderado",2)+IF(Q10="Significativo",4)+IF(Q10="Alto",6) -> 2 | S10: =IF(R10>0,1,0) -> 1 | T10: =SUM(G10,J10,M10,P10,S10) -> 5 | U10: =IFERROR(SUM(F10,I10,L10,O10,R10)/T10,0) -> 2.8 | Y10: X | AA10: =IF(W10="X",-1)+IF(X10="X",2)+IF(Y10="X",4)+IF(Z10="X",9) -> 4 | AD10: X | AF10: =IF(AC10="X",1)+IF(AD10="X",2)+IF(AE10="X",5) -> 2 | AJ10: X | AN10: =IF(AH10="X",1)+IF(AI10="X",2)+IF(AJ10="X",3)+IF(AK10="X",4)+IF(AL10="X",5)+IF(AM10="X",6) -> 3 | AP10: =AA10+AF10+AN10 -> 9 | AQ10: =(AP10+U10)/2 -> 5.9 | AR10: =IF(AS10="",0,10) -> 10 | AS10: =IF(AX10=TRUE,"Desprezível",IF(AY10=TRUE,"Administrável",IF(AZ10=TRUE,"Indesejável",IF(BA10=TRUE,"Intolerável","")))) -> Administrável | AU10: Mitigar | AW10: N.A. | AX10: =AND(U10>0,U10<=2,AP10>0,AP10<=7) -> FALSE | AY10: =OR(AND(U10>0,U10<=2,AP10>0,AP10>7,AP10<=13),AND(U10>0,U10>2,U10<=3,AP10>0,AP10<=10)) -> TRUE | AZ10: =OR(AND(U10>0,U10<=2,AP10>0,AP10>12,AP10<=17),AND(U10>0,U10>2,U10<=3,AP10>0,AP10>10,AP10<=13),AND(U10>0,U10>3,U10<=5,AP10>0,AP10<=10),AND(U10>0,U10>4,U10<=6,AP10>0,AP10<=7)) -> FALSE | BA10: =OR(AND(U10>0,U10>2,U10<=3,AP10>0,AP10>14,AP10<=20),AND(U10>0,U10>3,U10<=5,AP10>0,AP10>10),AND(U10>0,U10>5,U10<=6,AP10>0,AP10>7,AP10<=20)) -> FALSE | BC10: N.A.
I11: =IF(H11="N.A.",0)+IF(H11="Baixo",1)+IF(H11="Moderado",2)+IF(H11="Significativo",4)+IF(H11="Alto",6) -> 0 | J11: =IF(I11>0,1,0) -> 0 | L11: =IF(K11="N.A.",0)+IF(K11="Baixo",1)+IF(K11="Moderado",2)+IF(K11="Significativo",4)+IF(K11="Alto",6) -> 0 | R11: =IF(Q11="N.A.",0)+IF(Q11="Baixo",1)+IF(Q11="Moderado",2)+IF(Q11="Significativo",4)+IF(Q11="Alto",6) -> 0 | S11: =IF(R11>0,1,0) -> 0 | T11: =SUM(G11,J11,M11,P11,S11) -> 0 | U11: =IFERROR(SUM(F11,I11,L11,O11,R11)/T11,0) -> 0 | AF11: =IF(AC11="X",1)+IF(AD11="X",2)+IF(AE11="X",5) -> 0 | AW11: Baixo | AZ11: =OR(AND(U11>0,U11<=2,AP11>0,AP11>12,AP11<=17),AND(U11>0,U11>2,U11<=3,AP11>0,AP11>10,AP11<=13),AND(U11>0,U11>3,U11<=5,AP11>0,AP11<=10),AND(U11>0,U11>4,U11<=6,AP11>0,AP11<=7)) -> FALSE | BA11: =OR(AND(U11>0,U11>2,U11<=3,AP11>0,AP11>14,AP11<=20),AND(U11>0,U11>3,U11<=5,AP11>0,AP11>10),AND(U11>0,U11>5,U11<=6,AP11>0,AP11>7,AP11<=20)) -> FALSE | BC11: Baixo
B12: 2. | C12: Eventos de Sinistros em Imóveis | E12: Significativo | F12: =IF(E12="N.A.",0)+IF(E12="Baixo",1)+IF(E12="Moderado",2)+IF(E12="Significativo",4)+IF(E12="Alto",6) -> 4 | G12: =IF(F12>0,1,0) -> 1 | H12: Moderado | I12: =IF(H12="N.A.",0)+IF(H12="Baixo",1)+IF(H12="Moderado",2)+IF(H12="Significativo",4)+IF(H12="Alto",6) -> 2 | J12: =IF(I12>0,1,0) -> 1 | K12: Baixo | L12: =IF(K12="N.A.",0)+IF(K12="Baixo",1)+IF(K12="Moderado",2)+IF(K12="Significativo",4)+IF(K12="Alto",6) -> 1 | M12: =IF(L12>0,1,0) -> 1 | N12: Significativo | O12: =IF(N12="N.A.",0)+IF(N12="Baixo",1)+IF(N12="Moderado",2)+IF(N12="Significativo",4)+IF(N12="Alto",6) -> 4 | P12: =IF(O12>0,1,0) -> 1 | Q12: Significativo | R12: =IF(Q12="N.A.",0)+IF(Q12="Baixo",1)+IF(Q12="Moderado",2)+IF(Q12="Significativo",4)+IF(Q12="Alto",6) -> 4 | S12: =IF(R12>0,1,0) -> 1 | T12: =SUM(G12,J12,M12,P12,S12) -> 5 | U12: =IFERROR(SUM(F12,I12,L12,O12,R12)/T12,0) -> 3 | X12: X | AA12: =IF(W12="X",0)+IF(X12="X",2)+IF(Y12="X",4)+IF(Z12="X",9) -> 2 | AD12: X | AF12: =IF(AC12="X",1)+IF(AD12="X",2)+IF(AE12="X",5) -> 2 | AJ12: X | AN12: =IF(AH12="X",1)+IF(AI12="X",2)+IF(AJ12="X",3)+IF(AK12="X",4)+IF(AL12="X",5)+IF(AM12="X",6) -> 3 | AP12: =AA12+AF12+AN12 -> 7 | AQ12: =(AP12+U12)/2 -> 5 | AR12: =IF(AS12="",0,10) -> 10 | AS12: =IF(AX12=TRUE,"Desprezível",IF(AY12=TRUE,"Administrável",IF(AZ12=TRUE,"Indesejável",IF(BA12=TRUE,"Intolerável","")))) -> Administrável | AU12: Transferir | AW12: Alto | AX12: =AND(U12>0,U12<=2,AP12>0,AP12<=7) -> FALSE | AY12: =OR(AND(U12>0,U12<=2,AP12>0,AP12>7,AP12<=13),AND(U12>0,U12>2,U12<=3,AP12>0,AP12<=10)) -> TRUE | AZ12: =OR(AND(U12>0,U12<=2,AP12>0,AP12>12,AP12<=17),AND(U12>0,U12>2,U12<=3,AP12>0,AP12>10,AP12<=13),AND(U12>0,U12>3,U12<=5,AP12>0,AP12<=10),AND(U12>0,U12>4,U12<=6,AP12>0,AP12<=7)) -> FALSE | BA12: =OR(AND(U12>0,U12>2,U12<=3,AP12>0,AP12>14,AP12<=20),AND(U12>0,U12>3,U12<=5,AP12>0,AP12>10),AND(U12>0,U12>5,U12<=6,AP12>0,AP12>7,AP12<=20)) -> FALSE | BC12: Alto
F13: =IF(E13="N.A.",0)+IF(E13="Baixo",1)+IF(E13="Moderado",2)+IF(E13="Significativo",4)+IF(E13="Alto",6) -> 0 | G13: =IF(F13>0,1,0) -> 0 | I13: =IF(H13="N.A.",0)+IF(H13="Baixo",1)+IF(H13="Moderado",2)+IF(H13="Significativo",4)+IF(H13="Alto",6) -> 0 | J13: =IF(I13>0,1,0) -> 0 | L13: =IF(K13="N.A.",0)+IF(K13="Baixo",1)+IF(K13="Moderado",2)+IF(K13="Significativo",4)+IF(K13="Alto",6) -> 0 | M13: =IF(L13>0,1,0) -> 0 | O13: =IF(N13="N.A.",0)+IF(N13="Baixo",1)+IF(N13="Moderado",2)+IF(N13="Significativo",4)+IF(N13="Alto",6) -> 0 | P13: =IF(O13>0,1,0) -> 0 | R13: =IF(Q13="N.A.",0)+IF(Q13="Baixo",1)+IF(Q13="Moderado",2)+IF(Q13="Significativo",4)+IF(Q13="Alto",6) -> 0 | S13: =IF(R13>0,1,0) -> 0 | T13: =SUM(G13,J13,M13,P13,S13) -> 0 | U13: =IFERROR(SUM(F13,I13,L13,O13,R13)/T13,0) -> 0 | AA13: =IF(W13="X",0)+IF(X13="X",2)+IF(Y13="X",4)+IF(Z13="X",9) -> 0 | AF13: =IF(AC13="X",1)+IF(AD13="X",2)+IF(AE13="X",5) -> 0 | AZ13: =OR(AND(U13>0,U13<=2,AP13>0,AP13>12,AP13<=17),AND(U13>0,U13>2,U13<=3,AP13>0,AP13>10,AP13<=13),AND(U13>0,U13>3,U13<=5,AP13>0,AP13<=10),AND(U13>0,U13>4,U13<=6,AP13>0,AP13<=7)) -> FALSE | BA13: =OR(AND(U13>0,U13>2,U13<=3,AP13>0,AP13>14,AP13<=20),AND(U13>0,U13>3,U13<=5,AP13>0,AP13>10),AND(U13>0,U13>5,U13<=6,AP13>0,AP13>7,AP13<=20)) -> FALSE
B14: 3. | C14: Novos Negócios - Aquisição de Imóveis | E14: Alto | F14: =IF(E14="N.A.",0)+IF(E14="Baixo",1)+IF(E14="Moderado",2)+IF(E14="Significativo",4)+IF(E14="Alto",6) -> 6 | G14: =IF(F14>0,1,0) -> 1 | H14: Baixo | I14: =IF(H14="N.A.",0)+IF(H14="Baixo",1)+IF(H14="Moderado",2)+IF(H14="Significativo",4)+IF(H14="Alto",6) -> 1 | J14: =IF(I14>0,1,0) -> 1 | K14: Baixo | L14: =IF(K14="N.A.",0)+IF(K14="Baixo",1)+IF(K14="Moderado",2)+IF(K14="Significativo",4)+IF(K14="Alto",6) -> 1 | M14: =IF(L14>0,1,0) -> 1 | N14: Significativo | O14: =IF(N14="N.A.",0)+IF(N14="Baixo",1)+IF(N14="Moderado",2)+IF(N14="Significativo",4)+IF(N14="Alto",6) -> 4 | P14: =IF(O14>0,1,0) -> 1 | Q14: Moderado | R14: =IF(Q14="N.A.",0)+IF(Q14="Baixo",1)+IF(Q14="Moderado",2)+IF(Q14="Significativo",4)+IF(Q14="Alto",6) -> 2 | S14: =IF(R14>0,1,0) -> 1 | T14: =SUM(G14,J14,M14,P14,S14) -> 5 | U14: =IFERROR(SUM(F14,I14,L14,O14,R14)/T14,0) -> 2.8 | X14: X | AA14: =IF(W14="X",0)+IF(X14="X",2)+IF(Y14="X",4)+IF(Z14="X",9) -> 2 | AD14: X | AF14: =IF(AC14="X",1)+IF(AD14="X",2)+IF(AE14="X",5) -> 2 | AJ14: X | AN14: =IF(AH14="X",1)+IF(AI14="X",2)+IF(AJ14="X",3)+IF(AK14="X",4)+IF(AL14="X",5)+IF(AM14="X",6) -> 3 | AP14: =AA14+AF14+AN14 -> 7 | AQ14: =(AP14+U14)/2 -> 4.9 | AR14: =IF(AS14="",0,10) -> 10 | AS14: =IF(AX14=TRUE,"Desprezível",IF(AY14=TRUE,"Administrável",IF(AZ14=TRUE,"Indesejável",IF(BA14=TRUE,"Intolerável","")))) -> Administrável | AU14: Mitigar | AX14: =AND(U14>0,U14<=2,AP14>0,AP14<=7) -> FALSE | AY14: =OR(AND(U14>0,U14<=2,AP14>0,AP14>7,AP14<=13),AND(U14>0,U14>2,U14<=3,AP14>0,AP14<=10)) -> TRUE | AZ14: =OR(AND(U14>0,U14<=2,AP14>0,AP14>12,AP14<=17),AND(U14>0,U14>2,U14<=3,AP14>0,AP14>10,AP14<=13),AND(U14>0,U14>3,U14<=5,AP14>0,AP14<=10),AND(U14>0,U14>4,U14<=6,AP14>0,AP14<=7)) -> FALSE | BA14: =OR(AND(U14>0,U14>2,U14<=3,AP14>0,AP14>14,AP14<=20),AND(U14>0,U14>3,U14<=5,AP14>0,AP14>10),AND(U14>0,U14>5,U14<=6,AP14>0,AP14>7,AP14<=20)) -> FALSE
F15: =IF(E15="N.A.",0)+IF(E15="Baixo",1)+IF(E15="Moderado",2)+IF(E15="Significativo",4)+IF(E15="Alto",6) -> 0 | G15: =IF(F15>0,1,0) -> 0 | I15: =IF(H15="N.A.",0)+IF(H15="Baixo",1)+IF(H15="Moderado",2)+IF(H15="Significativo",4)+IF(H15="Alto",6) -> 0 | J15: =IF(I15>0,1,0) -> 0 | L15: =IF(K15="N.A.",0)+IF(K15="Baixo",1)+IF(K15="Moderado",2)+IF(K15="Significativo",4)+IF(K15="Alto",6) -> 0 | M15: =IF(L15>0,1,0) -> 0 | O15: =IF(N15="N.A.",0)+IF(N15="Baixo",1)+IF(N15="Moderado",2)+IF(N15="Significativo",4)+IF(N15="Alto",6) -> 0 | P15: =IF(O15>0,1,0) -> 0 | R15: =IF(Q15="N.A.",0)+IF(Q15="Baixo",1)+IF(Q15="Moderado",2)+IF(Q15="Significativo",4)+IF(Q15="Alto",6) -> 0 | S15: =IF(R15>0,1,0) -> 0 | T15: =SUM(G15,J15,M15,P15,S15) -> 0 | U15: =IFERROR(SUM(F15,I15,L15,O15,R15)/T15,0) -> 0 | AA15: =IF(W15="X",0)+IF(X15="X",2)+IF(Y15="X",4)+IF(Z15="X",9) -> 0 | AF15: =IF(AC15="X",1)+IF(AD15="X",2)+IF(AE15="X",5) -> 0 | AZ15: =OR(AND(U15>0,U15<=2,AP15>0,AP15>12,AP15<=17),AND(U15>0,U15>2,U15<=3,AP15>0,AP15>10,AP15<=13),AND(U15>0,U15>3,U15<=5,AP15>0,AP15<=10),AND(U15>0,U15>4,U15<=6,AP15>0,AP15<=7)) -> FALSE | BA15: =OR(AND(U15>0,U15>2,U15<=3,AP15>0,AP15>14,AP15<=20),AND(U15>0,U15>3,U15<=5,AP15>0,AP15>10),AND(U15>0,U15>5,U15<=6,AP15>0,AP15>7,AP15<=20)) -> FALSE
B16: 4. | C16: Novos Negócios - Definição do Produto | E16: Alto | F16: =IF(E16="N.A.",0)+IF(E16="Baixo",1)+IF(E16="Moderado",2)+IF(E16="Significativo",4)+IF(E16="Alto",6) -> 6 | G16: =IF(F16>0,1,0) -> 1 | H16: Baixo | I16: =IF(H16="N.A.",0)+IF(H16="Baixo",1)+IF(H16="Moderado",2)+IF(H16="Significativo",4)+IF(H16="Alto",6) -> 1 | J16: =IF(I16>0,1,0) -> 1 | K16: Baixo | L16: =IF(K16="N.A.",0)+IF(K16="Baixo",1)+IF(K16="Moderado",2)+IF(K16="Significativo",4)+IF(K16="Alto",6) -> 1 | M16: =IF(L16>0,1,0) -> 1 | N16: Significativo | O16: =IF(N16="N.A.",0)+IF(N16="Baixo",1)+IF(N16="Moderado",2)+IF(N16="Significativo",4)+IF(N16="Alto",6) -> 4 | P16: =IF(O16>0,1,0) -> 1 | Q16: Baixo | R16: =IF(Q16="N.A.",0)+IF(Q16="Baixo",1)+IF(Q16="Moderado",2)+IF(Q16="Significativo",4)+IF(Q16="Alto",6) -> 1 | S16: =IF(R16>0,1,0) -> 1 | T16: =SUM(G16,J16,M16,P16,S16) -> 5 | U16: =IFERROR(SUM(F16,I16,L16,O16,R16)/T16,0) -> 2.6 | X16: X | AA16: =IF(W16="X",0)+IF(X16="X",2)+IF(Y16="X",4)+IF(Z16="X",9) -> 2 | AD16: X | AF16: =IF(AC16="X",1)+IF(AD16="X",2)+IF(AE16="X",5) -> 2 | AJ16: X | AN16: =IF(AH16="X",1)+IF(AI16="X",2)+IF(AJ16="X",3)+IF(AK16="X",4)+IF(AL16="X",5)+IF(AM16="X",6) -> 3 | AP16: =AA16+AF16+AN16 -> 7 | AQ16: =(AP16+U16)/2 -> 4.8 | AR16: =IF(AS16="",0,10) -> 10 | AS16: =IF(AX16=TRUE,"Desprezível",IF(AY16=TRUE,"Administrável",IF(AZ16=TRUE,"Indesejável",IF(BA16=TRUE,"Intolerável","")))) -> Administrável | AU16: Mitigar | AW16: X | AX16: =AND(U16>0,U16<=2,AP16>0,AP16<=7) -> FALSE | AY16: =OR(AND(U16>0,U16<=2,AP16>0,AP16>7,AP16<=13),AND(U16>0,U16>2,U16<=3,AP16>0,AP16<=10)) -> TRUE | AZ16: =OR(AND(U16>0,U16<=2,AP16>0,AP16>12,AP16<=17),AND(U16>0,U16>2,U16<=3,AP16>0,AP16>10,AP16<=13),AND(U16>0,U16>3,U16<=5,AP16>0,AP16<=10),AND(U16>0,U16>4,U16<=6,AP16>0,AP16<=7)) -> FALSE | BA16: =OR(AND(U16>0,U16>2,U16<=3,AP16>0,AP16>14,AP16<=20),AND(U16>0,U16>3,U16<=5,AP16>0,AP16>10),AND(U16>0,U16>5,U16<=6,AP16>0,AP16>7,AP16<=20)) -> FALSE | BC16: X
F17: =IF(E17="N.A.",0)+IF(E17="Baixo",1)+IF(E17="Moderado",2)+IF(E17="Significativo",4)+IF(E17="Alto",6) -> 0 | G17: =IF(F17>0,1,0) -> 0 | I17: =IF(H17="N.A.",0)+IF(H17="Baixo",1)+IF(H17="Moderado",2)+IF(H17="Significativo",4)+IF(H17="Alto",6) -> 0 | J17: =IF(I17>0,1,0) -> 0 | L17: =IF(K17="N.A.",0)+IF(K17="Baixo",1)+IF(K17="Moderado",2)+IF(K17="Significativo",4)+IF(K17="Alto",6) -> 0 | M17: =IF(L17>0,1,0) -> 0 | O17: =IF(N17="N.A.",0)+IF(N17="Baixo",1)+IF(N17="Moderado",2)+IF(N17="Significativo",4)+IF(N17="Alto",6) -> 0 | P17: =IF(O17>0,1,0) -> 0 | R17: =IF(Q17="N.A.",0)+IF(Q17="Baixo",1)+IF(Q17="Moderado",2)+IF(Q17="Significativo",4)+IF(Q17="Alto",6) -> 0 | T17: =SUM(G17,J17,M17,P17,S17) -> 0 | U17: =IFERROR(SUM(F17,I17,L17,O17,R17)/T17,0) -> 0 | AA17: =IF(W17="X",0)+IF(X17="X",2)+IF(Y17="X",4)+IF(Z17="X",9) -> 0 | AF17: =IF(AC17="X",1)+IF(AD17="X",2)+IF(AE17="X",5) -> 0 | AZ17: =OR(AND(U17>0,U17<=2,AP17>0,AP17>12,AP17<=17),AND(U17>0,U17>2,U17<=3,AP17>0,AP17>10,AP17<=13),AND(U17>0,U17>3,U17<=5,AP17>0,AP17<=10),AND(U17>0,U17>4,U17<=6,AP17>0,AP17<=7)) -> FALSE | BA17: =OR(AND(U17>0,U17>2,U17<=3,AP17>0,AP17>14,AP17<=20),AND(U17>0,U17>3,U17<=5,AP17>0,AP17>10),AND(U17>0,U17>5,U17<=6,AP17>0,AP17>7,AP17<=20)) -> FALSE
B18: 5. | C18: Assistência Técnica - Conservação dos Imóveis | E18: Significativo | F18: =IF(E18="N.A.",0)+IF(E18="Baixo",1)+IF(E18="Moderado",2)+IF(E18="Significativo",4)+IF(E18="Alto",6) -> 4 | G18: =IF(F18>0,1,0) -> 1 | H18: Baixo | I18: =IF(H18="N.A.",0)+IF(H18="Baixo",1)+IF(H18="Moderado",2)+IF(H18="Significativo",4)+IF(H18="Alto",6) -> 1 | J18: =IF(I18>0,1,0) -> 1 | K18: Baixo | L18: =IF(K18="N.A.",0)+IF(K18="Baixo",1)+IF(K18="Moderado",2)+IF(K18="Significativo",4)+IF(K18="Alto",6) -> 1 | M18: =IF(L18>0,1,0) -> 1 | N18: Baixo | O18: =IF(N18="N.A.",0)+IF(N18="Baixo",1)+IF(N18="Moderado",2)+IF(N18="Significativo",4)+IF(N18="Alto",6) -> 1 | P18: =IF(O18>0,1,0) -> 1 | Q18: Significativo | R18: =IF(Q18="N.A.",0)+IF(Q18="Baixo",1)+IF(Q18="Moderado",2)+IF(Q18="Significativo",4)+IF(Q18="Alto",6) -> 4 | S18: =IF(R18>0,1,0) -> 1 | T18: =SUM(G18,J18,M18,P18,S18) -> 5 | U18: =IFERROR(SUM(F18,I18,L18,O18,R18)/T18,0) -> 2.2 | Y18: X | AA18: =IF(W18="X",0)+IF(X18="X",2)+IF(Y18="X",4)+IF(Z18="X",9) -> 4 | AD18: X | AF18: =IF(AC18="X",1)+IF(AD18="X",2)+IF(AE18="X",5) -> 2 | AJ18: X | AN18: =IF(AH18="X",1)+IF(AI18="X",2)+IF(AJ18="X",3)+IF(AK18="X",4)+IF(AL18="X",5)+IF(AM18="X",6) -> 3 | AP18: =AA18+AF18+AN18 -> 9 | AQ18: =(AP18+U18)/2 -> 5.6 | AR18: =IF(AS18="",0,10) -> 10 | AS18: =IF(AX18=TRUE,"Desprezível",IF(AY18=TRUE,"Administrável",IF(AZ18=TRUE,"Indesejável",IF(BA18=TRUE,"Intolerável","")))) -> Administrável | AU18: Prevenir | AX18: =AND(U18>0,U18<=2,AP18>0,AP18<=7) -> FALSE | AY18: =OR(AND(U18>0,U18<=2,AP18>0,AP18>7,AP18<=13),AND(U18>0,U18>2,U18<=3,AP18>0,AP18<=10)) -> TRUE | AZ18: =OR(AND(U18>0,U18<=2,AP18>0,AP18>12,AP18<=17),AND(U18>0,U18>2,U18<=3,AP18>0,AP18>10,AP18<=13),AND(U18>0,U18>3,U18<=5,AP18>0,AP18<=10),AND(U18>0,U18>4,U18<=6,AP18>0,AP18<=7)) -> FALSE | BA18: =OR(AND(U18>0,U18>2,U18<=3,AP18>0,AP18>14,AP18<=20),AND(U18>0,U18>3,U18<=5,AP18>0,AP18>10),AND(U18>0,U18>5,U18<=6,AP18>0,AP18>7,AP18<=20)) -> FALSE
F19: =IF(E19="N.A.",0)+IF(E19="Baixo",1)+IF(E19="Moderado",2)+IF(E19="Significativo",4)+IF(E19="Alto",6) -> 0 | G19: =IF(F19>0,1,0) -> 0 | I19: =IF(H19="N.A.",0)+IF(H19="Baixo",1)+IF(H19="Moderado",2)+IF(H19="Significativo",4)+IF(H19="Alto",6) -> 0 | J19: =IF(I19>0,1,0) -> 0 | L19: =IF(K19="N.A.",0)+IF(K19="Baixo",1)+IF(K19="Moderado",2)+IF(K19="Significativo",4)+IF(K19="Alto",6) -> 0 | M19: =IF(L19>0,1,0) -> 0 | O19: =IF(N19="N.A.",0)+IF(N19="Baixo",1)+IF(N19="Moderado",2)+IF(N19="Significativo",4)+IF(N19="Alto",6) -> 0 | P19: =IF(O19>0,1,0) -> 0 | R19: =IF(Q19="N.A.",0)+IF(Q19="Baixo",1)+IF(Q19="Moderado",2)+IF(Q19="Significativo",4)+IF(Q19="Alto",6) -> 0 | T19: =SUM(G19,J19,M19,P19,S19) -> 0 | U19: =IFERROR(SUM(F19,I19,L19,O19,R19)/T19,0) -> 0 | AA19: =IF(W19="X",0)+IF(X19="X",2)+IF(Y19="X",4)+IF(Z19="X",9) -> 0 | AF19: =IF(AC19="X",1)+IF(AD19="X",2)+IF(AE19="X",5) -> 0 | AZ19: =OR(AND(U19>0,U19<=2,AP19>0,AP19>12,AP19<=17),AND(U19>0,U19>2,U19<=3,AP19>0,AP19>10,AP19<=13),AND(U19>0,U19>3,U19<=5,AP19>0,AP19<=10),AND(U19>0,U19>4,U19<=6,AP19>0,AP19<=7)) -> FALSE | BA19: =OR(AND(U19>0,U19>2,U19<=3,AP19>0,AP19>14,AP19<=20),AND(U19>0,U19>3,U19<=5,AP19>0,AP19>10),AND(U19>0,U19>5,U19<=6,AP19>0,AP19>7,AP19<=20)) -> FALSE
B20: 6. | C20: Administrativo - Inadimplência | E20: Significativo | F20: =IF(E20="N.A.",0)+IF(E20="Baixo",1)+IF(E20="Moderado",2)+IF(E20="Significativo",4)+IF(E20="Alto",6) -> 4 | G20: =IF(F20>0,1,0) -> 1 | H20: Baixo | I20: =IF(H20="N.A.",0)+IF(H20="Baixo",1)+IF(H20="Moderado",2)+IF(H20="Significativo",4)+IF(H20="Alto",6) -> 1 | J20: =IF(I20>0,1,0) -> 1 | K20: Baixo | L20: =IF(K20="N.A.",0)+IF(K20="Baixo",1)+IF(K20="Moderado",2)+IF(K20="Significativo",4)+IF(K20="Alto",6) -> 1 | M20: =IF(L20>0,1,0) -> 1 | N20: Significativo | O20: =IF(N20="N.A.",0)+IF(N20="Baixo",1)+IF(N20="Moderado",2)+IF(N20="Significativo",4)+IF(N20="Alto",6) -> 4 | P20: =IF(O20>0,1,0) -> 1 | Q20: Baixo | R20: =IF(Q20="N.A.",0)+IF(Q20="Baixo",1)+IF(Q20="Moderado",2)+IF(Q20="Significativo",4)+IF(Q20="Alto",6) -> 1 | S20: =IF(R20>0,1,0) -> 1 | T20: =SUM(G20,J20,M20,P20,S20) -> 5 | U20: =IFERROR(SUM(F20,I20,L20,O20,R20)/T20,0) -> 2.2 | Y20: X | AA20: =IF(W20="X",0)+IF(X20="X",2)+IF(Y20="X",4)+IF(Z20="X",9) -> 4 | AC20: X | AF20: =IF(AC20="X",1)+IF(AD20="X",2)+IF(AE20="X",5) -> 1 | AJ20: X | AN20: =IF(AH20="X",1)+IF(AI20="X",2)+IF(AJ20="X",3)+IF(AK20="X",4)+IF(AL20="X",5)+IF(AM20="X",6) -> 3 | AP20: =AA20+AF20+AN20 -> 8 | AQ20: =(AP20+U20)/2 -> 5.1 | AR20: =IF(AS20="",0,10) -> 10 | AS20: =IF(AX20=TRUE,"Desprezível",IF(AY20=TRUE,"Administrável",IF(AZ20=TRUE,"Indesejável",IF(BA20=TRUE,"Intolerável","")))) -> Administrável | AU20: Mitigar | AX20: =AND(U20>0,U20<=2,AP20>0,AP20<=7) -> FALSE | AY20: =OR(AND(U20>0,U20<=2,AP20>0,AP20>7,AP20<=13),AND(U20>0,U20>2,U20<=3,AP20>0,AP20<=10)) -> TRUE | AZ20: =OR(AND(U20>0,U20<=2,AP20>0,AP20>12,AP20<=17),AND(U20>0,U20>2,U20<=3,AP20>0,AP20>10,AP20<=13),AND(U20>0,U20>3,U20<=5,AP20>0,AP20<=10),AND(U20>0,U20>4,U20<=6,AP20>0,AP20<=7)) -> FALSE | BA20: =OR(AND(U20>0,U20>2,U20<=3,AP20>0,AP20>14,AP20<=20),AND(U20>0,U20>3,U20<=5,AP20>0,AP20>10),AND(U20>0,U20>5,U20<=6,AP20>0,AP20>7,AP20<=20)) -> FALSE
F21: =IF(E21="N.A.",0)+IF(E21="Baixo",1)+IF(E21="Moderado",2)+IF(E21="Significativo",4)+IF(E21="Alto",6) -> 0 | G21: =IF(F21>0,1,0) -> 0 | I21: =IF(H21="N.A.",0)+IF(H21="Baixo",1)+IF(H21="Moderado",2)+IF(H21="Significativo",4)+IF(H21="Alto",6) -> 0 | J21: =IF(I21>0,1,0) -> 0 | L21: =IF(K21="N.A.",0)+IF(K21="Baixo",1)+IF(K21="Moderado",2)+IF(K21="Significativo",4)+IF(K21="Alto",6) -> 0 | M21: =IF(L21>0,1,0) -> 0 | O21: =IF(N21="N.A.",0)+IF(N21="Baixo",1)+IF(N21="Moderado",2)+IF(N21="Significativo",4)+IF(N21="Alto",6) -> 0 | P21: =IF(O21>0,1,0) -> 0 | R21: =IF(Q21="N.A.",0)+IF(Q21="Baixo",1)+IF(Q21="Moderado",2)+IF(Q21="Significativo",4)+IF(Q21="Alto",6) -> 0 | T21: =SUM(G21,J21,M21,P21,S21) -> 0 | U21: =IFERROR(SUM(F21,I21,L21,O21,R21)/T21,0) -> 0 | AA21: =IF(W21="X",0)+IF(X21="X",2)+IF(Y21="X",4)+IF(Z21="X",9) -> 0 | AF21: =IF(AC21="X",1)+IF(AD21="X",2)+IF(AE21="X",5) -> 0 | AZ21: =OR(AND(U21>0,U21<=2,AP21>0,AP21>12,AP21<=17),AND(U21>0,U21>2,U21<=3,AP21>0,AP21>10,AP21<=13),AND(U21>0,U21>3,U21<=5,AP21>0,AP21<=10),AND(U21>0,U21>4,U21<=6,AP21>0,AP21<=7)) -> FALSE | BA21: =OR(AND(U21>0,U21>2,U21<=3,AP21>0,AP21>14,AP21<=20),AND(U21>0,U21>3,U21<=5,AP21>0,AP21>10),AND(U21>0,U21>5,U21<=6,AP21>0,AP21>7,AP21<=20)) -> FALSE
B22: 7. | C22: Redução de faturamento em decorrência de Pandemias "Covid-19" | E22: Alto | F22: =IF(E22="N.A.",0)+IF(E22="Baixo",1)+IF(E22="Moderado",2)+IF(E22="Significativo",4)+IF(E22="Alto",6) -> 6 | G22: =IF(F22>0,1,0) -> 1 | H22: Baixo | I22: =IF(H22="N.A.",0)+IF(H22="Baixo",1)+IF(H22="Moderado",2)+IF(H22="Significativo",4)+IF(H22="Alto",6) -> 1 | J22: =IF(I22>0,1,0) -> 1 | K22: Baixo | L22: =IF(K22="N.A.",0)+IF(K22="Baixo",1)+IF(K22="Moderado",2)+IF(K22="Significativo",4)+IF(K22="Alto",6) -> 1 | M22: =IF(L22>0,1,0) -> 1 | N22: Significativo | O22: =IF(N22="N.A.",0)+IF(N22="Baixo",1)+IF(N22="Moderado",2)+IF(N22="Significativo",4)+IF(N22="Alto",6) -> 4 | P22: =IF(O22>0,1,0) -> 1 | Q22: Baixo | R22: =IF(Q22="N.A.",0)+IF(Q22="Baixo",1)+IF(Q22="Moderado",2)+IF(Q22="Significativo",4)+IF(Q22="Alto",6) -> 1 | S22: =IF(R22>0,1,0) -> 1 | T22: =SUM(G22,J22,M22,P22,S22) -> 5 | U22: =IFERROR(SUM(F22,I22,L22,O22,R22)/T22,0) -> 2.6 | Y22: X | AA22: =IF(W22="X",0)+IF(X22="X",2)+IF(Y22="X",4)+IF(Z22="X",9) -> 4 | AD22: X | AF22: =IF(AC22="X",1)+IF(AD22="X",2)+IF(AE22="X",5) -> 2 | AJ22: X | AN22: =IF(AH22="X",1)+IF(AI22="X",2)+IF(AJ22="X",3)+IF(AK22="X",4)+IF(AL22="X",5)+IF(AM22="X",6) -> 3 | AP22: =AA22+AF22+AN22 -> 9 | AQ22: =(AP22+U22)/2 -> 5.8 | AR22: =IF(AS22="",0,10) -> 10 | AS22: =IF(AX22=TRUE,"Desprezível",IF(AY22=TRUE,"Administrável",IF(AZ22=TRUE,"Indesejável",IF(BA22=TRUE,"Intolerável","")))) -> Administrável | AU22: Mitigar | AX22: =AND(U22>0,U22<=2,AP22>0,AP22<=7) -> FALSE | AY22: =OR(AND(U22>0,U22<=2,AP22>0,AP22>7,AP22<=13),AND(U22>0,U22>2,U22<=3,AP22>0,AP22<=10)) -> TRUE | AZ22: =OR(AND(U22>0,U22<=2,AP22>0,AP22>12,AP22<=17),AND(U22>0,U22>2,U22<=3,AP22>0,AP22>10,AP22<=13),AND(U22>0,U22>3,U22<=5,AP22>0,AP22<=10),AND(U22>0,U22>4,U22<=6,AP22>0,AP22<=7)) -> FALSE | BA22: =OR(AND(U22>0,U22>2,U22<=3,AP22>0,AP22>14,AP22<=20),AND(U22>0,U22>3,U22<=5,AP22>0,AP22>10),AND(U22>0,U22>5,U22<=6,AP22>0,AP22>7,AP22<=20)) -> FALSE
F23: =IF(E23="N.A.",0)+IF(E23="Baixo",1)+IF(E23="Moderado",2)+IF(E23="Significativo",4)+IF(E23="Alto",6) -> 0 | G23: =IF(F23>0,1,0) -> 0 | I23: =IF(H23="N.A.",0)+IF(H23="Baixo",1)+IF(H23="Moderado",2)+IF(H23="Significativo",4)+IF(H23="Alto",6) -> 0 | J23: =IF(I23>0,1,0) -> 0 | L23: =IF(K23="N.A.",0)+IF(K23="Baixo",1)+IF(K23="Moderado",2)+IF(K23="Significativo",4)+IF(K23="Alto",6) -> 0 | M23: =IF(L23>0,1,0) -> 0 | O23: =IF(N23="N.A.",0)+IF(N23="Baixo",1)+IF(N23="Moderado",2)+IF(N23="Significativo",4)+IF(N23="Alto",6) -> 0 | P23: =IF(O23>0,1,0) -> 0 | R23: =IF(Q23="N.A.",0)+IF(Q23="Baixo",1)+IF(Q23="Moderado",2)+IF(Q23="Significativo",4)+IF(Q23="Alto",6) -> 0 | T23: =SUM(G23,J23,M23,P23,S23) -> 0 | U23: =IFERROR(SUM(F23,I23,L23,O23,R23)/T23,0) -> 0 | AA23: =IF(W23="X",0)+IF(X23="X",2)+IF(Y23="X",4)+IF(Z23="X",9) -> 0 | AF23: =IF(AC23="X",1)+IF(AD23="X",2)+IF(AE23="X",5) -> 0 | AZ23: =OR(AND(U23>0,U23<=2,AP23>0,AP23>12,AP23<=17),AND(U23>0,U23>2,U23<=3,AP23>0,AP23>10,AP23<=13),AND(U23>0,U23>3,U23<=5,AP23>0,AP23<=10),AND(U23>0,U23>4,U23<=6,AP23>0,AP23<=7)) -> FALSE | BA23: =OR(AND(U23>0,U23>2,U23<=3,AP23>0,AP23>14,AP23<=20),AND(U23>0,U23>3,U23<=5,AP23>0,AP23>10),AND(U23>0,U23>5,U23<=6,AP23>0,AP23>7,AP23<=20)) -> FALSE
B24: 8. | F24: =IF(E24="N.A.",0)+IF(E24="Baixo",1)+IF(E24="Moderado",2)+IF(E24="Significativo",4)+IF(E24="Alto",6) -> 0 | G24: =IF(F24>0,1,0) -> 0 | I24: =IF(H24="N.A.",0)+IF(H24="Baixo",1)+IF(H24="Moderado",2)+IF(H24="Significativo",4)+IF(H24="Alto",6) -> 0 | J24: =IF(I24>0,1,0) -> 0 | L24: =IF(K24="N.A.",0)+IF(K24="Baixo",1)+IF(K24="Moderado",2)+IF(K24="Significativo",4)+IF(K24="Alto",6) -> 0 | M24: =IF(L24>0,1,0) -> 0 | O24: =IF(N24="N.A.",0)+IF(N24="Baixo",1)+IF(N24="Moderado",2)+IF(N24="Significativo",4)+IF(N24="Alto",6) -> 0 | P24: =IF(O24>0,1,0) -> 0 | R24: =IF(Q24="N.A.",0)+IF(Q24="Baixo",1)+IF(Q24="Moderado",2)+IF(Q24="Significativo",4)+IF(Q24="Alto",6) -> 0 | S24: =IF(R24>0,1,0) -> 0 | T24: =SUM(G24,J24,M24,P24,S24) -> 0 | U24: =IFERROR(SUM(F24,I24,L24,O24,R24)/T24,0) -> 0 | AA24: =IF(W24="X",0)+IF(X24="X",2)+IF(Y24="X",4)+IF(Z24="X",9) -> 0 | AF24: =IF(AC24="X",1)+IF(AD24="X",2)+IF(AE24="X",5) -> 0 | AN24: =IF(AH24="X",1)+IF(AI24="X",2)+IF(AJ24="X",3)+IF(AK24="X",4)+IF(AL24="X",5)+IF(AM24="X",6) -> 0 | AP24: =AA24+AF24+AN24 -> 0 | AQ24: =(AP24+U24)/2 -> 0 | AR24: =IF(AS24="",0,10) -> 0 | AS24: =IF(AX24=TRUE,"Desprezível",IF(AY24=TRUE,"Administrável",IF(AZ24=TRUE,"Indesejável",IF(BA24=TRUE,"Intolerável","")))) | AX24: =AND(U24>0,U24<=2,AP24>0,AP24<=7) -> FALSE | AY24: =OR(AND(U24>0,U24<=2,AP24>0,AP24>7,AP24<=13),AND(U24>0,U24>2,U24<=3,AP24>0,AP24<=10)) -> FALSE | AZ24: =OR(AND(U24>0,U24<=2,AP24>0,AP24>12,AP24<=17),AND(U24>0,U24>2,U24<=3,AP24>0,AP24>10,AP24<=13),AND(U24>0,U24>3,U24<=5,AP24>0,AP24<=10),AND(U24>0,U24>4,U24<=6,AP24>0,AP24<=7)) -> FALSE | BA24: =OR(AND(U24>0,U24>2,U24<=3,AP24>0,AP24>14,AP24<=20),AND(U24>0,U24>3,U24<=5,AP24>0,AP24>10),AND(U24>0,U24>5,U24<=6,AP24>0,AP24>7,AP24<=20)) -> FALSE
F25: =IF(E25="N.A.",0)+IF(E25="Baixo",1)+IF(E25="Moderado",2)+IF(E25="Significativo",4)+IF(E25="Alto",6) -> 0 | G25: =IF(F25>0,1,0) -> 0 | I25: =IF(H25="N.A.",0)+IF(H25="Baixo",1)+IF(H25="Moderado",2)+IF(H25="Significativo",4)+IF(H25="Alto",6) -> 0 | J25: =IF(I25>0,1,0) -> 0 | L25: =IF(K25="N.A.",0)+IF(K25="Baixo",1)+IF(K25="Moderado",2)+IF(K25="Significativo",4)+IF(K25="Alto",6) -> 0 | M25: =IF(L25>0,1,0) -> 0 | O25: =IF(N25="N.A.",0)+IF(N25="Baixo",1)+IF(N25="Moderado",2)+IF(N25="Significativo",4)+IF(N25="Alto",6) -> 0 | P25: =IF(O25>0,1,0) -> 0 | R25: =IF(Q25="N.A.",0)+IF(Q25="Baixo",1)+IF(Q25="Moderado",2)+IF(Q25="Significativo",4)+IF(Q25="Alto",6) -> 0 | T25: =SUM(G25,J25,M25,P25,S25) -> 0 | U25: =IFERROR(SUM(F25,I25,L25,O25,R25)/T25,0) -> 0 | AA25: =IF(W25="X",0)+IF(X25="X",2)+IF(Y25="X",4)+IF(Z25="X",9) -> 0 | AF25: =IF(AC25="X",1)+IF(AD25="X",2)+IF(AE25="X",5) -> 0 | AZ25: =OR(AND(U25>0,U25<=2,AP25>0,AP25>12,AP25<=17),AND(U25>0,U25>2,U25<=3,AP25>0,AP25>10,AP25<=13),AND(U25>0,U25>3,U25<=5,AP25>0,AP25<=10),AND(U25>0,U25>4,U25<=6,AP25>0,AP25<=7)) -> FALSE | BA25: =OR(AND(U25>0,U25>2,U25<=3,AP25>0,AP25>14,AP25<=20),AND(U25>0,U25>3,U25<=5,AP25>0,AP25>10),AND(U25>0,U25>5,U25<=6,AP25>0,AP25>7,AP25<=20)) -> FALSE
B26: 9. | F26: =IF(E26="N.A.",0)+IF(E26="Baixo",1)+IF(E26="Moderado",2)+IF(E26="Significativo",4)+IF(E26="Alto",6) -> 0 | G26: =IF(F26>0,1,0) -> 0 | I26: =IF(H26="N.A.",0)+IF(H26="Baixo",1)+IF(H26="Moderado",2)+IF(H26="Significativo",4)+IF(H26="Alto",6) -> 0 | J26: =IF(I26>0,1,0) -> 0 | L26: =IF(K26="N.A.",0)+IF(K26="Baixo",1)+IF(K26="Moderado",2)+IF(K26="Significativo",4)+IF(K26="Alto",6) -> 0 | M26: =IF(L26>0,1,0) -> 0 | O26: =IF(N26="N.A.",0)+IF(N26="Baixo",1)+IF(N26="Moderado",2)+IF(N26="Significativo",4)+IF(N26="Alto",6) -> 0 | P26: =IF(O26>0,1,0) -> 0 | R26: =IF(Q26="N.A.",0)+IF(Q26="Baixo",1)+IF(Q26="Moderado",2)+IF(Q26="Significativo",4)+IF(Q26="Alto",6) -> 0 | S26: =IF(R26>0,1,0) -> 0 | T26: =SUM(G26,J26,M26,P26,S26) -> 0 | U26: =IFERROR(SUM(F26,I26,L26,O26,R26)/T26,0) -> 0 | AA26: =IF(W26="X",0)+IF(X26="X",2)+IF(Y26="X",4)+IF(Z26="X",9) -> 0 | AF26: =IF(AC26="X",1)+IF(AD26="X",2)+IF(AE26="X",5) -> 0 | AN26: =IF(AH26="X",1)+IF(AI26="X",2)+IF(AJ26="X",3)+IF(AK26="X",4)+IF(AL26="X",5)+IF(AM26="X",6) -> 0 | AP26: =AA26+AF26+AN26 -> 0 | AQ26: =(AP26+U26)/2 -> 0 | AR26: =IF(AS26="",0,10) -> 0 | AS26: =IF(AX26=TRUE,"Desprezível",IF(AY26=TRUE,"Administrável",IF(AZ26=TRUE,"Indesejável",IF(BA26=TRUE,"Intolerável","")))) | AX26: =AND(U26>0,U26<=2,AP26>0,AP26<=7) -> FALSE | AY26: =OR(AND(U26>0,U26<=2,AP26>0,AP26>7,AP26<=13),AND(U26>0,U26>2,U26<=3,AP26>0,AP26<=10)) -> FALSE | AZ26: =OR(AND(U26>0,U26<=2,AP26>0,AP26>12,AP26<=17),AND(U26>0,U26>2,U26<=3,AP26>0,AP26>10,AP26<=13),AND(U26>0,U26>3,U26<=5,AP26>0,AP26<=10),AND(U26>0,U26>4,U26<=6,AP26>0,AP26<=7)) -> FALSE | BA26: =OR(AND(U26>0,U26>2,U26<=3,AP26>0,AP26>14,AP26<=20),AND(U26>0,U26>3,U26<=5,AP26>0,AP26>10),AND(U26>0,U26>5,U26<=6,AP26>0,AP26>7,AP26<=20)) -> FALSE
F27: =IF(E27="N.A.",0)+IF(E27="Baixo",1)+IF(E27="Moderado",2)+IF(E27="Significativo",4)+IF(E27="Alto",6) -> 0 | G27: =IF(F27>0,1,0) -> 0 | I27: =IF(H27="N.A.",0)+IF(H27="Baixo",1)+IF(H27="Moderado",2)+IF(H27="Significativo",4)+IF(H27="Alto",6) -> 0 | J27: =IF(I27>0,1,0) -> 0 | L27: =IF(K27="N.A.",0)+IF(K27="Baixo",1)+IF(K27="Moderado",2)+IF(K27="Significativo",4)+IF(K27="Alto",6) -> 0 | M27: =IF(L27>0,1,0) -> 0 | O27: =IF(N27="N.A.",0)+IF(N27="Baixo",1)+IF(N27="Moderado",2)+IF(N27="Significativo",4)+IF(N27="Alto",6) -> 0 | P27: =IF(O27>0,1,0) -> 0 | R27: =IF(Q27="N.A.",0)+IF(Q27="Baixo",1)+IF(Q27="Moderado",2)+IF(Q27="Significativo",4)+IF(Q27="Alto",6) -> 0 | T27: =SUM(G27,J27,M27,P27,S27) -> 0 | U27: =IFERROR(SUM(F27,I27,L27,O27,R27)/T27,0) -> 0 | AA27: =IF(W27="X",0)+IF(X27="X",2)+IF(Y27="X",4)+IF(Z27="X",9) -> 0 | AF27: =IF(AC27="X",1)+IF(AD27="X",2)+IF(AE27="X",5) -> 0 | AZ27: =OR(AND(U27>0,U27<=2,AP27>0,AP27>12,AP27<=17),AND(U27>0,U27>2,U27<=3,AP27>0,AP27>10,AP27<=13),AND(U27>0,U27>3,U27<=5,AP27>0,AP27<=10),AND(U27>0,U27>4,U27<=6,AP27>0,AP27<=7)) -> FALSE | BA27: =OR(AND(U27>0,U27>2,U27<=3,AP27>0,AP27>14,AP27<=20),AND(U27>0,U27>3,U27<=5,AP27>0,AP27>10),AND(U27>0,U27>5,U27<=6,AP27>0,AP27>7,AP27<=20)) -> FALSE
B28: 10. | F28: =IF(E28="N.A.",0)+IF(E28="Baixo",1)+IF(E28="Moderado",2)+IF(E28="Significativo",4)+IF(E28="Alto",6) -> 0 | G28: =IF(F28>0,1,0) -> 0 | I28: =IF(H28="N.A.",0)+IF(H28="Baixo",1)+IF(H28="Moderado",2)+IF(H28="Significativo",4)+IF(H28="Alto",6) -> 0 | J28: =IF(I28>0,1,0) -> 0 | L28: =IF(K28="N.A.",0)+IF(K28="Baixo",1)+IF(K28="Moderado",2)+IF(K28="Significativo",4)+IF(K28="Alto",6) -> 0 | M28: =IF(L28>0,1,0) -> 0 | O28: =IF(N28="N.A.",0)+IF(N28="Baixo",1)+IF(N28="Moderado",2)+IF(N28="Significativo",4)+IF(N28="Alto",6) -> 0 | P28: =IF(O28>0,1,0) -> 0 | R28: =IF(Q28="N.A.",0)+IF(Q28="Baixo",1)+IF(Q28="Moderado",2)+IF(Q28="Significativo",4)+IF(Q28="Alto",6) -> 0 | S28: =IF(R28>0,1,0) -> 0 | T28: =SUM(G28,J28,M28,P28,S28) -> 0 | U28: =IFERROR(SUM(F28,I28,L28,O28,R28)/T28,0) -> 0 | AA28: =IF(W28="X",0)+IF(X28="X",2)+IF(Y28="X",4)+IF(Z28="X",9) -> 0 | AF28: =IF(AC28="X",1)+IF(AD28="X",2)+IF(AE28="X",5) -> 0 | AN28: =IF(AH28="X",1)+IF(AI28="X",2)+IF(AJ28="X",3)+IF(AK28="X",4)+IF(AL28="X",5)+IF(AM28="X",6) -> 0 | AP28: =AA28+AF28+AN28 -> 0 | AQ28: =(AP28+U28)/2 -> 0 | AR28: =IF(AS28="",0,10) -> 0 | AS28: =IF(AX28=TRUE,"Desprezível",IF(AY28=TRUE,"Administrável",IF(AZ28=TRUE,"Indesejável",IF(BA28=TRUE,"Intolerável","")))) | AX28: =AND(U28>0,U28<=2,AP28>0,AP28<=7) -> FALSE | AY28: =OR(AND(U28>0,U28<=2,AP28>0,AP28>7,AP28<=13),AND(U28>0,U28>2,U28<=3,AP28>0,AP28<=10)) -> FALSE | AZ28: =OR(AND(U28>0,U28<=2,AP28>0,AP28>12,AP28<=17),AND(U28>0,U28>2,U28<=3,AP28>0,AP28>10,AP28<=13),AND(U28>0,U28>3,U28<=5,AP28>0,AP28<=10),AND(U28>0,U28>4,U28<=6,AP28>0,AP28<=7)) -> FALSE | BA28: =OR(AND(U28>0,U28>2,U28<=3,AP28>0,AP28>14,AP28<=20),AND(U28>0,U28>3,U28<=5,AP28>0,AP28>10),AND(U28>0,U28>5,U28<=6,AP28>0,AP28>7,AP28<=20)) -> FALSE
F29: =IF(E29="N.A.",0)+IF(E29="Baixo",1)+IF(E29="Moderado",2)+IF(E29="Significativo",4)+IF(E29="Alto",6) -> 0 | G29: =IF(F29>0,1,0) -> 0 | I29: =IF(H29="N.A.",0)+IF(H29="Baixo",1)+IF(H29="Moderado",2)+IF(H29="Significativo",4)+IF(H29="Alto",6) -> 0 | J29: =IF(I29>0,1,0) -> 0 | L29: =IF(K29="N.A.",0)+IF(K29="Baixo",1)+IF(K29="Moderado",2)+IF(K29="Significativo",4)+IF(K29="Alto",6) -> 0 | M29: =IF(L29>0,1,0) -> 0 | O29: =IF(N29="N.A.",0)+IF(N29="Baixo",1)+IF(N29="Moderado",2)+IF(N29="Significativo",4)+IF(N29="Alto",6) -> 0 | P29: =IF(O29>0,1,0) -> 0 | R29: =IF(Q29="N.A.",0)+IF(Q29="Baixo",1)+IF(Q29="Moderado",2)+IF(Q29="Significativo",4)+IF(Q29="Alto",6) -> 0 | T29: =SUM(G29,J29,M29,P29,S29) -> 0 | U29: =IFERROR(SUM(F29,I29,L29,O29,R29)/T29,0) -> 0 | AA29: =IF(W29="X",0)+IF(X29="X",2)+IF(Y29="X",4)+IF(Z29="X",9) -> 0 | AF29: =IF(AC29="X",1)+IF(AD29="X",2)+IF(AE29="X",5) -> 0 | AZ29: =OR(AND(U29>0,U29<=2,AP29>0,AP29>12,AP29<=17),AND(U29>0,U29>2,U29<=3,AP29>0,AP29>10,AP29<=13),AND(U29>0,U29>3,U29<=5,AP29>0,AP29<=10),AND(U29>0,U29>4,U29<=6,AP29>0,AP29<=7)) -> FALSE | BA29: =OR(AND(U29>0,U29>2,U29<=3,AP29>0,AP29>14,AP29<=20),AND(U29>0,U29>3,U29<=5,AP29>0,AP29>10),AND(U29>0,U29>5,U29<=6,AP29>0,AP29>7,AP29<=20)) -> FALSE
B30: 11. | F30: =IF(E30="N.A.",0)+IF(E30="Baixo",1)+IF(E30="Moderado",2)+IF(E30="Significativo",4)+IF(E30="Alto",6) -> 0 | G30: =IF(F30>0,1,0) -> 0 | I30: =IF(H30="N.A.",0)+IF(H30="Baixo",1)+IF(H30="Moderado",2)+IF(H30="Significativo",4)+IF(H30="Alto",6) -> 0 | J30: =IF(I30>0,1,0) -> 0 | L30: =IF(K30="N.A.",0)+IF(K30="Baixo",1)+IF(K30="Moderado",2)+IF(K30="Significativo",4)+IF(K30="Alto",6) -> 0 | M30: =IF(L30>0,1,0) -> 0 | O30: =IF(N30="N.A.",0)+IF(N30="Baixo",1)+IF(N30="Moderado",2)+IF(N30="Significativo",4)+IF(N30="Alto",6) -> 0 | P30: =IF(O30>0,1,0) -> 0 | R30: =IF(Q30="N.A.",0)+IF(Q30="Baixo",1)+IF(Q30="Moderado",2)+IF(Q30="Significativo",4)+IF(Q30="Alto",6) -> 0 | S30: =IF(R30>0,1,0) -> 0 | T30: =SUM(G30,J30,M30,P30,S30) -> 0 | U30: =IFERROR(SUM(F30,I30,L30,O30,R30)/T30,0) -> 0 | AA30: =IF(W30="X",0)+IF(X30="X",2)+IF(Y30="X",4)+IF(Z30="X",9) -> 0 | AF30: =IF(AC30="X",1)+IF(AD30="X",2)+IF(AE30="X",5) -> 0 | AN30: =IF(AH30="X",1)+IF(AI30="X",2)+IF(AJ30="X",3)+IF(AK30="X",4)+IF(AL30="X",5)+IF(AM30="X",6) -> 0 | AP30: =AA30+AF30+AN30 -> 0 | AQ30: =(AP30+U30)/2 -> 0 | AR30: =IF(AS30="",0,10) -> 0 | AS30: =IF(AX30=TRUE,"Desprezível",IF(AY30=TRUE,"Administrável",IF(AZ30=TRUE,"Indesejável",IF(BA30=TRUE,"Intolerável","")))) | AX30: =AND(U30>0,U30<=2,AP30>0,AP30<=7) -> FALSE | AY30: =OR(AND(U30>0,U30<=2,AP30>0,AP30>7,AP30<=13),AND(U30>0,U30>2,U30<=3,AP30>0,AP30<=10)) -> FALSE | AZ30: =OR(AND(U30>0,U30<=2,AP30>0,AP30>12,AP30<=17),AND(U30>0,U30>2,U30<=3,AP30>0,AP30>10,AP30<=13),AND(U30>0,U30>3,U30<=5,AP30>0,AP30<=10),AND(U30>0,U30>4,U30<=6,AP30>0,AP30<=7)) -> FALSE | BA30: =OR(AND(U30>0,U30>2,U30<=3,AP30>0,AP30>14,AP30<=20),AND(U30>0,U30>3,U30<=5,AP30>0,AP30>10),AND(U30>0,U30>5,U30<=6,AP30>0,AP30>7,AP30<=20)) -> FALSE
F31: =IF(E31="N.A.",0)+IF(E31="Baixo",1)+IF(E31="Moderado",2)+IF(E31="Significativo",4)+IF(E31="Alto",6) -> 0 | G31: =IF(F31>0,1,0) -> 0 | I31: =IF(H31="N.A.",0)+IF(H31="Baixo",1)+IF(H31="Moderado",2)+IF(H31="Significativo",4)+IF(H31="Alto",6) -> 0 | J31: =IF(I31>0,1,0) -> 0 | L31: =IF(K31="N.A.",0)+IF(K31="Baixo",1)+IF(K31="Moderado",2)+IF(K31="Significativo",4)+IF(K31="Alto",6) -> 0 | M31: =IF(L31>0,1,0) -> 0 | O31: =IF(N31="N.A.",0)+IF(N31="Baixo",1)+IF(N31="Moderado",2)+IF(N31="Significativo",4)+IF(N31="Alto",6) -> 0 | P31: =IF(O31>0,1,0) -> 0 | R31: =IF(Q31="N.A.",0)+IF(Q31="Baixo",1)+IF(Q31="Moderado",2)+IF(Q31="Significativo",4)+IF(Q31="Alto",6) -> 0 | T31: =SUM(G31,J31,M31,P31,S31) -> 0 | U31: =IFERROR(SUM(F31,I31,L31,O31,R31)/T31,0) -> 0 | AA31: =IF(W31="X",0)+IF(X31="X",2)+IF(Y31="X",4)+IF(Z31="X",9) -> 0 | AF31: =IF(AC31="X",1)+IF(AD31="X",2)+IF(AE31="X",5) -> 0 | AZ31: =OR(AND(U31>0,U31<=2,AP31>0,AP31>12,AP31<=17),AND(U31>0,U31>2,U31<=3,AP31>0,AP31>10,AP31<=13),AND(U31>0,U31>3,U31<=5,AP31>0,AP31<=10),AND(U31>0,U31>4,U31<=6,AP31>0,AP31<=7)) -> FALSE | BA31: =OR(AND(U31>0,U31>2,U31<=3,AP31>0,AP31>14,AP31<=20),AND(U31>0,U31>3,U31<=5,AP31>0,AP31>10),AND(U31>0,U31>5,U31<=6,AP31>0,AP31>7,AP31<=20)) -> FALSE
B32: 12. | F32: =IF(E32="N.A.",0)+IF(E32="Baixo",1)+IF(E32="Moderado",2)+IF(E32="Significativo",4)+IF(E32="Alto",6) -> 0 | G32: =IF(F32>0,1,0) -> 0 | I32: =IF(H32="N.A.",0)+IF(H32="Baixo",1)+IF(H32="Moderado",2)+IF(H32="Significativo",4)+IF(H32="Alto",6) -> 0 | J32: =IF(I32>0,1,0) -> 0 | L32: =IF(K32="N.A.",0)+IF(K32="Baixo",1)+IF(K32="Moderado",2)+IF(K32="Significativo",4)+IF(K32="Alto",6) -> 0 | M32: =IF(L32>0,1,0) -> 0 | O32: =IF(N32="N.A.",0)+IF(N32="Baixo",1)+IF(N32="Moderado",2)+IF(N32="Significativo",4)+IF(N32="Alto",6) -> 0 | P32: =IF(O32>0,1,0) -> 0 | R32: =IF(Q32="N.A.",0)+IF(Q32="Baixo",1)+IF(Q32="Moderado",2)+IF(Q32="Significativo",4)+IF(Q32="Alto",6) -> 0 | S32: =IF(R32>0,1,0) -> 0 | T32: =SUM(G32,J32,M32,P32,S32) -> 0 | U32: =IFERROR(SUM(F32,I32,L32,O32,R32)/T32,0) -> 0 | AA32: =IF(W32="X",0)+IF(X32="X",2)+IF(Y32="X",4)+IF(Z32="X",9) -> 0 | AF32: =IF(AC32="X",1)+IF(AD32="X",2)+IF(AE32="X",5) -> 0 | AN32: =IF(AH32="X",1)+IF(AI32="X",2)+IF(AJ32="X",3)+IF(AK32="X",4)+IF(AL32="X",5)+IF(AM32="X",6) -> 0 | AP32: =AA32+AF32+AN32 -> 0 | AQ32: =(AP32+U32)/2 -> 0 | AR32: =IF(AS32="",0,10) -> 0 | AS32: =IF(AX32=TRUE,"Desprezível",IF(AY32=TRUE,"Administrável",IF(AZ32=TRUE,"Indesejável",IF(BA32=TRUE,"Intolerável","")))) | AX32: =AND(U32>0,U32<=2,AP32>0,AP32<=7) -> FALSE | AY32: =OR(AND(U32>0,U32<=2,AP32>0,AP32>7,AP32<=13),AND(U32>0,U32>2,U32<=3,AP32>0,AP32<=10)) -> FALSE | AZ32: =OR(AND(U32>0,U32<=2,AP32>0,AP32>12,AP32<=17),AND(U32>0,U32>2,U32<=3,AP32>0,AP32>10,AP32<=13),AND(U32>0,U32>3,U32<=5,AP32>0,AP32<=10),AND(U32>0,U32>4,U32<=6,AP32>0,AP32<=7)) -> FALSE | BA32: =OR(AND(U32>0,U32>2,U32<=3,AP32>0,AP32>14,AP32<=20),AND(U32>0,U32>3,U32<=5,AP32>0,AP32>10),AND(U32>0,U32>5,U32<=6,AP32>0,AP32>7,AP32<=20)) -> FALSE
F33: =IF(E33="N.A.",0)+IF(E33="Baixo",1)+IF(E33="Moderado",2)+IF(E33="Significativo",4)+IF(E33="Alto",6) -> 0 | G33: =IF(F33>0,1,0) -> 0 | I33: =IF(H33="N.A.",0)+IF(H33="Baixo",1)+IF(H33="Moderado",2)+IF(H33="Significativo",4)+IF(H33="Alto",6) -> 0 | J33: =IF(I33>0,1,0) -> 0 | L33: =IF(K33="N.A.",0)+IF(K33="Baixo",1)+IF(K33="Moderado",2)+IF(K33="Significativo",4)+IF(K33="Alto",6) -> 0 | M33: =IF(L33>0,1,0) -> 0 | O33: =IF(N33="N.A.",0)+IF(N33="Baixo",1)+IF(N33="Moderado",2)+IF(N33="Significativo",4)+IF(N33="Alto",6) -> 0 | P33: =IF(O33>0,1,0) -> 0 | R33: =IF(Q33="N.A.",0)+IF(Q33="Baixo",1)+IF(Q33="Moderado",2)+IF(Q33="Significativo",4)+IF(Q33="Alto",6) -> 0 | T33: =SUM(G33,J33,M33,P33,S33) -> 0 | U33: =IFERROR(SUM(F33,I33,L33,O33,R33)/T33,0) -> 0 | AA33: =IF(W33="X",0)+IF(X33="X",2)+IF(Y33="X",4)+IF(Z33="X",9) -> 0 | AF33: =IF(AC33="X",1)+IF(AD33="X",2)+IF(AE33="X",5) -> 0 | AZ33: =OR(AND(U33>0,U33<=2,AP33>0,AP33>12,AP33<=17),AND(U33>0,U33>2,U33<=3,AP33>0,AP33>10,AP33<=13),AND(U33>0,U33>3,U33<=5,AP33>0,AP33<=10),AND(U33>0,U33>4,U33<=6,AP33>0,AP33<=7)) -> FALSE | BA33: =OR(AND(U33>0,U33>2,U33<=3,AP33>0,AP33>14,AP33<=20),AND(U33>0,U33>3,U33<=5,AP33>0,AP33>10),AND(U33>0,U33>5,U33<=6,AP33>0,AP33>7,AP33<=20)) -> FALSE
B34: 13. | F34: =IF(E34="N.A.",0)+IF(E34="Baixo",1)+IF(E34="Moderado",2)+IF(E34="Significativo",4)+IF(E34="Alto",6) -> 0 | G34: =IF(F34>0,1,0) -> 0 | I34: =IF(H34="N.A.",0)+IF(H34="Baixo",1)+IF(H34="Moderado",2)+IF(H34="Significativo",4)+IF(H34="Alto",6) -> 0 | J34: =IF(I34>0,1,0) -> 0 | L34: =IF(K34="N.A.",0)+IF(K34="Baixo",1)+IF(K34="Moderado",2)+IF(K34="Significativo",4)+IF(K34="Alto",6) -> 0 | M34: =IF(L34>0,1,0) -> 0 | O34: =IF(N34="N.A.",0)+IF(N34="Baixo",1)+IF(N34="Moderado",2)+IF(N34="Significativo",4)+IF(N34="Alto",6) -> 0 | P34: =IF(O34>0,1,0) -> 0 | R34: =IF(Q34="N.A.",0)+IF(Q34="Baixo",1)+IF(Q34="Moderado",2)+IF(Q34="Significativo",4)+IF(Q34="Alto",6) -> 0 | S34: =IF(R34>0,1,0) -> 0 | T34: =SUM(G34,J34,M34,P34,S34) -> 0 | U34: =IFERROR(SUM(F34,I34,L34,O34,R34)/T34,0) -> 0 | AA34: =IF(W34="X",0)+IF(X34="X",2)+IF(Y34="X",4)+IF(Z34="X",9) -> 0 | AF34: =IF(AC34="X",1)+IF(AD34="X",2)+IF(AE34="X",5) -> 0 | AN34: =IF(AH34="X",1)+IF(AI34="X",2)+IF(AJ34="X",3)+IF(AK34="X",4)+IF(AL34="X",5)+IF(AM34="X",6) -> 0 | AP34: =AA34+AF34+AN34 -> 0 | AQ34: =(AP34+U34)/2 -> 0 | AR34: =IF(AS34="",0,10) -> 0 | AS34: =IF(AX34=TRUE,"Desprezível",IF(AY34=TRUE,"Administrável",IF(AZ34=TRUE,"Indesejável",IF(BA34=TRUE,"Intolerável","")))) | AX34: =AND(U34>0,U34<=2,AP34>0,AP34<=7) -> FALSE | AY34: =OR(AND(U34>0,U34<=2,AP34>0,AP34>7,AP34<=13),AND(U34>0,U34>2,U34<=3,AP34>0,AP34<=10)) -> FALSE | AZ34: =OR(AND(U34>0,U34<=2,AP34>0,AP34>12,AP34<=17),AND(U34>0,U34>2,U34<=3,AP34>0,AP34>10,AP34<=13),AND(U34>0,U34>3,U34<=5,AP34>0,AP34<=10),AND(U34>0,U34>4,U34<=6,AP34>0,AP34<=7)) -> FALSE | BA34: =OR(AND(U34>0,U34>2,U34<=3,AP34>0,AP34>14,AP34<=20),AND(U34>0,U34>3,U34<=5,AP34>0,AP34>10),AND(U34>0,U34>5,U34<=6,AP34>0,AP34>7,AP34<=20)) -> FALSE
F35: =IF(E35="N.A.",0)+IF(E35="Baixo",1)+IF(E35="Moderado",2)+IF(E35="Significativo",4)+IF(E35="Alto",6) -> 0 | G35: =IF(F35>0,1,0) -> 0 | I35: =IF(H35="N.A.",0)+IF(H35="Baixo",1)+IF(H35="Moderado",2)+IF(H35="Significativo",4)+IF(H35="Alto",6) -> 0 | J35: =IF(I35>0,1,0) -> 0 | L35: =IF(K35="N.A.",0)+IF(K35="Baixo",1)+IF(K35="Moderado",2)+IF(K35="Significativo",4)+IF(K35="Alto",6) -> 0 | M35: =IF(L35>0,1,0) -> 0 | O35: =IF(N35="N.A.",0)+IF(N35="Baixo",1)+IF(N35="Moderado",2)+IF(N35="Significativo",4)+IF(N35="Alto",6) -> 0 | P35: =IF(O35>0,1,0) -> 0 | R35: =IF(Q35="N.A.",0)+IF(Q35="Baixo",1)+IF(Q35="Moderado",2)+IF(Q35="Significativo",4)+IF(Q35="Alto",6) -> 0 | T35: =SUM(G35,J35,M35,P35,S35) -> 0 | U35: =IFERROR(SUM(F35,I35,L35,O35,R35)/T35,0) -> 0 | AA35: =IF(W35="X",0)+IF(X35="X",2)+IF(Y35="X",4)+IF(Z35="X",9) -> 0 | AF35: =IF(AC35="X",1)+IF(AD35="X",2)+IF(AE35="X",5) -> 0 | AZ35: =OR(AND(U35>0,U35<=2,AP35>0,AP35>12,AP35<=17),AND(U35>0,U35>2,U35<=3,AP35>0,AP35>10,AP35<=13),AND(U35>0,U35>3,U35<=5,AP35>0,AP35<=10),AND(U35>0,U35>4,U35<=6,AP35>0,AP35<=7)) -> FALSE | BA35: =OR(AND(U35>0,U35>2,U35<=3,AP35>0,AP35>14,AP35<=20),AND(U35>0,U35>3,U35<=5,AP35>0,AP35>10),AND(U35>0,U35>5,U35<=6,AP35>0,AP35>7,AP35<=20)) -> FALSE
B36: 14. | F36: =IF(E36="N.A.",0)+IF(E36="Baixo",1)+IF(E36="Moderado",2)+IF(E36="Significativo",4)+IF(E36="Alto",6) -> 0 | G36: =IF(F36>0,1,0) -> 0 | I36: =IF(H36="N.A.",0)+IF(H36="Baixo",1)+IF(H36="Moderado",2)+IF(H36="Significativo",4)+IF(H36="Alto",6) -> 0 | J36: =IF(I36>0,1,0) -> 0 | L36: =IF(K36="N.A.",0)+IF(K36="Baixo",1)+IF(K36="Moderado",2)+IF(K36="Significativo",4)+IF(K36="Alto",6) -> 0 | M36: =IF(L36>0,1,0) -> 0 | O36: =IF(N36="N.A.",0)+IF(N36="Baixo",1)+IF(N36="Moderado",2)+IF(N36="Significativo",4)+IF(N36="Alto",6) -> 0 | P36: =IF(O36>0,1,0) -> 0 | R36: =IF(Q36="N.A.",0)+IF(Q36="Baixo",1)+IF(Q36="Moderado",2)+IF(Q36="Significativo",4)+IF(Q36="Alto",6) -> 0 | S36: =IF(R36>0,1,0) -> 0 | T36: =SUM(G36,J36,M36,P36,S36) -> 0 | U36: =IFERROR(SUM(F36,I36,L36,O36,R36)/T36,0) -> 0 | AA36: =IF(W36="X",0)+IF(X36="X",2)+IF(Y36="X",4)+IF(Z36="X",9) -> 0 | AF36: =IF(AC36="X",1)+IF(AD36="X",2)+IF(AE36="X",5) -> 0 | AN36: =IF(AH36="X",1)+IF(AI36="X",2)+IF(AJ36="X",3)+IF(AK36="X",4)+IF(AL36="X",5)+IF(AM36="X",6) -> 0 | AP36: =AA36+AF36+AN36 -> 0 | AQ36: =(AP36+U36)/2 -> 0 | AR36: =IF(AS36="",0,10) -> 0 | AS36: =IF(AX36=TRUE,"Desprezível",IF(AY36=TRUE,"Administrável",IF(AZ36=TRUE,"Indesejável",IF(BA36=TRUE,"Intolerável","")))) | AX36: =AND(U36>0,U36<=2,AP36>0,AP36<=7) -> FALSE | AY36: =OR(AND(U36>0,U36<=2,AP36>0,AP36>7,AP36<=13),AND(U36>0,U36>2,U36<=3,AP36>0,AP36<=10)) -> FALSE | AZ36: =OR(AND(U36>0,U36<=2,AP36>0,AP36>12,AP36<=17),AND(U36>0,U36>2,U36<=3,AP36>0,AP36>10,AP36<=13),AND(U36>0,U36>3,U36<=5,AP36>0,AP36<=10),AND(U36>0,U36>4,U36<=6,AP36>0,AP36<=7)) -> FALSE | BA36: =OR(AND(U36>0,U36>2,U36<=3,AP36>0,AP36>14,AP36<=20),AND(U36>0,U36>3,U36<=5,AP36>0,AP36>10),AND(U36>0,U36>5,U36<=6,AP36>0,AP36>7,AP36<=20)) -> FALSE
F37: =IF(E37="N.A.",0)+IF(E37="Baixo",1)+IF(E37="Moderado",2)+IF(E37="Significativo",4)+IF(E37="Alto",6) -> 0 | G37: =IF(F37>0,1,0) -> 0 | I37: =IF(H37="N.A.",0)+IF(H37="Baixo",1)+IF(H37="Moderado",2)+IF(H37="Significativo",4)+IF(H37="Alto",6) -> 0 | J37: =IF(I37>0,1,0) -> 0 | L37: =IF(K37="N.A.",0)+IF(K37="Baixo",1)+IF(K37="Moderado",2)+IF(K37="Significativo",4)+IF(K37="Alto",6) -> 0 | M37: =IF(L37>0,1,0) -> 0 | O37: =IF(N37="N.A.",0)+IF(N37="Baixo",1)+IF(N37="Moderado",2)+IF(N37="Significativo",4)+IF(N37="Alto",6) -> 0 | P37: =IF(O37>0,1,0) -> 0 | R37: =IF(Q37="N.A.",0)+IF(Q37="Baixo",1)+IF(Q37="Moderado",2)+IF(Q37="Significativo",4)+IF(Q37="Alto",6) -> 0 | T37: =SUM(G37,J37,M37,P37,S37) -> 0 | U37: =IFERROR(SUM(F37,I37,L37,O37,R37)/T37,0) -> 0 | AA37: =IF(W37="X",0)+IF(X37="X",2)+IF(Y37="X",4)+IF(Z37="X",9) -> 0 | AF37: =IF(AC37="X",1)+IF(AD37="X",2)+IF(AE37="X",5) -> 0 | AZ37: =OR(AND(U37>0,U37<=2,AP37>0,AP37>12,AP37<=17),AND(U37>0,U37>2,U37<=3,AP37>0,AP37>10,AP37<=13),AND(U37>0,U37>3,U37<=5,AP37>0,AP37<=10),AND(U37>0,U37>4,U37<=6,AP37>0,AP37<=7)) -> FALSE | BA37: =OR(AND(U37>0,U37>2,U37<=3,AP37>0,AP37>14,AP37<=20),AND(U37>0,U37>3,U37<=5,AP37>0,AP37>10),AND(U37>0,U37>5,U37<=6,AP37>0,AP37>7,AP37<=20)) -> FALSE
B38: 15. | F38: =IF(E38="N.A.",0)+IF(E38="Baixo",1)+IF(E38="Moderado",2)+IF(E38="Significativo",4)+IF(E38="Alto",6) -> 0 | G38: =IF(F38>0,1,0) -> 0 | I38: =IF(H38="N.A.",0)+IF(H38="Baixo",1)+IF(H38="Moderado",2)+IF(H38="Significativo",4)+IF(H38="Alto",6) -> 0 | J38: =IF(I38>0,1,0) -> 0 | L38: =IF(K38="N.A.",0)+IF(K38="Baixo",1)+IF(K38="Moderado",2)+IF(K38="Significativo",4)+IF(K38="Alto",6) -> 0 | M38: =IF(L38>0,1,0) -> 0 | O38: =IF(N38="N.A.",0)+IF(N38="Baixo",1)+IF(N38="Moderado",2)+IF(N38="Significativo",4)+IF(N38="Alto",6) -> 0 | P38: =IF(O38>0,1,0) -> 0 | R38: =IF(Q38="N.A.",0)+IF(Q38="Baixo",1)+IF(Q38="Moderado",2)+IF(Q38="Significativo",4)+IF(Q38="Alto",6) -> 0 | S38: =IF(R38>0,1,0) -> 0 | T38: =SUM(G38,J38,M38,P38,S38) -> 0 | U38: =IFERROR(SUM(F38,I38,L38,O38,R38)/T38,0) -> 0 | AA38: =IF(W38="X",0)+IF(X38="X",2)+IF(Y38="X",4)+IF(Z38="X",9) -> 0 | AF38: =IF(AC38="X",1)+IF(AD38="X",2)+IF(AE38="X",5) -> 0 | AN38: =IF(AH38="X",1)+IF(AI38="X",2)+IF(AJ38="X",3)+IF(AK38="X",4)+IF(AL38="X",5)+IF(AM38="X",6) -> 0 | AP38: =AA38+AF38+AN38 -> 0 | AQ38: =(AP38+U38)/2 -> 0 | AR38: =IF(AS38="",0,10) -> 0 | AS38: =IF(AX38=TRUE,"Desprezível",IF(AY38=TRUE,"Administrável",IF(AZ38=TRUE,"Indesejável",IF(BA38=TRUE,"Intolerável","")))) | AX38: =AND(U38>0,U38<=2,AP38>0,AP38<=7) -> FALSE | AY38: =OR(AND(U38>0,U38<=2,AP38>0,AP38>7,AP38<=13),AND(U38>0,U38>2,U38<=3,AP38>0,AP38<=10)) -> FALSE | AZ38: =OR(AND(U38>0,U38<=2,AP38>0,AP38>12,AP38<=17),AND(U38>0,U38>2,U38<=3,AP38>0,AP38>10,AP38<=13),AND(U38>0,U38>3,U38<=5,AP38>0,AP38<=10),AND(U38>0,U38>4,U38<=6,AP38>0,AP38<=7)) -> FALSE | BA38: =OR(AND(U38>0,U38>2,U38<=3,AP38>0,AP38>14,AP38<=20),AND(U38>0,U38>3,U38<=5,AP38>0,AP38>10),AND(U38>0,U38>5,U38<=6,AP38>0,AP38>7,AP38<=20)) -> FALSE
F39: =IF(E39="N.A.",0)+IF(E39="Baixo",1)+IF(E39="Moderado",2)+IF(E39="Significativo",4)+IF(E39="Alto",6) -> 0 | G39: =IF(F39>0,1,0) -> 0 | I39: =IF(H39="N.A.",0)+IF(H39="Baixo",1)+IF(H39="Moderado",2)+IF(H39="Significativo",4)+IF(H39="Alto",6) -> 0 | J39: =IF(I39>0,1,0) -> 0 | L39: =IF(K39="N.A.",0)+IF(K39="Baixo",1)+IF(K39="Moderado",2)+IF(K39="Significativo",4)+IF(K39="Alto",6) -> 0 | M39: =IF(L39>0,1,0) -> 0 | O39: =IF(N39="N.A.",0)+IF(N39="Baixo",1)+IF(N39="Moderado",2)+IF(N39="Significativo",4)+IF(N39="Alto",6) -> 0 | P39: =IF(O39>0,1,0) -> 0 | R39: =IF(Q39="N.A.",0)+IF(Q39="Baixo",1)+IF(Q39="Moderado",2)+IF(Q39="Significativo",4)+IF(Q39="Alto",6) -> 0 | T39: =SUM(G39,J39,M39,P39,S39) -> 0 | U39: =IFERROR(SUM(F39,I39,L39,O39,R39)/T39,0) -> 0 | AA39: =IF(W39="X",0)+IF(X39="X",2)+IF(Y39="X",4)+IF(Z39="X",9) -> 0 | AF39: =IF(AC39="X",1)+IF(AD39="X",2)+IF(AE39="X",5) -> 0 | AZ39: =OR(AND(U39>0,U39<=2,AP39>0,AP39>12,AP39<=17),AND(U39>0,U39>2,U39<=3,AP39>0,AP39>10,AP39<=13),AND(U39>0,U39>3,U39<=5,AP39>0,AP39<=10),AND(U39>0,U39>4,U39<=6,AP39>0,AP39<=7)) -> FALSE | BA39: =OR(AND(U39>0,U39>2,U39<=3,AP39>0,AP39>14,AP39<=20),AND(U39>0,U39>3,U39<=5,AP39>0,AP39>10),AND(U39>0,U39>5,U39<=6,AP39>0,AP39>7,AP39<=20)) -> FALSE
B40: 16. | F40: =IF(E40="N.A.",0)+IF(E40="Baixo",1)+IF(E40="Moderado",2)+IF(E40="Significativo",4)+IF(E40="Alto",6) -> 0 | G40: =IF(F40>0,1,0) -> 0 | I40: =IF(H40="N.A.",0)+IF(H40="Baixo",1)+IF(H40="Moderado",2)+IF(H40="Significativo",4)+IF(H40="Alto",6) -> 0 | J40: =IF(I40>0,1,0) -> 0 | L40: =IF(K40="N.A.",0)+IF(K40="Baixo",1)+IF(K40="Moderado",2)+IF(K40="Significativo",4)+IF(K40="Alto",6) -> 0 | M40: =IF(L40>0,1,0) -> 0 | O40: =IF(N40="N.A.",0)+IF(N40="Baixo",1)+IF(N40="Moderado",2)+IF(N40="Significativo",4)+IF(N40="Alto",6) -> 0 | P40: =IF(O40>0,1,0) -> 0 | R40: =IF(Q40="N.A.",0)+IF(Q40="Baixo",1)+IF(Q40="Moderado",2)+IF(Q40="Significativo",4)+IF(Q40="Alto",6) -> 0 | S40: =IF(R40>0,1,0) -> 0 | T40: =SUM(G40,J40,M40,P40,S40) -> 0 | U40: =IFERROR(SUM(F40,I40,L40,O40,R40)/T40,0) -> 0 | AA40: =IF(W40="X",0)+IF(X40="X",2)+IF(Y40="X",4)+IF(Z40="X",9) -> 0 | AF40: =IF(AC40="X",1)+IF(AD40="X",2)+IF(AE40="X",5) -> 0 | AN40: =IF(AH40="X",1)+IF(AI40="X",2)+IF(AJ40="X",3)+IF(AK40="X",4)+IF(AL40="X",5)+IF(AM40="X",6) -> 0 | AP40: =AA40+AF40+AN40 -> 0 | AQ40: =(AP40+U40)/2 -> 0 | AR40: =IF(AS40="",0,10) -> 0 | AS40: =IF(AX40=TRUE,"Desprezível",IF(AY40=TRUE,"Administrável",IF(AZ40=TRUE,"Indesejável",IF(BA40=TRUE,"Intolerável","")))) | AX40: =AND(U40>0,U40<=2,AP40>0,AP40<=7) -> FALSE | AY40: =OR(AND(U40>0,U40<=2,AP40>0,AP40>7,AP40<=13),AND(U40>0,U40>2,U40<=3,AP40>0,AP40<=10)) -> FALSE | AZ40: =OR(AND(U40>0,U40<=2,AP40>0,AP40>12,AP40<=17),AND(U40>0,U40>2,U40<=3,AP40>0,AP40>10,AP40<=13),AND(U40>0,U40>3,U40<=5,AP40>0,AP40<=10),AND(U40>0,U40>4,U40<=6,AP40>0,AP40<=7)) -> FALSE | BA40: =OR(AND(U40>0,U40>2,U40<=3,AP40>0,AP40>14,AP40<=20),AND(U40>0,U40>3,U40<=5,AP40>0,AP40>10),AND(U40>0,U40>5,U40<=6,AP40>0,AP40>7,AP40<=20)) -> FALSE
F41: =IF(E41="N.A.",0)+IF(E41="Baixo",1)+IF(E41="Moderado",2)+IF(E41="Significativo",4)+IF(E41="Alto",6) -> 0 | G41: =IF(F41>0,1,0) -> 0 | I41: =IF(H41="N.A.",0)+IF(H41="Baixo",1)+IF(H41="Moderado",2)+IF(H41="Significativo",4)+IF(H41="Alto",6) -> 0 | J41: =IF(I41>0,1,0) -> 0 | L41: =IF(K41="N.A.",0)+IF(K41="Baixo",1)+IF(K41="Moderado",2)+IF(K41="Significativo",4)+IF(K41="Alto",6) -> 0 | M41: =IF(L41>0,1,0) -> 0 | O41: =IF(N41="N.A.",0)+IF(N41="Baixo",1)+IF(N41="Moderado",2)+IF(N41="Significativo",4)+IF(N41="Alto",6) -> 0 | P41: =IF(O41>0,1,0) -> 0 | R41: =IF(Q41="N.A.",0)+IF(Q41="Baixo",1)+IF(Q41="Moderado",2)+IF(Q41="Significativo",4)+IF(Q41="Alto",6) -> 0 | T41: =SUM(G41,J41,M41,P41,S41) -> 0 | U41: =IFERROR(SUM(F41,I41,L41,O41,R41)/T41,0) -> 0 | AA41: =IF(W41="X",0)+IF(X41="X",2)+IF(Y41="X",4)+IF(Z41="X",9) -> 0 | AF41: =IF(AC41="X",1)+IF(AD41="X",2)+IF(AE41="X",5) -> 0 | AZ41: =OR(AND(U41>0,U41<=2,AP41>0,AP41>12,AP41<=17),AND(U41>0,U41>2,U41<=3,AP41>0,AP41>10,AP41<=13),AND(U41>0,U41>3,U41<=5,AP41>0,AP41<=10),AND(U41>0,U41>4,U41<=6,AP41>0,AP41<=7)) -> FALSE | BA41: =OR(AND(U41>0,U41>2,U41<=3,AP41>0,AP41>14,AP41<=20),AND(U41>0,U41>3,U41<=5,AP41>0,AP41>10),AND(U41>0,U41>5,U41<=6,AP41>0,AP41>7,AP41<=20)) -> FALSE
B42: 17. | F42: =IF(E42="N.A.",0)+IF(E42="Baixo",1)+IF(E42="Moderado",2)+IF(E42="Significativo",4)+IF(E42="Alto",6) -> 0 | G42: =IF(F42>0,1,0) -> 0 | I42: =IF(H42="N.A.",0)+IF(H42="Baixo",1)+IF(H42="Moderado",2)+IF(H42="Significativo",4)+IF(H42="Alto",6) -> 0 | J42: =IF(I42>0,1,0) -> 0 | L42: =IF(K42="N.A.",0)+IF(K42="Baixo",1)+IF(K42="Moderado",2)+IF(K42="Significativo",4)+IF(K42="Alto",6) -> 0 | M42: =IF(L42>0,1,0) -> 0 | O42: =IF(N42="N.A.",0)+IF(N42="Baixo",1)+IF(N42="Moderado",2)+IF(N42="Significativo",4)+IF(N42="Alto",6) -> 0 | P42: =IF(O42>0,1,0) -> 0 | R42: =IF(Q42="N.A.",0)+IF(Q42="Baixo",1)+IF(Q42="Moderado",2)+IF(Q42="Significativo",4)+IF(Q42="Alto",6) -> 0 | S42: =IF(R42>0,1,0) -> 0 | T42: =SUM(G42,J42,M42,P42,S42) -> 0 | U42: =IFERROR(SUM(F42,I42,L42,O42,R42)/T42,0) -> 0 | AA42: =IF(W42="X",0)+IF(X42="X",2)+IF(Y42="X",4)+IF(Z42="X",9) -> 0 | AF42: =IF(AC42="X",1)+IF(AD42="X",2)+IF(AE42="X",5) -> 0 | AN42: =IF(AH42="X",1)+IF(AI42="X",2)+IF(AJ42="X",3)+IF(AK42="X",4)+IF(AL42="X",5)+IF(AM42="X",6) -> 0 | AP42: =AA42+AF42+AN42 -> 0 | AQ42: =(AP42+U42)/2 -> 0 | AR42: =IF(AS42="",0,10) -> 0 | AS42: =IF(AX42=TRUE,"Desprezível",IF(AY42=TRUE,"Administrável",IF(AZ42=TRUE,"Indesejável",IF(BA42=TRUE,"Intolerável","")))) | AX42: =AND(U42>0,U42<=2,AP42>0,AP42<=7) -> FALSE | AY42: =OR(AND(U42>0,U42<=2,AP42>0,AP42>7,AP42<=13),AND(U42>0,U42>2,U42<=3,AP42>0,AP42<=10)) -> FALSE | AZ42: =OR(AND(U42>0,U42<=2,AP42>0,AP42>12,AP42<=17),AND(U42>0,U42>2,U42<=3,AP42>0,AP42>10,AP42<=13),AND(U42>0,U42>3,U42<=5,AP42>0,AP42<=10),AND(U42>0,U42>4,U42<=6,AP42>0,AP42<=7)) -> FALSE | BA42: =OR(AND(U42>0,U42>2,U42<=3,AP42>0,AP42>14,AP42<=20),AND(U42>0,U42>3,U42<=5,AP42>0,AP42>10),AND(U42>0,U42>5,U42<=6,AP42>0,AP42>7,AP42<=20)) -> FALSE
F43: =IF(E43="N.A.",0)+IF(E43="Baixo",1)+IF(E43="Moderado",2)+IF(E43="Significativo",4)+IF(E43="Alto",6) -> 0 | G43: =IF(F43>0,1,0) -> 0 | I43: =IF(H43="N.A.",0)+IF(H43="Baixo",1)+IF(H43="Moderado",2)+IF(H43="Significativo",4)+IF(H43="Alto",6) -> 0 | J43: =IF(I43>0,1,0) -> 0 | L43: =IF(K43="N.A.",0)+IF(K43="Baixo",1)+IF(K43="Moderado",2)+IF(K43="Significativo",4)+IF(K43="Alto",6) -> 0 | M43: =IF(L43>0,1,0) -> 0 | O43: =IF(N43="N.A.",0)+IF(N43="Baixo",1)+IF(N43="Moderado",2)+IF(N43="Significativo",4)+IF(N43="Alto",6) -> 0 | P43: =IF(O43>0,1,0) -> 0 | R43: =IF(Q43="N.A.",0)+IF(Q43="Baixo",1)+IF(Q43="Moderado",2)+IF(Q43="Significativo",4)+IF(Q43="Alto",6) -> 0 | T43: =SUM(G43,J43,M43,P43,S43) -> 0 | U43: =IFERROR(SUM(F43,I43,L43,O43,R43)/T43,0) -> 0 | AA43: =IF(W43="X",0)+IF(X43="X",2)+IF(Y43="X",4)+IF(Z43="X",9) -> 0 | AF43: =IF(AC43="X",1)+IF(AD43="X",2)+IF(AE43="X",5) -> 0 | AZ43: =OR(AND(U43>0,U43<=2,AP43>0,AP43>12,AP43<=17),AND(U43>0,U43>2,U43<=3,AP43>0,AP43>10,AP43<=13),AND(U43>0,U43>3,U43<=5,AP43>0,AP43<=10),AND(U43>0,U43>4,U43<=6,AP43>0,AP43<=7)) -> FALSE | BA43: =OR(AND(U43>0,U43>2,U43<=3,AP43>0,AP43>14,AP43<=20),AND(U43>0,U43>3,U43<=5,AP43>0,AP43>10),AND(U43>0,U43>5,U43<=6,AP43>0,AP43>7,AP43<=20)) -> FALSE
B44: 18. | F44: =IF(E44="N.A.",0)+IF(E44="Baixo",1)+IF(E44="Moderado",2)+IF(E44="Significativo",4)+IF(E44="Alto",6) -> 0 | G44: =IF(F44>0,1,0) -> 0 | I44: =IF(H44="N.A.",0)+IF(H44="Baixo",1)+IF(H44="Moderado",2)+IF(H44="Significativo",4)+IF(H44="Alto",6) -> 0 | J44: =IF(I44>0,1,0) -> 0 | L44: =IF(K44="N.A.",0)+IF(K44="Baixo",1)+IF(K44="Moderado",2)+IF(K44="Significativo",4)+IF(K44="Alto",6) -> 0 | M44: =IF(L44>0,1,0) -> 0 | O44: =IF(N44="N.A.",0)+IF(N44="Baixo",1)+IF(N44="Moderado",2)+IF(N44="Significativo",4)+IF(N44="Alto",6) -> 0 | P44: =IF(O44>0,1,0) -> 0 | R44: =IF(Q44="N.A.",0)+IF(Q44="Baixo",1)+IF(Q44="Moderado",2)+IF(Q44="Significativo",4)+IF(Q44="Alto",6) -> 0 | S44: =IF(R44>0,1,0) -> 0 | T44: =SUM(G44,J44,M44,P44,S44) -> 0 | U44: =IFERROR(SUM(F44,I44,L44,O44,R44)/T44,0) -> 0 | AA44: =IF(W44="X",0)+IF(X44="X",2)+IF(Y44="X",4)+IF(Z44="X",9) -> 0 | AF44: =IF(AC44="X",1)+IF(AD44="X",2)+IF(AE44="X",5) -> 0 | AN44: =IF(AH44="X",1)+IF(AI44="X",2)+IF(AJ44="X",3)+IF(AK44="X",4)+IF(AL44="X",5)+IF(AM44="X",6) -> 0 | AP44: =AA44+AF44+AN44 -> 0 | AQ44: =(AP44+U44)/2 -> 0 | AR44: =IF(AS44="",0,10) -> 0 | AS44: =IF(AX44=TRUE,"Desprezível",IF(AY44=TRUE,"Administrável",IF(AZ44=TRUE,"Indesejável",IF(BA44=TRUE,"Intolerável","")))) | AX44: =AND(U44>0,U44<=2,AP44>0,AP44<=7) -> FALSE | AY44: =OR(AND(U44>0,U44<=2,AP44>0,AP44>7,AP44<=13),AND(U44>0,U44>2,U44<=3,AP44>0,AP44<=10)) -> FALSE | AZ44: =OR(AND(U44>0,U44<=2,AP44>0,AP44>12,AP44<=17),AND(U44>0,U44>2,U44<=3,AP44>0,AP44>10,AP44<=13),AND(U44>0,U44>3,U44<=5,AP44>0,AP44<=10),AND(U44>0,U44>4,U44<=6,AP44>0,AP44<=7)) -> FALSE | BA44: =OR(AND(U44>0,U44>2,U44<=3,AP44>0,AP44>14,AP44<=20),AND(U44>0,U44>3,U44<=5,AP44>0,AP44>10),AND(U44>0,U44>5,U44<=6,AP44>0,AP44>7,AP44<=20)) -> FALSE
...

Sheet Ações-Riscos-CANTU
B2: Ações para tratar riscos
C6: Identificação de Riscos | E6: Significância
B7: Item | G7: BOM/RO/GR | I7: Responsável | K7: Ações / Monitoramento
B10: ='[1]Riscos-CANTU'!B10 -> 1. | C10: ='[1]Riscos-CANTU'!C10 -> Comercial - Vacância | E10: ='[1]Riscos-CANTU'!AS10 -> Administrável | K10: a) gestão comercial: vacância em R$ de 5,7%; em ABL de 9,96%, base set.2020;
I11: Ana Cristina | K11: b) negociações pontuais com locatários visando evitar a desocupação;
K12: c) imóvel de Fortaleza representa 15% do custo mensal (R$ 27k)
B14: ='[1]Riscos-CANTU'!B12 -> 2. | C14: ='[1]Riscos-CANTU'!C12 -> Eventos de Sinistros em Imóveis | E14: ='[1]Riscos-CANTU'!AS12 -> Administrável | K14: a) seguro dos imóveis:
I15: Ana Cristina | K15: b) segurança ou monitoramento nos imóveis desocupados;
B18: ='[1]Riscos-CANTU'!B14 -> 3. | C18: ='[1]Riscos-CANTU'!C14 -> Novos Negócios - Aquisição de Imóveis | E18: ='[1]Riscos-CANTU'!AS14 -> Administrável | K18: a) procedimento de análise de viabilidade;
I19: Nelson | K19: b) apresentação e aprovação do Conselho;
B22: ='[1]Riscos-CANTU'!B16 -> 4. | C22: ='[1]Riscos-CANTU'!C16 -> Novos Negócios - Definição do Produto | E22: ='[1]Riscos-CANTU'!AS16 -> Administrável | K22: a) pesquisa de mercado;
I23: Nelson | K23: b) busca de negócios com locação "casada";
K24: c) viabilidade apresentada e aprovada pelo Conselho;
B26: ='[1]Riscos-CANTU'!B18 -> 5. | C26: ='[1]Riscos-CANTU'!C18 -> Assistência Técnica - Conservação dos Imóveis | E26: ='[1]Riscos-CANTU'!AS18 -> Administrável | K26: a) manutenção corretiva;
I27: Ana Cristina | K27: b) manutenção e controle preventivo (futura equip. de manutenção da Piemonte);
B30: ='[1]Riscos-CANTU'!B20 -> 6. | C30: ='[1]Riscos-CANTU'!C20 -> Administrativo - Inadimplência | E30: ='[1]Riscos-CANTU'!AS20 -> Administrável | K30: a) acompanhamento por evento;
I31: Ana Cristina | K31: b) procedimentos jurídicos;
B34: ='[1]Riscos-CANTU'!B22 -> 7. | C34: ='[1]Riscos-CANTU'!C22 -> Redução de faturamento em decorrência de Pandemias "Covid-19" | E34: ='[1]Riscos-CANTU'!AS22 -> Administrável | K34: a) acompanhamento por evento;
I35: Ana Cristina | K35: b) buscar negociações;
B38: ='[1]Riscos-CANTU'!B24 -> 8. | C38: ='[1]Riscos-CANTU'!C24 -> 0 | E38: ='[1]Riscos-CANTU'!AS24
B42: ='[1]Riscos-CANTU'!B26 -> 9. | C42: ='[1]Riscos-CANTU'!C26 -> 0 | E42: ='[1]Riscos-CANTU'!AS26
B46: ='[1]Riscos-CANTU'!B28 -> 10. | C46: ='[1]Riscos-CANTU'!C28 -> 0 | E46: ='[1]Riscos-CANTU'!AS28
B50: ='[1]Riscos-CANTU'!B30 -> 11. | C50: ='[1]Riscos-CANTU'!C30 -> 0 | E50: ='[1]Riscos-CANTU'!AS30
B54: ='[1]Riscos-CANTU'!B32 -> 12. | C54: ='[1]Riscos-CANTU'!C32 -> 0 | E54: ='[1]Riscos-CANTU'!AS32
B58: ='[1]Riscos-CANTU'!B34 -> 13. | C58: ='[1]Riscos-CANTU'!C34 -> 0 | E58: ='[1]Riscos-CANTU'!AS34
B62: ='[1]Riscos-CANTU'!B36 -> 14. | C62: ='[1]Riscos-CANTU'!C36 -> 0 | E62: ='[1]Riscos-CANTU'!AS36
B66: ='[1]Riscos-CANTU'!B38 -> 15. | C66: ='[1]Riscos-CANTU'!C38 -> 0 | E66: ='[1]Riscos-CANTU'!AS38
B70: ='[1]Riscos-CANTU'!B40 -> 16. | C70: ='[1]Riscos-CANTU'!C40 -> 0 | E70: ='[1]Riscos-CANTU'!AS40
B74: ='[1]Riscos-CANTU'!B42 -> 17. | C74: ='[1]Riscos-CANTU'!C42 -> 0 | E74: ='[1]Riscos-CANTU'!AS42
B78: ='[1]Riscos-CANTU'!B44 -> 18. | C78: ='[1]Riscos-CANTU'!C44 -> 0 | E78: ='[1]Riscos-CANTU'!AS44
B82: ='[1]Riscos-CANTU'!B46 -> 19. | C82: ='[1]Riscos-CANTU'!C46 -> 0 | E82: ='[1]Riscos-CANTU'!AS46
B86: ='[1]Riscos-CANTU'!B48 -> 20. | C86: ='[1]Riscos-CANTU'!C48 -> 0 | E86: ='[1]Riscos-CANTU'!AS48
B90: ='[1]Riscos-CANTU'!#REF! -> #REF! | C90: ='[1]Riscos-CANTU'!#REF! -> #REF! | E90: ='[1]Riscos-CANTU'!#REF! -> #REF!

Sheet Oportunidades-CANTU
E1: Matriz de Avaliação e Gestão de Oportunidades
E4: GESTÃO DE PROPRIEDADES
B6: Item | C6: Oportunidade | E6: Avaliação de Impacto | W6: Condição para Implantação / Execução | AT6: Valor Agregado | AV6: Estratégia | AY6: Valor Agregado
E7: Financeiro | F7: Pontos | G7: Inf. Média | H7: Legal | I7: Pontos | J7: Inf. Média | K7: Imagem | L7: Pontos | M7: Inf. Média | N7: Direcionamento Estratégico | O7: Pontos | P7: Inf. Média | Q7: Operação | R7: Pontos | S7: Inf. Média | W7: Prazo | AB7: Pontos | AD7: Complexidade | AI7: Pontos | AK7: Payback (ROI) | AP7: Pontos
U8: Impacto | W8: Muito Curto | X8: Curto | Y8: Médio | Z8: Longo | AA8: Muito Longo | AD8: Nenhuma | AE8: Baixa | AF8: Média | AG8: Alta | AH8: Muito Alta | AK8: Imediato | AL8: Curto Prazo | AM8: Médio Prazo | AN8: Longo Prazo | AO8: Muito Longo | AQ8: Probabilidade | AR8: Média | AY8: Baixo | AZ8: Médio | BA8: Alto | BB8: Muito Alto
