Workbook
Name \0: #N/A
Name \1: #REF!
Name \a: #REF!
Name \e: #N/A
Name \m: [1]TUBULÃO!#REF!
Name \s: #N/A
Name _________________la29: #REF!
Name _________________la3: #REF!
Name _________________la31: #REF!
Name _________________la32: #REF!
Name _________________la4: #REF!
Name _________________la5: #REF!
Name _________________la6: #REF!
Name _________________la7: #REF!
Name _________________la8: #REF!
Name _________________la9: #REF!
Name _________________lb1: #REF!
Name _________________lb10: #REF!
Name _________________lb11: #REF!
Name _________________lb12: #REF!
Name _________________lb13: #REF!
Name _________________lb14: #REF!
Name _________________lb15: #REF!
Name _________________lb16: #REF!
Name _________________lb17: #REF!
Name _________________lb18: #REF!
Name _________________lb19: #REF!
Name _________________lb2: #REF!
Name _________________lb20: #REF!
Name _________________lb21: #REF!
Name _________________lb22: #REF!
Name _________________lb23: #REF!
Name _________________lb24: #REF!
Name _________________lb25: #REF!
Name _________________lb27: #REF!
Name _________________lb28: #REF!
Name _________________lb29: #REF!
Name _________________lb3: #REF!
Name _________________lb30: #REF!
Name _________________lb31: #REF!
Name _________________lb32: #REF!
Name _________________lb4: #REF!
Name _________________lb5: #REF!
Name _________________lb6: #REF!
Name _________________lb7: #REF!
Name _________________lb8: #REF!
Name _________________lb9: #REF!
Name _________________lbc1: #REF!
Name _________________lbc10: #REF!
Name _________________lbc11: #REF!
Name _________________lbc12: #REF!
Name _________________lbc13: #REF!
Name _________________lbc14: #REF!
Name _________________lbc15: #REF!
Name _________________lbc16: #REF!
Name _________________lbc17: #REF!
Name _________________lbc18: #REF!
Name _________________lbc19: #REF!
Name _________________lbc2: #REF!
Name _________________lbc20: #REF!

Sheet Miragio
I2: INCC - M (Abr/23) | L2: INCC - M (Mai/23) | O2: INCC - M (Jun/23) | R2: INCC - M (Jul/23)
B3: INCC - Base | C3: 44075 | D3: 810.965 | I3: 1061.071 | L3: 1065.289 | O3: 1074.292 | R3: 1074.895
A4: Orçamento base | C4: Periodo | E4: Prazo | F4: Valor total | G4: Valor unitário | I4: Medição - Maio 2023 | L4: Medição - Junho 2023 | O4: Medição - Julho 2023 | R4: Medição - Agosto 2023
A5: 01.01.04.01 | B5: PESSOAL | C5: 44166 | D5: 45139 | I5: Orç. Piemonte Reaj | J5: Medido Terceiros RM | K5: Valor MO ADM | L5: Orç. Piemonte Reaj | M5: Medido Terceiros RM | N5: Valor MO ADM | O5: Orç. Piemonte Reaj | P5: Medido Terceiros RM | Q5: Valor MO ADM | R5: Orç. Piemonte Reaj | S5: Medido Terceiros RM | T5: Valor MO ADM
A6: 01.01.04.01.001 | B6: ENGENHEIRO PRODUCAO | C6: 44166 | D6: 45139 | E6: 33 | F6: 462000 | G6: =F6/E6 -> 14000 | I6: =$G6*I$3/$D$3 -> 18317.676 | K6: =IF(J6>I6,0,I6-J6) -> 18317.676 | L6: =$G6*L$3/$D$3 -> 18390.493 | N6: =IF(M6>L6,0,L6-M6) -> 18390.493 | O6: =$G6*O$3/$D$3 -> 18545.915 | Q6: =IF(P6>O6,0,O6-P6) -> 18545.915 | R6: =$G6*R$3/$D$3 -> 18556.325 | T6: =IF(S6>R6,0,R6-S6) -> 18556.325
A7: 01.01.04.01.002 | B7: ENGENHEIRO SEGURANCA DO TRABALHO | C7: 44166 | D7: 45139 | E7: 33 | F7: 99000 | G7: =F7/E7 -> 3000 | I7: =$G7*I$3/$D$3 -> 3925.2163 | K7: =IF(J7>I7,0,I7-J7) -> 3925.2163 | L7: =$G7*L$3/$D$3 -> 3940.8199 | N7: =IF(M7>L7,0,L7-M7) -> 3940.8199 | O7: =$G7*O$3/$D$3 -> 3974.1247 | Q7: =IF(P7>O7,0,O7-P7) -> 3974.1247 | R7: =$G7*R$3/$D$3 -> 3976.3553 | T7: =IF(S7>R7,0,R7-S7) -> 3976.3553
A8: 01.01.04.01.003 | B8: MESTRE DE OBRAS | C8: 44166 | D8: 45139 | E8: 33 | F8: 409008.6 | G8: =F8/E8 -> 12394.2 | I8: =$G8*I$3/$D$3 -> 16216.638 | J8: 12244.56 | K8: =IF(J8>I8,0,I8-J8) -> 3972.0784 | L8: =$G8*L$3/$D$3 -> 16281.103 | M8: 12244.56 | N8: =IF(M8>L8,0,L8-M8) -> 4036.5433 | O8: =$G8*O$3/$D$3 -> 16418.699 | P8: 12244.56 | Q8: =IF(P8>O8,0,O8-P8) -> 4174.1386 | R8: =$G8*R$3/$D$3 -> 16427.914 | S8: 14448.58 | T8: =IF(S8>R8,0,R8-S8) -> 1979.3344
A9: 01.01.04.01.004 | B9: MESTRE DE OBRAS _EMPREITEIRA | C9: 44256 | D9: 45139 | E9: 30 | F9: 120000 | G9: =F9/E9 -> 4000 | I9: =$G9*I$3/$D$3 -> 5233.6217 | J9: =3636+453.41 -> 4089.41 | K9: =IF(J9>I9,0,I9-J9) -> 1144.2117 | L9: =$G9*L$3/$D$3 -> 5254.4265 | M9: =3636+453.41 -> 4089.41 | N9: =IF(M9>L9,0,L9-M9) -> 1165.0165 | O9: =$G9*O$3/$D$3 -> 5298.8329 | P9: =3636+453.41 -> 4089.41 | Q9: =IF(P9>O9,0,O9-P9) -> 1209.4229 | R9: =$G9*R$3/$D$3 -> 5301.8071 | S9: =3636+453.41 -> 4089.41 | T9: =IF(S9>R9,0,R9-S9) -> 1212.3971
A10: 01.01.04.01.005 | B10: CONTRA MESTRE | C10: 44166 | D10: 45139 | E10: 33 | F10: 189000 | G10: =F10/E10 -> 5727.2727 | I10: =$G10*I$3/$D$3 -> 7493.5947 | K10: =IF(J10>I10,0,I10-J10) -> 7493.5947 | L10: =$G10*L$3/$D$3 -> 7523.3834 | N10: =IF(M10>L10,0,L10-M10) -> 7523.3834 | O10: =$G10*O$3/$D$3 -> 7586.9652 | Q10: =IF(P10>O10,0,O10-P10) -> 7586.9652 | R10: =$G10*R$3/$D$3 -> 7591.2238 | T10: =IF(S10>R10,0,R10-S10) -> 7591.2238
A11: 01.01.04.01.006 | B11: ALMOXARIFE | C11: 44166 | D11: 45139 | E11: 33 | F11: 197174.34 | G11: =F11/E11 -> 5974.98 | I11: =$G11*I$3/$D$3 -> 7817.6962 | J11: =2799.72+349.13 -> 3148.85 | K11: =IF(J11>I11,0,I11-J11) -> 4668.8462 | L11: =$G11*L$3/$D$3 -> 7848.7733 | M11: =349.13+2799.72 -> 3148.85 | N11: =IF(M11>L11,0,L11-M11) -> 4699.9233 | O11: =$G11*O$3/$D$3 -> 7915.1051 | P11: =349.13+2799.72 -> 3148.85 | Q11: =IF(P11>O11,0,O11-P11) -> 4766.2551 | R11: =$G11*R$3/$D$3 -> 7919.5479 | S11: =349.13+2799.72 -> 3148.85 | T11: =IF(S11>R11,0,R11-S11) -> 4770.6979
A12: 01.01.04.01.007 | B12: TECNICO SEGURANCA_EMPREITEIRO | C12: 44256 | D12: 45139 | E12: 30 | F12: 87000 | G12: =F12/E12 -> 2900 | I12: =$G12*I$3/$D$3 -> 3794.3757 | J12: 2880 | K12: =IF(J12>I12,0,I12-J12) -> 914.37571 | L12: =$G12*L$3/$D$3 -> 3809.4592 | M12: 2880 | N12: =IF(M12>L12,0,L12-M12) -> 929.45922 | O12: =$G12*O$3/$D$3 -> 3841.6538 | P12: 2880 | Q12: =IF(P12>O12,0,O12-P12) -> 961.65383 | R12: =$G12*R$3/$D$3 -> 3843.8102 | S12: 2880 | T12: =IF(S12>R12,0,R12-S12) -> 963.81015
A13: 01.01.04.01.008 | B13: ADMINISTRATIVO DE OBRA | C13: 44166 | D13: 45139 | E13: 33 | F13: 221649.78 | G13: =F13/E13 -> 6716.66 | I13: =$G13*I$3/$D$3 -> 8788.1143 | K13: =IF(J13>I13,0,I13-J13) -> 8788.1143 | L13: =$G13*L$3/$D$3 -> 8823.0491 | N13: =IF(M13>L13,0,L13-M13) -> 8823.0491 | O13: =$G13*O$3/$D$3 -> 8897.6147 | Q13: =IF(P13>O13,0,O13-P13) -> 8897.6147 | R13: =$G13*R$3/$D$3 -> 8902.6089 | T13: =IF(S13>R13,0,R13-S13) -> 8902.6089
A14: 01.01.04.01.010 | B14: ESTAGIARIO (3X) | C14: 44166 | D14: 45139 | E14: 33 | F14: 143550 | G14: =F14/E14 -> 4350 | I14: =$G14*I$3/$D$3 -> 5691.5636 | K14: =IF(J14>I14,0,I14-J14) -> 5691.5636 | L14: =$G14*L$3/$D$3 -> 5714.1888 | N14: =IF(M14>L14,0,L14-M14) -> 5714.1888 | O14: =$G14*O$3/$D$3 -> 5762.4807 | Q14: =IF(P14>O14,0,O14-P14) -> 5762.4807 | R14: =$G14*R$3/$D$3 -> 5765.7152 | T14: =IF(S14>R14,0,R14-S14) -> 5765.7152
A15: 01.01.04.01.011 | B15: COORDENADOR DE OBRAS (1X) | C15: 44166 | D15: 45139 | E15: 33 | F15: 204430.38 | G15: =F15/E15 -> 6194.86 | I15: =$G15*I$3/$D$3 -> 8105.3884 | K15: =IF(J15>I15,0,I15-J15) -> 8105.3884 | L15: =$G15*L$3/$D$3 -> 8137.6092 | N15: =IF(M15>L15,0,L15-M15) -> 8137.6092 | O15: =$G15*O$3/$D$3 -> 8206.382 | Q15: =IF(P15>O15,0,O15-P15) -> 8206.382 | R15: =$G15*R$3/$D$3 -> 8210.9882 | T15: =IF(S15>R15,0,R15-S15) -> 8210.9882
A16: 01.01.04.01.012 | B16: TECNICO SEGURANCA (1X) | C16: 44166 | D16: 45139 | E16: 33 | F16: 132000 | G16: =F16/E16 -> 4000 | I16: =$G16*I$3/$D$3 -> 5233.6217 | K16: =IF(J16>I16,0,I16-J16) -> 5233.6217 | L16: =$G16*L$3/$D$3 -> 5254.4265 | N16: =IF(M16>L16,0,L16-M16) -> 5254.4265 | O16: =$G16*O$3/$D$3 -> 5298.8329 | Q16: =IF(P16>O16,0,O16-P16) -> 5298.8329 | R16: =$G16*R$3/$D$3 -> 5301.8071 | T16: =IF(S16>R16,0,R16-S16) -> 5301.8071
G17: =SUM(G6:G16) -> 69257.973 | I17: =SUM(I6:I16) -> 90617.507 | J17: =SUM(J6:J16) -> 22362.82 | K17: =SUM(K6:K16) -> 68254.687 | L17: =SUM(L6:L16) -> 90977.732 | M17: =SUM(M6:M16) -> 22362.82 | N17: =SUM(N6:N16) -> 68614.912 | O17: =SUM(O6:O16) -> 91746.606 | P17: =SUM(P6:P16) -> 22362.82 | ... T17: =SUM(T6:T16) -> 67231.263

Sheet IND. FIN.
A1: INCC - DI | H1: INCC - M | O1: CUB2006 MÉDIO | U1: Mês Vigente | V1: 46204 | W1: https://sindusconpr.com.br/incc-di-fgv-310-p
A2: (n) | C2: (n-1) | E2: (n-2) | H2: (n) | J2: (n-1) | L2: (n-2) | O2: (n) | Q2: (n-1) | S2: (n-2) | W2: https://sindusconpr.com.br/tabela-completa-370-p
A3: MÊS | B3: INDÍCE | C3: MÊS | D3: INDÍCE | E3: MÊS | F3: INDÍCE | H3: MÊS | I3: INDÍCE | J3: MÊS | K3: INDÍCE | L3: MÊS | M3: INDÍCE | O3: MÊS | P3: INDÍCE | Q3: MÊS | R3: INDÍCE | S3: MÊS | T3: INDÍCE | W3: https://sindusconpr.com.br/incc-m-fgv-1364-p
A4: 44197 | B4: 852.809 | C4: =A5 -> 44228 | D4: =B4 -> 852.809 | E4: =A6 -> 44256 | F4: =B4 -> 852.809 | H4: 44197 | I4: 850.495 | J4: =H5 -> 44228 | K4: =I4 -> 850.495 | L4: =H6 -> 44256 | M4: =I4 -> 850.495 | O4: 44197 | P4: 2273.96 | Q4: =O5 -> 44228 | R4: =P4 -> 2273.96 | S4: =O6 -> 44256 | T4: =P4 -> 2273.96
A5: 44228 | B5: 868.929 | C5: =A6 -> 44256 | D5: =B5 -> 868.929 | E5: =A7 -> 44287 | F5: =B5 -> 868.929 | H5: 44228 | I5: 859.573 | J5: =H6 -> 44256 | K5: =I5 -> 859.573 | L5: =H7 -> 44287 | M5: =I5 -> 859.573 | O5: 44228 | P5: 2293.94 | Q5: =O6 -> 44256 | R5: =P5 -> 2293.94 | S5: =O7 -> 44287 | T5: =P5 -> 2293.94
A6: 44256 | B6: 880.265 | C6: =A7 -> 44287 | D6: =B6 -> 880.265 | E6: =A8 -> 44317 | F6: =B6 -> 880.265 | H6: 44256 | I6: 876.75 | J6: =H7 -> 44287 | K6: =I6 -> 876.75 | L6: =H8 -> 44317 | M6: =I6 -> 876.75 | O6: 44256 | P6: 2323.15 | Q6: =O7 -> 44287 | R6: =P6 -> 2323.15 | S6: =O8 -> 44317 | T6: =P6 -> 2323.15
A7: 44287 | B7: 888.191 | C7: =A8 -> 44317 | D7: =B7 -> 888.191 | E7: =A9 -> 44348 | F7: =B7 -> 888.191 | H7: 44287 | I7: 885.093 | J7: =H8 -> 44317 | K7: =I7 -> 885.093 | L7: =H9 -> 44348 | M7: =I7 -> 885.093 | O7: 44287 | P7: 2357.58 | Q7: =O8 -> 44317 | R7: =P7 -> 2357.58 | S7: =O9 -> 44348 | T7: =P7 -> 2357.58
A8: 44317 | B8: 907.899 | C8: =A9 -> 44348 | D8: =B8 -> 907.899 | E8: =A10 -> 44378 | F8: =B8 -> 907.899 | H8: 44317 | I8: 901.032 | J8: =H9 -> 44348 | K8: =I8 -> 901.032 | L8: =H10 -> 44378 | M8: =I8 -> 901.032 | O8: 44317 | P8: 2394.27 | Q8: =O9 -> 44348 | R8: =P8 -> 2394.27 | S8: =O10 -> 44378 | T8: =P8 -> 2394.27
A9: 44348 | B9: 927.512 | C9: =A10 -> 44378 | D9: =B9 -> 927.512 | E9: =A11 -> 44409 | F9: =B9 -> 927.512 | H9: 44348 | I9: 921.762 | J9: =H10 -> 44378 | K9: =I9 -> 921.762 | L9: =H11 -> 44409 | M9: =I9 -> 921.762 | O9: 44348 | P9: 2441.78 | Q9: =O10 -> 44378 | R9: =P9 -> 2441.78 | S9: =O11 -> 44409 | T9: =P9 -> 2441.78
A10: 44378 | B10: 935.359 | C10: =A11 -> 44409 | D10: =B10 -> 935.359 | E10: =A12 -> 44440 | F10: =B10 -> 935.359 | H10: 44378 | I10: 933.23 | J10: =H11 -> 44409 | K10: =I10 -> 933.23 | L10: =H12 -> 44440 | M10: =I10 -> 933.23 | O10: 44378 | P10: 2497.79 | Q10: =O11 -> 44409 | R10: =P10 -> 2497.79 | S10: =O12 -> 44440 | T10: =P10 -> 2497.79
A11: 44409 | B11: 939.699 | C11: =A12 -> 44440 | D11: =B11 -> 939.699 | E11: =A13 -> 44470 | F11: =B11 -> 939.699 | H11: 44409 | I11: 938.475 | J11: =H12 -> 44440 | K11: =I11 -> 938.475 | L11: =H13 -> 44470 | M11: =I11 -> 938.475 | O11: 44409 | P11: 2523.29 | Q11: =O12 -> 44440 | R11: =P11 -> 2523.29 | S11: =O13 -> 44470 | T11: =P11 -> 2523.29
A12: 44440 | B12: 944.52 | C12: =A13 -> 44470 | D12: =B12 -> 944.52 | E12: =A14 -> 44501 | F12: =B12 -> 944.52 | H12: 44440 | I12: 943.736 | J12: =H13 -> 44470 | K12: =I12 -> 943.736 | L12: =H14 -> 44501 | M12: =I12 -> 943.736 | O12: 44440 | P12: 2551.83 | Q12: =O13 -> 44470 | R12: =P12 -> 2551.83 | S12: =O14 -> 44501 | T12: =P12 -> 2551.83
A13: 44470 | B13: 952.596 | C13: =A14 -> 44501 | D13: =B13 -> 952.596 | E13: =A15 -> 44531 | F13: =B13 -> 952.596 | H13: 44470 | I13: 951.249 | J13: =H14 -> 44501 | K13: =I13 -> 951.249 | L13: =H15 -> 44531 | M13: =I13 -> 951.249 | O13: 44470 | P13: 2577.05 | Q13: =O14 -> 44501 | R13: =P13 -> 2577.05 | S13: =O15 -> 44531 | T13: =P13 -> 2577.05
A14: 44501 | B14: 959.001 | C14: =A15 -> 44531 | D14: =B14 -> 959.001 | E14: =A16 -> 44562 | F14: =B14 -> 959.001 | H14: 44501 | I14: 957.984 | J14: =H15 -> 44531 | K14: =I14 -> 957.984 | L14: =H16 -> 44562 | M14: =I14 -> 957.984 | O14: 44501 | P14: 2603.53 | Q14: =O15 -> 44531 | R14: =P14 -> 2603.53 | S14: =O16 -> 44562 | T14: =P14 -> 2603.53
A15: 44531 | B15: 962.321 | C15: =A16 -> 44562 | D15: =B15 -> 962.321 | E15: =A17 -> 44593 | F15: =B15 -> 962.321 | H15: 44531 | I15: 960.894 | J15: =H16 -> 44562 | K15: =I15 -> 960.894 | L15: =H17 -> 44593 | M15: =I15 -> 960.894 | O15: 44531 | P15: 2617.93 | Q15: =O16 -> 44562 | R15: =P15 -> 2617.93 | S15: =O17 -> 44593 | T15: =P15 -> 2617.93
... A68: 46143 | B68: 1270.695 | C68: =A69 -> 46174 | D68: =B68 -> 1270.695 | E68: =A70 -> 46204 | F68: =B68 -> 1270.695 | H68: 46143 | I68: 1264.363 | J68: =H69 -> 46174 | K68: =I68 -> 1264.363 | L68: =H70 -> 46204 | M68: =I68 -> 1264.363 | O68: 46143 | P68: 3291.09 | Q68: =O69 -> 46174 | R68: =P68 -> 3291.09 | S68: =O70 -> 46204 | T68: =P68 -> 3291.09
A69: 46174 | B69: 1280.641 | C69: =A70 -> 46204 | D69: =B69 -> 1280.641 | E69: =A71 -> 46235 | F69: =B69 -> 1280.641 | H69: 46174 | I69: 1275.085 | J69: =H70 -> 46204 | K69: =I69 -> 1275.085 | L69: =H71 -> 46235 | M69: =I69 -> 1275.085 | O69: 46174 | Q69: =O70 -> 46204 | R69: =P69 -> 0 | S69: =O71 -> 46235 | T69: =P69 -> 0
A70: 46204 | C70: =A71 -> 46235 | D70: =B70 -> 0 | E70: =A72 -> 46266 | F70: =B70 -> 0 | H70: 46204 | J70: =H71 -> 46235 | K70: =I70 -> 0 | L70: =H72 -> 46266 | M70: =I70 -> 0 | O70: 46204 | Q70: =O71 -> 46235 | R70: =P70 -> 0 | S70: =O72 -> 46266 | T70: =P70 -> 0
A71: 46235 | C71: =A72 -> 46266 | D71: =B71 -> 0 | E71: =A73 -> 46296 | F71: =B71 -> 0 | H71: 46235 | J71: =H72 -> 46266 | K71: =I71 -> 0 | L71: =H73 -> 46296 | M71: =I71 -> 0 | O71: 46235 | Q71: =O72 -> 46266 | R71: =P71 -> 0 | S71: =O73 -> 46296 | T71: =P71 -> 0
A72: 46266 | C72: =A73 -> 46296 | D72: =B72 -> 0 | E72: =A74 -> 46327 | F72: =B72 -> 0 | H72: 46266 | J72: =H73 -> 46296 | K72: =I72 -> 0 | L72: =H74 -> 46327 | M72: =I72 -> 0 | O72: 46266 | Q72: =O73 -> 46296 | R72: =P72 -> 0 | S72: =O74 -> 46327 | T72: =P72 -> 0
A73: 46296 | C73: =A74 -> 46327 | D73: =B73 -> 0 | E73: =A75 -> 46357 | F73: =B73 -> 0 | H73: 46296 | J73: =H74 -> 46327 | K73: =I73 -> 0 | L73: =H75 -> 46357 | M73: =I73 -> 0 | O73: 46296 | Q73: =O74 -> 46327 | R73: =P73 -> 0 | S73: =O75 -> 46357 | T73: =P73 -> 0
A74: 46327 | C74: =A75 -> 46357 | D74: =B74 -> 0 | E74: =A76 -> 46388 | F74: =B74 -> 0 | H74: 46327 | J74: =H75 -> 46357 | K74: =I74 -> 0 | L74: =H76 -> 46388 | M74: =I74 -> 0 | O74: 46327 | Q74: =O75 -> 46357 | R74: =P74 -> 0 | S74: =O76 -> 46388 | T74: =P74 -> 0
A75: 46357 | C75: =A76 -> 46388 | D75: =B75 -> 0 | E75: =A77 -> 46419 | F75: =B75 -> 0 | H75: 46357 | J75: =H76 -> 46388 | K75: =I75 -> 0 | L75: =H77 -> 46419 | M75: =I75 -> 0 | O75: 46357 | Q75: =O76 -> 46388 | R75: =P75 -> 0 | S75: =O77 -> 46419 | T75: =P75 -> 0
A76: 46388 | C76: =A77 -> 46419 | D76: =B76 -> 0 | E76: =A78 -> 46447 | F76: =B76 -> 0 | H76: 46388 | J76: =H77 -> 46419 | K76: =I76 -> 0 | L76: =H78 -> 46447 | M76: =I76 -> 0 | O76: 46388 | Q76: =O77 -> 46419 | R76: =P76 -> 0 | S76: =O78 -> 46447 | T76: =P76 -> 0
A77: 46419 | C77: =A78 -> 46447 | D77: =B77 -> 0 | E77: =A79 -> 46478 | F77: =B77 -> 0 | H77: 46419 | J77: =H78 -> 46447 | K77: =I77 -> 0 | L77: =H79 -> 46478 | M77: =I77 -> 0 | O77: 46419 | Q77: =O78 -> 46447 | R77: =P77 -> 0 | S77: =O79 -> 46478 | T77: =P77 -> 0
A78: 46447 | C78: =A79 -> 46478 | D78: =B78 -> 0 | E78: =A80 -> 46508 | F78: =B78 -> 0 | H78: 46447 | J78: =H79 -> 46478 | K78: =I78 -> 0 | L78: =H80 -> 46508 | M78: =I78 -> 0 | O78: 46447 | Q78: =O79 -> 46478 | R78: =P78 -> 0 | S78: =O80 -> 46508 | T78: =P78 -> 0
A79: 46478 | C79: =A80 -> 46508 | D79: =B79 -> 0 | E79: =A81 -> 46539 | F79: =B79 -> 0 | H79: 46478 | J79: =H80 -> 46508 | K79: =I79 -> 0 | L79: =H81 -> 46539 | M79: =I79 -> 0 | O79: 46478 | Q79: =O80 -> 46508 | R79: =P79 -> 0 | S79: =O81 -> 46539 | T79: =P79 -> 0
A80: 46508 | C80: =A81 -> 46539 | D80: =B80 -> 0 | E80: =A82 -> 46569 | F80: =B80 -> 0 | H80: 46508 | J80: =H81 -> 46539 | K80: =I80 -> 0 | L80: =H82 -> 46569 | M80: =I80 -> 0 | O80: 46508 | Q80: =O81 -> 46539 | R80: =P80 -> 0 | S80: =O82 -> 46569 | T80: =P80 -> 0
A81: 46539 | C81: =A82 -> 46569 | D81: =B81 -> 0 | E81: =A83 -> 46600 | F81: =B81 -> 0 | H81: 46539 | J81: =H82 -> 46569 | K81: =I81 -> 0 | L81: =H83 -> 46600 | M81: =I81 -> 0 | O81: 46539 | Q81: =O82 -> 46569 | R81: =P81 -> 0 | S81: =O83 -> 46600 | T81: =P81 -> 0
... A96: 46997 | C96: =A97 -> 47027 | D96: =B96 -> 0 | E96: =A98 -> 47058 | F96: =B96 -> 0 | H96: 46997 | J96: =H97 -> 47027 | K96: =I96 -> 0 | L96: =H98 -> 47058 | M96: =I96 -> 0 | O96: 46997 | Q96: =O97 -> 47027 | R96: =P96 -> 0 | S96: =O98 -> 47058 | T96: =P96 -> 0
A97: 47027 | C97: =A98 -> 47058 | D97: =B97 -> 0 | E97: =A99 -> 47088 | F97: =B97 -> 0 | H97: 47027 | J97: =H98 -> 47058 | K97: =I97 -> 0 | L97: =H99 -> 47088 | M97: =I97 -> 0 | O97: 47027 | Q97: =O98 -> 47058 | R97: =P97 -> 0
A98: 47058 | C98: =A99 -> 47088 | D98: =B98 -> 0 | E98: =A100 -> 47119 | F98: =B98 -> 0 | H98: 47058 | J98: =H99 -> 47088 | K98: =I98 -> 0 | L98: =H100 -> 47119 | M98: =I98 -> 0 | O98: 47058
A99: 47088 | C99: =A100 -> 47119 | D99: =B99 -> 0 | E99: =A101 -> 47150 | F99: =B99 -> 0 | H99: 47088 | J99: =H100 -> 47119 | K99: =I99 -> 0 | L99: =H101 -> 47150 | M99: =I99 -> 0
A100: 47119 | C100: =A101 -> 47150 | D100: =B100 -> 0 | E100: =A102 -> 47178 | F100: =B100 -> 0 | H100: 47119 | J100: =H101 -> 47150 | K100: =I100 -> 0 | L100: =H102 -> 47178 | M100: =I100 -> 0
A101: 47150 | C101: =A102 -> 47178 | D101: =B101 -> 0 | E101: =A103 -> 47209 | F101: =B101 -> 0 | H101: 47150 | J101: =H102 -> 47178 | K101: =I101 -> 0 | L101: =H103 -> 47209 | M101: =I101 -> 0
A102: 47178 | C102: =A103 -> 47209 | D102: =B102 -> 0 | E102: =A104 -> 47239 | F102: =B102 -> 0 | H102: 47178 | J102: =H103 -> 47209 | K102: =I102 -> 0 | L102: =H104 -> 47239 | M102: =I102 -> 0
A103: 47209 | C103: =A104 -> 47239 | D103: =B103 -> 0 | E103: =A105 -> 47270 | F103: =B103 -> 0 | H103: 47209 | J103: =H104 -> 47239 | K103: =I103 -> 0 | L103: =H105 -> 47270 | M103: =I103 -> 0
A104: 47239 | C104: =A105 -> 47270 | D104: =B104 -> 0 | E104: =A106 -> 47300 | F104: =B104 -> 0 | H104: 47239 | J104: =H105 -> 47270 | K104: =I104 -> 0 | L104: =H106 -> 47300 | M104: =I104 -> 0
A105: 47270 | C105: =A106 -> 47300 | D105: =B105 -> 0 | E105: =A107 -> 47331 | F105: =B105 -> 0 | H105: 47270 | J105: =H106 -> 47300 | K105: =I105 -> 0 | L105: =H107 -> 47331 | M105: =I105 -> 0
A106: 47300 | C106: =A107 -> 47331 | D106: =B106 -> 0 | E106: =A108 -> 47362 | F106: =B106 -> 0 | H106: 47300 | J106: =H107 -> 47331 | K106: =I106 -> 0 | L106: =H108 -> 47362 | M106: =I106 -> 0
...

Sheet Croma
A1: INCC M - Vigente | B1: ='IND. FIN.'!V1 -> 46204 | C1: =VLOOKUP(B1,'IND. FIN.'!$J$4:$K$97,2,0) -> 1275.085 | D1: Contrato Piemonte | L1: Contratos Terceiro
A2: INCC - Base | B2: 44958 | C2: ='IND. FIN.'!K16 -> 967.003 | D2: R$ | G2: INCC | L2: Thal | S2: =IF(S3>$B$1,0,VLOOKUP(S$3,'IND. FIN.'!$C$4:$D$97,2,0)) -> 1043.76 | W2: =IF(W3>$B$1,0,VLOOKUP(W$3,'IND. FIN.'!$C$4:$D$97,2,0)) -> 1044.679 | AA2: =IF(AA3>$B$1,0,VLOOKUP(AA$3,'IND. FIN.'!$C$4:$D$97,2,0)) -> 1045.616 | AE2: =IF(AE3>$B$1,0,VLOOKUP(AE$3,'IND. FIN.'!$C$4:$D$97,2,0)) -> 1046.896 | AI2: =IF(AI3>$B$1,0,VLOOKUP(AI$3,'IND. FIN.'!$C$4:$D$97,2,0)) -> 1050.701 | AM2: =IF(AM3>$B$1,0,VLOOKUP(AM$3,'IND. FIN.'!$C$4:$D$97,2,0)) -> 1051.632 | AQ2: =IF(AQ3>$B$1,0,VLOOKUP(AQ$3,'IND. FIN.'!$C$4:$D$97,2,0)) -> 1056.418 | AU2: =IF(AU3>$B$1,0,VLOOKUP(AU$3,'IND. FIN.'!$C$4:$D$97,2,0)) -> 1056.896 | AY2: =IF(AY3>$B$1,0,VLOOKUP(AY$3,'IND. FIN.'!$C$4:$D$97,2,0)) -> 1060.116 | BC2: =IF(BC3>$B$1,0,VLOOKUP(BC$3,'IND. FIN.'!$C$4:$D$97,2,0)) -> 1061.635 | BG2: =IF(BG3>$B$1,0,VLOOKUP(BG$3,'IND. FIN.'!$C$4:$D$97,2,0)) -> 1067.919 | BK2: =IF(BK3>$B$1,0,VLOOKUP(BK$3,'IND. FIN.'!$C$4:$D$97,2,0)) -> 1075.54 | BO2: =IF(BO3>$B$1,0,VLOOKUP(BO$3,'IND. FIN.'!$C$4:$D$97,2,0)) -> 1076.626 | BS2: =IF(BS3>$B$1,0,VLOOKUP(BS$3,'IND. FIN.'!$C$4:$D$97,2,0)) -> 1078.412 | BW2: =IF(BW3>$B$1,0,VLOOKUP(BW$3,'IND. FIN.'!$C$4:$D$97,2,0)) -> 1082.104 | CA2: =IF(CA3>$B$1,0,VLOOKUP(CA$3,'IND. FIN.'!$C$4:$D$97,2,0)) -> 1084.242 | CE2: =IF(CE3>$B$1,0,VLOOKUP(CE$3,'IND. FIN.'!$C$4:$D$97,2,0)) -> 1084.986 | CI2: =IF(CI3>$B$1,0,VLOOKUP(CI$3,'IND. FIN.'!$C$4:$D$97,2,0)) -> 1088.312 | CM2: =IF(CM3>$B$1,0,VLOOKUP(CM$3,'IND. FIN.'!$C$4:$D$97,2,0)) -> 1091.25 | CQ2: =IF(CQ3>$B$1,0,VLOOKUP(CQ$3,'IND. FIN.'!$C$4:$D$97,2,0)) -> 1092.685 | CU2: =IF(CU3>$B$1,0,VLOOKUP(CU$3,'IND. FIN.'!$C$4:$D$97,2,0)) -> 1095.738 | CY2: =IF(CY3>$B$1,0,VLOOKUP(CY$3,'IND. FIN.'!$C$4:$D$97,2,0)) -> 1101.389 | DC2: =IF(DC3>$B$1,0,VLOOKUP(DC$3,'IND. FIN.'!$C$4:$D$97,2,0)) -> 1110.887 | DG2: =IF(DG3>$B$1,0,VLOOKUP(DG$3,'IND. FIN.'!$C$4:$D$97,2,0)) -> 1118.827 | DK2: =IF(DK3>$B$1,0,VLOOKUP(DK$3,'IND. FIN.'!$C$4:$D$97,2,0)) -> 1126.916 | DO2: =IF(DO3>$B$1,0,VLOOKUP(DO$3,'IND. FIN.'!$C$4:$D$97,2,0)) -> 1134.775 | DS2: =IF(DS3>$B$1,0,VLOOKUP(DS$3,'IND. FIN.'!$C$4:$D$97,2,0)) -> 1141.398 | DW2: =IF(DW3>$B$1,0,VLOOKUP(DW$3,'IND. FIN.'!$C$4:$D$97,2,0)) -> 1149.17 | EA2: =IF(EA3>$B$1,0,VLOOKUP(EA$3,'IND. FIN.'!$C$4:$D$97,2,0)) -> 1153.725 | EE2: =IF(EE3>$B$1,0,VLOOKUP(EE$3,'IND. FIN.'!$C$4:$D$97,2,0)) -> 1159.536 | EI2: =IF(EI3>$B$1,0,VLOOKUP(EI$3,'IND. FIN.'!$C$4:$D$97,2,0)) -> 1169.116 | EM2: =IF(EM3>$B$1,0,VLOOKUP(EM$3,'IND. FIN.'!$C$4:$D$97,2,0)) -> 1173.775 | EQ2: =IF(EQ3>$B$1,0,VLOOKUP(EQ$3,'IND. FIN.'!$C$4:$D$97,2,0)) -> 1178.386 | EU2: =IF(EU3>$B$1,0,VLOOKUP(EU$3,'IND. FIN.'!$C$4:$D$97,2,0)) -> 1184.462 | EY2: =IF(EY3>$B$1,0,VLOOKUP(EY$3,'IND. FIN.'!$C$4:$D$97,2,0)) -> 1191.327 | FC2: =IF(FC3>$B$1,0,VLOOKUP(FC$3,'IND. FIN.'!$C$4:$D$97,2,0)) -> 1199.509 | FG2: =IF(FG3>$B$1,0,VLOOKUP(FG$3,'IND. FIN.'!$C$4:$D$97,2,0)) -> 1210.471 | FK2: =IF(FK3>$B$1,0,VLOOKUP(FK$3,'IND. FIN.'!$C$4:$D$97,2,0)) -> 1216.706
A3: Orçamento base | D3: Valor total | E3: Valor unitário | F3: Saldo | G3: Valor total | H3: Valor unitário | I3: Total medido Piemonte | J3: Total medido Terceiros | K3: Saldo | L3: Prazo | M3: Valor total | N3: Valor unitário | O3: Prazo | P3: Valor total | Q3: Valor unitário | R3: Saldo | S3: 44774 | W3: =EDATE(S3,1) -> 44805 | AA3: =EDATE(W3,1) -> 44835 | AE3: =EDATE(AA3,1) -> 44866 | AI3: =EDATE(AE3,1) -> 44896 | AM3: =EDATE(AI3,1) -> 44927 | AQ3: =EDATE(AM3,1) -> 44958 | AU3: =EDATE(AQ3,1) -> 44986 | AY3: =EDATE(AU3,1) -> 45017 | BC3: =EDATE(AY3,1) -> 45047 | BG3: =EDATE(BC3,1) -> 45078 | BK3: =EDATE(BG3,1) -> 45108 | BO3: =EDATE(BK3,1) -> 45139 | BS3: =EDATE(BO3,1) -> 45170 | BW3: =EDATE(BS3,1) -> 45200 | CA3: =EDATE(BW3,1) -> 45231 | CE3: =EDATE(CA3,1) -> 45261 | CI3: =EDATE(CE3,1) -> 45292 | CM3: =EDATE(CI3,1) -> 45323 | CQ3: =EDATE(CM3,1) -> 45352 | CU3: =EDATE(CQ3,1) -> 45383 | CY3: =EDATE(CU3,1) -> 45413 | DC3: =EDATE(CY3,1) -> 45444 | DG3: =EDATE(DC3,1) -> 45474 | DK3: =EDATE(DG3,1) -> 45505 | DO3: =EDATE(DK3,1) -> 45536 | DS3: =EDATE(DO3,1) -> 45566 | DW3: =EDATE(DS3,1) -> 45597 | EA3: =EDATE(DW3,1) -> 45627 | EE3: =EDATE(EA3,1) -> 45658 | EI3: =EDATE(EE3,1) -> 45689 | EM3: =EDATE(EI3,1) -> 45717 | EQ3: =EDATE(EM3,1) -> 45748 | EU3: =EDATE(EQ3,1) -> 45778 | EY3: =EDATE(EU3,1) -> 45809 | FC3: =EDATE(EY3,1) -> 45839 | FG3: =EDATE(FC3,1) -> 45870 | FK3: =EDATE(FG3,1) -> 45901
A4: 01.01.04.01 | B4: PESSOAL | C4: Prazo | S4: Medido Piemonte | T4: Medido Piemonte INCC | U4: Medido Terceiros INCC | V4: Medido Terceiros | W4: Medido Piemonte | X4: Medido Piemonte INCC | Y4: Medido Terceiros INCC | Z4: Medido Terceiros | AA4: Medido Piemonte | AB4: Medido Piemonte INCC | AC4: Medido Terceiros INCC | AD4: Medido Terceiros | AE4: Medido Piemonte | AF4: Medido Piemonte INCC | AG4: Medido Terceiros INCC | AH4: Medido Terceiros | AI4: Medido Piemonte | AJ4: Medido Piemonte INCC | AK4: Medido Terceiros INCC | AL4: Medido Terceiros | AM4: Medido Piemonte | AN4: Medido Piemonte INCC | AO4: Medido Terceiros INCC | AP4: Medido Terceiros | AQ4: Medido Piemonte | AR4: Medido Piemonte INCC | AS4: Medido Terceiros INCC | AT4: Medido Terceiros | AU4: Medido Piemonte | AV4: Medido Piemonte INCC | AW4: Medido Terceiros INCC | AX4: Medido Terceiros | AY4: Medido Piemonte | AZ4: Medido Piemonte INCC | BA4: Medido Terceiros INCC | BB4: Medido Terceiros | BC4: Medido Piemonte | BD4: Medido Piemonte INCC | BE4: Medido Terceiros INCC | BF4: Medido Terceiros | BG4: Medido Piemonte | BH4: Medido Piemonte INCC | BI4: Medido Terceiros INCC | BJ4: Medido Terceiros | BK4: Medido Piemonte | BL4: Medido Piemonte INCC | BM4: Medido Terceiros INCC | BN4: Medido Terceiros | BO4: Medido Piemonte | BP4: Medido Piemonte INCC | BQ4: Medido Terceiros INCC | BR4: Medido Terceiros | BS4: Medido Piemonte | BT4: Medido Piemonte INCC | BU4: Medido Terceiros INCC | BV4: Medido Terceiros | BW4: Medido Piemonte | BX4: Medido Piemonte INCC | BY4: Medido Terceiros INCC | BZ4: Medido Terceiros | CA4: Medido Piemonte | CB4: Medido Piemonte INCC | CC4: Medido Terceiros INCC | CD4: Medido Terceiros | CE4: Medido Piemonte | CF4: Medido Piemonte INCC | CG4: Medido Terceiros INCC | CH4: Medido Terceiros | CI4: Medido Piemonte | CJ4: Medido Piemonte INCC | CK4: Medido Terceiros INCC | CL4: Medido Terceiros | CM4: Medido Piemonte | CN4: Medido Piemonte INCC | CO4: Medido Terceiros INCC | CP4: Medido Terceiros | CQ4: Medido Piemonte | CR4: Medido Piemonte INCC | CS4: Medido Terceiros INCC | CT4: Medido Terceiros | CU4: Medido Piemonte | CV4: Medido Piemonte INCC | CW4: Medido Terceiros INCC | CX4: Medido Terceiros | CY4: Medido Piemonte | CZ4: Medido Piemonte INCC | DA4: Medido Terceiros INCC | DB4: Medido Terceiros | DC4: Medido Piemonte | DD4: Medido Piemonte INCC | DE4: Medido Terceiros INCC | DF4: Medido Terceiros | DG4: Medido Piemonte | DH4: Medido Piemonte INCC | DI4: Medido Terceiros INCC | DJ4: Medido Terceiros | DK4: Medido Piemonte | DL4: Medido Piemonte INCC | DM4: Medido Terceiros INCC | DN4: Medido Terceiros | DO4: Medido Piemonte | DP4: Medido Piemonte INCC | DQ4: Medido Terceiros INCC | DR4: Medido Terceiros | DS4: Medido Piemonte | DT4: Medido Piemonte INCC | DU4: Medido Terceiros INCC | DV4: Medido Terceiros | DW4: Medido Piemonte | DX4: Medido Piemonte INCC | DY4: Medido Terceiros INCC | DZ4: Medido Terceiros | EA4: Medido Piemonte | EB4: Medido Piemonte INCC | EC4: Medido Terceiros INCC | ED4: Medido Terceiros | EE4: Medido Piemonte | EF4: Medido Piemonte INCC | EG4: Medido Terceiros INCC | EH4: Medido Terceiros | EI4: Medido Piemonte | EJ4: Medido Piemonte INCC | EK4: Medido Terceiros INCC | EL4: Medido Terceiros | EM4: Medido Piemonte | EN4: Medido Piemonte INCC | EO4: Medido Terceiros INCC | EP4: Medido Terceiros | EQ4: Medido Piemonte | ER4: Medido Piemonte INCC | ES4: Medido Terceiros INCC | ET4: Medido Terceiros | EU4: Medido Piemonte | EV4: Medido Piemonte INCC | EW4: Medido Terceiros INCC | EX4: Medido Terceiros | EY4: Medido Piemonte | EZ4: Medido Piemonte INCC | FA4: Medido Terceiros INCC | FB4: Medido Terceiros | FC4: Medido Piemonte | FD4: Medido Piemonte INCC | FE4: Medido Terceiros INCC | FF4: Medido Terceiros | FG4: Medido Piemonte | FH4: Medido Piemonte INCC | FI4: Medido Terceiros INCC | FJ4: Medido Terceiros | FK4: Medido Piemonte | FL4: Medido Piemonte INCC | FM4: Medido Terceiros INCC | FN4: Medido Terceiros
A5: 01.01.04.01.001 | B5: COORDENADOR DE OBRAS | C5: 37 | D5: =E5*C5 -> 666000 | E5: 18000 | F5: =K5*$C$1 -> -75090.788 | G5: =D5/$C$2 -> 688.72589 | H5: =E5/$C$2 -> 18.614213 | I5: =SUMIFS($S5:$FN5,$S$4:$FN$4,$T$4) -> 747.6167 | J5: =SUMIFS($S5:$FN5,$S$4:$FN$4,$U$4) -> 0 | K5: =G5-I5-J5 -> -58.890809 | R5: =M5-SUMIFS(S5:ET5,$S$4:$ET$4,$V$4) -> 0 | S5: 19460.583 | T5: 18.675664 | U5: 0 | W5: 19460.583 | X5: 18.614213 | Y5: 0 | AA5: 19460.573 | AB5: 18.595741 | AC5: 0 | AE5: 19513.722 | AF5: 18.638532 | AG5: 0 | AI5: 19109.02 | AJ5: 18.226336 | AK5: 0 | AM5: 19617.552 | AN5: 18.661185 | AO5: 0 | AQ5: 19670.986 | AR5: 18.653246 | AS5: 0 | AU5: 19705.886 | AV5: 18.647192 | AW5: 0 | AY5: 19750.951 | AZ5: 18.656734 | BA5: 0 | BC5: 19829.57 | BD5: 18.688259 | BE5: 0 | BG5: 19997.051 | BH5: 18.77148 | BI5: 0 | BK5: 20008.371 | BL5: 18.624704 | BM5: 0 | BO5: 62392.633 | BP5: 58.045329 | BQ5: 0 | BS5: 20104.599 | BT5: 18.658613 | BU5: 0 | BW5: 20145.163 | BX5: 18.651703 | BY5: 0 | CA5: 20165.389 | CB5: 18.632821 | CC5: 0 | CE5: 20217.845 | CF5: 18.662598 | CG5: 0 | CI5: 20264.678 | CJ5: 18.657348 | CK5: 0 | CM5: 20305.624 | CN5: 18.651892 | CO5: 0 | CQ5: 20354.652 | CR5: 18.659083 | CS5: 0 | CU5: 20438.262 | CV5: 18.690631 | CW5: 0 | CY5: 20558.663 | CZ5: 18.72389 | DA5: 0 | DC5: 20750.151 | DD5: 18.78765 | DE5: 0 | DG5: 20893.578 | DH5: 18.742871 | DI5: 0 | DK5: 20893.561 | DL5: 18.614213 | DM5: 0 | DO5: 21027.341 | DP5: 18.614213 | DQ5: 0 | DS5: 21155.444 | DT5: 18.614213 | DU5: 0 | DW5: 21297.191 | DX5: 18.614213 | DY5: 0 | EA5: 21390.672 | EB5: 18.614213 | EC5: 0 | EE5: 21499.23 | EF5: 18.614213 | EG5: 0 | EI5: =IF($E5*EI$2/$C$2-EL5>0,$E5*EI$2/$C$2-EL5,0) -> 21762.174 | EJ5: =IFERROR(EI5/EI$2,0) -> 18.614213 | EK5: =IFERROR(EL5/EI$2,0) -> 0 | EM5: =IF($E5*EM$2/$C$2-EP5>0,$E5*EM$2/$C$2-EP5,0) -> 21848.898 | EN5: =IFERROR(EM5/EM$2,0) -> 18.614213 | EO5: =IFERROR(EP5/EM$2,0) -> 0 | EQ5: =IF($E5*EQ$2/$C$2-ET5>0,$E5*EQ$2/$C$2-ET5,0) -> 21934.728 | ER5: =IFERROR(EQ5/EQ$2,0) -> 18.614213 | ES5: =IFERROR(ET5/EQ$2,0) -> 0 | EU5: =IF($E5*EU$2/$C$2-EX5>0,$E5*EU$2/$C$2-EX5,0) -> 22047.828 | EV5: =IFERROR(EU5/EU$2,0) -> 18.614213 | EW5: =IFERROR(EX5/EU$2,0) -> 0 | EY5: =IF($E5*EY$2/$C$2-FB5>0,$E5*EY$2/$C$2-FB5,0) -> 22175.615 | EZ5: =IFERROR(EY5/EY$2,0) -> 18.614213 | FA5: =IFERROR(FB5/EY$2,0) -> 0 | FC5: =IF($E5*FC$2/$C$2-FF5>0,$E5*FC$2/$C$2-FF5,0) -> 22327.916 | FD5: =IFERROR(FC5/FC$2,0) -> 18.614213 | FE5: =IFERROR(FF5/FC$2,0) -> 0 | FG5: =IF($E5*FG$2/$C$2-FJ5>0,$E5*FG$2/$C$2-FJ5,0) -> 22531.965 | FH5: =IFERROR(FG5/FG$2,0) -> 18.614213 | FI5: =IFERROR(FJ5/FG$2,0) -> 0 | FK5: =IF($E5*FK$2/$C$2-FN5>0,$E5*FK$2/$C$2-FN5,0) -> 22648.025 | FL5: =IFERROR(FK5/FK$2,0) -> 18.614213 | FM5: =IFERROR(FN5/FK$2,0) -> 0
A6: 01.01.04.01.002 | B6: ENGENHEIRO RESIDENTE | C6: 37 | D6: =E6*C6 -> 518000 | E6: 14000 | F6: =K6*$C$1 -> -838.73931 | G6: =D6/$C$2 -> 535.67569 | H6: =E6/$C$2 -> 14.477721 | I6: =SUMIFS($S6:$FN6,$S$4:$FN$4,$T$4) -> 536.33348 | J6: =SUMIFS($S6:$FN6,$S$4:$FN$4,$U$4) -> 0 | K6: =G6-I6-J6 -> -0.6577909 | R6: =M6-SUMIFS(S6:ET6,$S$4:$ET$4,$V$4) -> 0 | S6: 15136.009 | T6: 14.525516 | U6: 0 | W6: 15136.009 | X6: 14.477721 | Y6: 0 | AA6: 15136.016 | AB6: 14.463368 | AC6: 0 | AE6: 15177.29 | AF6: 14.496588 | AG6: 0 | AI6: 14862.564 | AJ6: 14.176033 | AK6: 0 | AM6: 15258.046 | AN6: 14.514207 | AO6: 0 | AQ6: 15299.711 | AR6: 14.508133 | AS6: 0 | AU6: 15326.856 | AV6: 14.503424 | AW6: 0 | AY6: 15361.907 | AZ6: 14.510846 | BA6: 0 | BC6: 15422.934 | BD6: 14.535252 | BE6: 0 | BG6: 15553.322 | BH6: 14.600096 | BI6: 0 | BK6: 15561.999 | BL6: 14.485818 | BM6: 0 | BO6: 0 | BP6: 0 | BQ6: 0 | BS6: 15636.985 | BT6: 14.512323 | BU6: 0 | BW6: 15668.549 | BX6: 14.506962 | BY6: 0 | CA6: 15684.244 | CB6: 14.492242 | CC6: 0 | CE6: 15724.976 | CF6: 14.51534 | CG6: 0 | CI6: 15761.341 | CJ6: 14.511201 | CK6: 0 | CM6: 15793.361 | CN6: 14.507117 | CO6: 0 | CQ6: 15831.449 | CR6: 14.512668 | CS6: 0 | CU6: 15896.441 | CV6: 14.537172 | CW6: 0 | CY6: 15989.987 | CZ6: 14.562949 | DA6: 0 | DC6: 16138.999 | DD6: 14.61261 | DE6: 0 | DG6: 16250.568 | DH6: 14.577796 | DI6: 0 | DK6: 16250.547 | DL6: 14.477721 | DM6: 0 | DO6: 16354.599 | DP6: 14.477721 | DQ6: 0 | DS6: 16454.234 | DT6: 14.477721 | DU6: 0 | DW6: 16564.482 | DX6: 14.477721 | DY6: 0 | EA6: 16637.189 | EB6: 14.477721 | EC6: 0 | EE6: 16721.623 | EF6: 14.477721 | EG6: 0 | EI6: =IF($E6*EI$2/$C$2-EL6>0,$E6*EI$2/$C$2-EL6,0) -> 16926.136 | EJ6: =IFERROR(EI6/EI$2,0) -> 14.477721 | EK6: =IFERROR(EL6/EI$2,0) -> 0 | EM6: =IF($E6*EM$2/$C$2-EP6>0,$E6*EM$2/$C$2-EP6,0) -> 16993.587 | EN6: =IFERROR(EM6/EM$2,0) -> 14.477721 | EO6: =IFERROR(EP6/EM$2,0) -> 0 | EQ6: =IF($E6*EQ$2/$C$2-ET6>0,$E6*EQ$2/$C$2-ET6,0) -> 17060.344 | ER6: =IFERROR(EQ6/EQ$2,0) -> 14.477721 | ES6: =IFERROR(ET6/EQ$2,0) -> 0 | EU6: =IF($E6*EU$2/$C$2-EX6>0,$E6*EU$2/$C$2-EX6,0) -> 17148.311 | EV6: =IFERROR(EU6/EU$2,0) -> 14.477721 | EW6: =IFERROR(EX6/EU$2,0) -> 0 | EY6: =IF($E6*EY$2/$C$2-FB6>0,$E6*EY$2/$C$2-FB6,0) -> 17247.7 | EZ6: =IFERROR(EY6/EY$2,0) -> 14.477721 | FA6: =IFERROR(FB6/EY$2,0) -> 0 | FC6: =IF($E6*FC$2/$C$2-FF6>0,$E6*FC$2/$C$2-FF6,0) -> 17366.157 | FD6: =IFERROR(FC6/FC$2,0) -> 14.477721 | FE6: =IFERROR(FF6/FC$2,0) -> 0 | FG6: =IF($E6*FG$2/$C$2-FJ6>0,$E6*FG$2/$C$2-FJ6,0) -> 17524.862 | FH6: =IFERROR(FG6/FG$2,0) -> 14.477721 | FI6: =IFERROR(FJ6/FG$2,0) -> 0 | FK6: =IF($E6*FK$2/$C$2-FN6>0,$E6*FK$2/$C$2-FN6,0) -> 17615.13 | FL6: =IFERROR(FK6/FK$2,0) -> 14.477721 | FM6: =IFERROR(FN6/FK$2,0) -> 0
A7: 01.01.04.01.003 | B7: ESTAGIARIO | C7: 37 | D7: =E7*C7 -> 107300 | E7: 2900 | F7: =K7*$C$1 -> -173.6174 | G7: =D7/$C$2 -> 110.96139 | H7: =E7/$C$2 -> 2.9989566 | I7: =SUMIFS($S7:$FN7,$S$4:$FN$4,$T$4) -> 111.09755 | J7: =SUMIFS($S7:$FN7,$S$4:$FN$4,$U$4) -> 0 | K7: =G7-I7-J7 -> -0.13616143 | R7: =M7-SUMIFS(S7:ET7,$S$4:$ET$4,$V$4) -> 0 | S7: 3135.316 | T7: 3.0088568 | U7: 0 | W7: 3135.316 | X7: 2.9989564 | Y7: 0 | AA7: 3135.3301 | AB7: 2.9959953 | AC7: 0 | AE7: 3143.8386 | AF7: 3.0028374 | AG7: 0 | AI7: 3078.7038 | AJ7: 2.9364924 | AK7: 0 | AM7: 3160.5826 | AN7: 3.0065024 | AO7: 0 | AQ7: 3169.2053 | AR7: 3.0052366 | AS7: 0 | AU7: 3174.8282 | AV7: 3.0042613 | AW7: 0 | AY7: 3182.0886 | AZ7: 3.0057985 | BA7: 0 | BC7: 3194.7608 | BD7: 3.0108832 | BE7: 0 | BG7: 3221.7845 | BH7: 3.0243291 | BI7: 0 | BK7: 3223.5675 | BL7: 3.0006437 | BM7: 0 | BO7: 0 | BP7: 0 | BQ7: 0 | BS7: 3239.0873 | BT7: 3.0061219 | BU7: 0 | BW7: 3245.5985 | BX7: 3.0049862 | BY7: 0 | CA7: 3248.8892 | CB7: 3.0019738 | CC7: 0 | CE7: 3257.2866 | CF7: 3.0067215 | CG7: 0 | CI7: 3264.8213 | CJ7: 3.0058659 | CK7: 0 | CM7: 3271.4839 | CN7: 3.0050474 | CO7: 0 | CQ7: 3279.3614 | CR7: 3.0061862 | CS7: 0 | CU7: 3292.8303 | CV7: 3.0112677 | CW7: 0 | CY7: 3312.2469 | CZ7: 3.016643 | DA7: 0 | DC7: 3343.0527 | DD7: 3.0268745 | DE7: 0 | DG7: 3366.1837 | DH7: 3.0196813 | DI7: 0 | DK7: 3366.1848 | DL7: 2.9989566 | DM7: 0 | DO7: 3387.7383 | DP7: 2.9989566 | DQ7: 0 | DS7: 3408.3771 | DT7: 2.9989566 | DU7: 0 | DW7: 3431.2142 | DX7: 2.9989566 | DY7: 0 | EA7: 3446.2749 | EB7: 2.9989566 | EC7: 0 | EE7: 3463.7648 | EF7: 2.9989566 | EG7: 0 | EI7: =IF($E7*EI$2/$C$2-EL7>0,$E7*EI$2/$C$2-EL7,0) -> 3506.1281 | EJ7: =IFERROR(EI7/EI$2,0) -> 2.9989566 | EK7: =IFERROR(EL7/EI$2,0) -> 0 | EM7: =IF($E7*EM$2/$C$2-EP7>0,$E7*EM$2/$C$2-EP7,0) -> 3520.1002 | EN7: =IFERROR(EM7/EM$2,0) -> 2.9989566 | EO7: =IFERROR(EP7/EM$2,0) -> 0 | EQ7: =IF($E7*EQ$2/$C$2-ET7>0,$E7*EQ$2/$C$2-ET7,0) -> 3533.9284 | ER7: =IFERROR(EQ7/EQ$2,0) -> 2.9989566 | ES7: =IFERROR(ET7/EQ$2,0) -> 0 | EU7: =IF($E7*EU$2/$C$2-EX7>0,$E7*EU$2/$C$2-EX7,0) -> 3552.1501 | EV7: =IFERROR(EU7/EU$2,0) -> 2.9989566 | EW7: =IFERROR(EX7/EU$2,0) -> 0 | EY7: =IF($E7*EY$2/$C$2-FB7>0,$E7*EY$2/$C$2-FB7,0) -> 3572.7379 | EZ7: =IFERROR(EY7/EY$2,0) -> 2.9989566 | FA7: =IFERROR(FB7/EY$2,0) -> 0 | FC7: =IF($E7*FC$2/$C$2-FF7>0,$E7*FC$2/$C$2-FF7,0) -> 3597.2754 | FD7: =IFERROR(FC7/FC$2,0) -> 2.9989566 | FE7: =IFERROR(FF7/FC$2,0) -> 0 | FG7: =IF($E7*FG$2/$C$2-FJ7>0,$E7*FG$2/$C$2-FJ7,0) -> 3630.15 | FH7: =IFERROR(FG7/FG$2,0) -> 2.9989566 | FI7: =IFERROR(FJ7/FG$2,0) -> 0 | FK7: =IF($E7*FK$2/$C$2-FN7>0,$E7*FK$2/$C$2-FN7,0) -> 3648.8485 | FL7: =IFERROR(FK7/FK$2,0) -> 2.9989566 | FM7: =IFERROR(FN7/FK$2,0) -> 0
A8: 01.01.04.01.004 | B8: MESTRE DE OBRAS | C8: 37 | D8: =E8*C8 -> 764283.47 | E8: 20656.31 | F8: =K8*$C$1 -> -256965.28 | G8: =D8/$C$2 -> 790.36308 | H8: =E8/$C$2 -> 21.361164 | I8: =SUMIFS($S8:$FN8,$S$4:$FN$4,$T$4) -> 215.47715 | J8: =SUMIFS($S8:$FN8,$S$4:$FN$4,$U$4) -> 776.41389 | K8: =G8-I8-J8 -> -201.52796 | L8: 36 | M8: 934937.64 | N8: =M8/L8 -> 25970.49 | O8: 21 | P8: 37339.708 | Q8: =P8/O8 -> 1778.0814 | R8: =M8-SUMIFS(S8:ET8,$S$4:$ET$4,$V$4) -> 97977.963 | S8: 0 | T8: 0 | U8: 22.077255 | V8: 23005.14 | W8: 0 | X8: 0 | Y8: 22.004612 | Z8: 23005.14 | AA8: 0 | AB8: 0 | AC8: 21.982723 | AD8: 23005.073 | AE8: 0 | AF8: 0 | AG8: 21.973356 | AH8: 23005.136 | AI8: 0 | AJ8: 0 | AK8: 36.084415 | AL8: 37831.947 | AM8: 0 | AN8: 0 | AO8: 24.704448 | AP8: 25970.526 | AQ8: 0 | AR8: 0 | AS8: 104.29878 | AT8: 109989.42 | AU8: 0 | AV8: 0 | AW8: 19.660145 | AX8: 20776.35 | AY8: 0 | AZ8: 0 | BA8: 24.531701 | BB8: 25970.485 | BC8: 1979.4356 | BD8: 1.8655072 | BE8: 19.580555 | BF8: 20776.359 | BG8: 0 | BH8: 0 | BI8: 24.196671 | BJ8: 25776.447 | BK8: 0 | BL8: 0 | BM8: 28.89792 | BN8: 31044.805 | BO8: 0 | BP8: 0 | BQ8: 27.796914 | BR8: 29878.764 | BS8: 0 | BT8: 0 | BU8: 18.221114 | BV8: 19633.196 | BW8: 0 | BX8: 0 | BY8: 25.487614 | BZ8: 27528.433 | CA8: 0 | CB8: 0 | CC8: 25.436694 | CD8: 27528.887 | CE8: 0 | CF8: 0 | CG8: 25.410912 | CH8: 27528.53 | CI8: 0 | CJ8: 0 | CK8: 20.276185 | CL8: 22022.978 | CM8: 0 | CN8: 0 | CO8: 30.951043 | CP8: 33695.255 | CQ8: 0 | CR8: 0 | CS8: 25.235491 | CT8: 27528.665 | CU8: 0 | CV8: 0 | CW8: 25.175094 | CX8: 27529.041 | CY8: 0 | CZ8: 0 | DA8: 25.072066 | DB8: 27528.903 | DC8: 0 | DD8: 0 | DE8: 43.103628 | DF8: 47606.103 | DG8: 0 | DH8: 0 | DI8: 36.512471 | DJ8: 40702.204 | DK8: 0 | DL8: 0 | DM8: 19.620413 | DN8: 22022.972 | DO8: 0 | DP8: 0 | DQ8: 19.495584 | DR8: 22022.972 | DS8: 0 | DT8: 0 | DU8: 19.377532 | DV8: 22022.972 | DW8: 0 | DX8: 0 | DY8: 19.248561 | DZ8: 22022.972 | EA8: 24547.353 | EB8: 21.361164 | EC8: 0 | EE8: 24671.931 | EF8: 21.361164 | EG8: 0 | EI8: =IF($E8*EI$2/$C$2-EL8>0,$E8*EI$2/$C$2-EL8,0) -> 24973.679 | EJ8: =IFERROR(EI8/EI$2,0) -> 21.361164 | EK8: =IFERROR(EL8/EI$2,0) -> 0 | EM8: =IF($E8*EM$2/$C$2-EP8>0,$E8*EM$2/$C$2-EP8,0) -> 25073.201 | EN8: =IFERROR(EM8/EM$2,0) -> 21.361164 | EO8: =IFERROR(EP8/EM$2,0) -> 0 | EQ8: =IF($E8*EQ$2/$C$2-ET8>0,$E8*EQ$2/$C$2-ET8,0) -> 25171.697 | ER8: =IFERROR(EQ8/EQ$2,0) -> 21.361164 | ES8: =IFERROR(ET8/EQ$2,0) -> 0 | EU8: =IF($E8*EU$2/$C$2-EX8>0,$E8*EU$2/$C$2-EX8,0) -> 25301.487 | EV8: =IFERROR(EU8/EU$2,0) -> 21.361164 | EW8: =IFERROR(EX8/EU$2,0) -> 0 | EY8: =IF($E8*EY$2/$C$2-FB8>0,$E8*EY$2/$C$2-FB8,0) -> 25448.132 | EZ8: =IFERROR(EY8/EY$2,0) -> 21.361164 | FA8: =IFERROR(FB8/EY$2,0) -> 0 | FC8: =IF($E8*FC$2/$C$2-FF8>0,$E8*FC$2/$C$2-FF8,0) -> 25622.909 | FD8: =IFERROR(FC8/FC$2,0) -> 21.361164 | FE8: =IFERROR(FF8/FC$2,0) -> 0 | FG8: =IF($E8*FG$2/$C$2-FJ8>0,$E8*FG$2/$C$2-FJ8,0) -> 25857.07 | FH8: =IFERROR(FG8/FG$2,0) -> 21.361164 | FI8: =IFERROR(FJ8/FG$2,0) -> 0 | FK8: =IF($E8*FK$2/$C$2-FN8>0,$E8*FK$2/$C$2-FN8,0) -> 25990.257 | FL8: =IFERROR(FK8/FK$2,0) -> 21.361164 | FM8: =IFERROR(FN8/FK$2,0) -> 0
A9: 01.01.04.01.005 | B9: CONTRA-MESTRE DE OBRAS | C9: 37 | D9: =E9*C9 -> 467752.52 | E9: 12641.96 | F9: =K9*$C$1 -> -32941.994 | G9: =D9/$C$2 -> 483.71362 | H9: =E9/$C$2 -> 13.073341 | I9: =SUMIFS($S9:$FN9,$S$4:$FN$4,$T$4) -> 104.58673 | J9: =SUMIFS($S9:$FN9,$S$4:$FN$4,$U$4) -> 404.96203 | K9: =G9-I9-J9 -> -25.835136 | L9: 30 | M9: 476829.36 | N9: =M9/L9 -> 15894.312 | O9: 21 | P9: 28609.754 | Q9: =P9/O9 -> 1362.3693 | R9: =M9-SUMIFS(S9:ET9,$S$4:$ET$4,$V$4) -> 29545.247 | S9: 0 | T9: 0 | U9: 0 | V9: 0 | W9: 0 | X9: 0 | Y9: 0 | Z9: 0 | AA9: 0 | AB9: 0 | AC9: 0 | AD9: 0 | AE9: 0 | AF9: 0 | AG9: 0 | AH9: 0 | AI9: 0 | AJ9: 0 | AK9: 0 | AL9: 0 | AM9: 0 | AN9: 0 | AO9: 0 | AP9: 0 | AQ9: 0 | AR9: 0 | AS9: 0 | AT9: 0 | AU9: 0 | AV9: 0 | AW9: 0 | AX9: 0 | AY9: 0 | AZ9: 0 | BA9: 0 | BB9: 0 | BC9: 0 | BD9: 0 | BE9: 0 | BF9: 0 | BG9: 0 | BH9: 0 | BI9: 0 | BJ9: 0 | BK9: 0 | BL9: 0 | BM9: 15.023643 | BN9: 16139.78 | BO9: 0 | BP9: 0 | BQ9: 25.710129 | BR9: 27635.689 | BS9: 0 | BT9: 0 | BU9: 13.93952 | BV9: 15019.791 | BW9: 0 | BX9: 0 | BY9: 15.598645 | BZ9: 16847.644 | CA9: 0 | CB9: 0 | CC9: 12.579354 | CD9: 13614.018 | CE9: 0 | CF9: 0 | CG9: 15.552086 | CH9: 16848.12 | CI9: 0 | CJ9: 0 | CK9: 12.409331 | CL9: 13478.394 | CM9: 0 | CN9: 0 | CO9: 18.756502 | CP9: 20419.51 | CQ9: 0 | CR9: 0 | CS9: 15.44444 | CT9: 16847.892 | CU9: 0 | CV9: 0 | CW9: 15.406998 | CX9: 16847.598 | CY9: 0 | CZ9: 0 | DA9: 15.34399 | DB9: 16847.562 | DC9: 0 | DD9: 0 | DE9: 118.64585 | DF9: 131039.24 | DG9: 0 | DH9: 0 | DI9: 10.57957 | DJ9: 11793.555 | DK9: 0 | DL9: 0 | DM9: 16.913169 | DN9: 18984.221 | DO9: 0 | DP9: 0 | DQ9: 16.805564 | DR9: 18984.221 | DS9: 0 | DT9: 0 | DU9: 16.703801 | DV9: 18984.221 | DW9: 0 | DX9: 0 | DY9: 16.592626 | DZ9: 18984.221 | EB9: 0 | EC9: 16.520114 | ED9: 18984.221 | EF9: 0 | EG9: 16.436697 | EH9: 18984.221 | EI9: =IF($E9*EI$2/$C$2-EL9>0,$E9*EI$2/$C$2-EL9,0) -> 15284.252 | EJ9: =IFERROR(EI9/EI$2,0) -> 13.073341 | EK9: =IFERROR(EL9/EI$2,0) -> 0 | EM9: =IF($E9*EM$2/$C$2-EP9>0,$E9*EM$2/$C$2-EP9,0) -> 15345.161 | EN9: =IFERROR(EM9/EM$2,0) -> 13.073341 | EO9: =IFERROR(EP9/EM$2,0) -> 0 | EQ9: =IF($E9*EQ$2/$C$2-ET9>0,$E9*EQ$2/$C$2-ET9,0) -> 15405.442 | ER9: =IFERROR(EQ9/EQ$2,0) -> 13.073341 | ES9: =IFERROR(ET9/EQ$2,0) -> 0 | EU9: =IF($E9*EU$2/$C$2-EX9>0,$E9*EU$2/$C$2-EX9,0) -> 15484.876 | EV9: =IFERROR(EU9/EU$2,0) -> 13.073341 | EW9: =IFERROR(EX9/EU$2,0) -> 0 | EY9: =IF($E9*EY$2/$C$2-FB9>0,$E9*EY$2/$C$2-FB9,0) -> 15574.624 | EZ9: =IFERROR(EY9/EY$2,0) -> 13.073341 | FA9: =IFERROR(FB9/EY$2,0) -> 0 | FC9: =IF($E9*FC$2/$C$2-FF9>0,$E9*FC$2/$C$2-FF9,0) -> 15681.59 | FD9: =IFERROR(FC9/FC$2,0) -> 13.073341 | FE9: =IFERROR(FF9/FC$2,0) -> 0 | FG9: =IF($E9*FG$2/$C$2-FJ9>0,$E9*FG$2/$C$2-FJ9,0) -> 15824.9 | FH9: =IFERROR(FG9/FG$2,0) -> 13.073341 | FI9: =IFERROR(FJ9/FG$2,0) -> 0 | FK9: =IF($E9*FK$2/$C$2-FN9>0,$E9*FK$2/$C$2-FN9,0) -> 15906.412 | FL9: =IFERROR(FK9/FK$2,0) -> 13.073341 | FM9: =IFERROR(FN9/FK$2,0) -> 0
A10: 01.01.04.01.006 | B10: ADMINISTRATIVO DE OBRAS | C10: 37 | D10: =E10*C10 -> 467752.52 | E10: 12641.96 | F10: =K10*$C$1 -> -11050.301 | G10: =D10/$C$2 -> 483.71362 | H10: =E10/$C$2 -> 13.073341 | I10: =SUMIFS($S10:$FN10,$S$4:$FN$4,$T$4) -> 492.37994 | J10: =SUMIFS($S10:$FN10,$S$4:$FN$4,$U$4) -> 0 | K10: =G10-I10-J10 -> -8.6663252 | R10: =M10-SUMIFS(S10:ET10,$S$4:$ET$4,$V$4) -> 0 | S10: 13667.773 | T10: 13.1165 | U10: 0 | W10: 13667.773 | X10: 13.073341 | Y10: 0 | AA10: 13667.773 | AB10: 13.060374 | AC10: 0 | AE10: 13705.04 | AF10: 13.090369 | AG10: 0 | AI10: 13420.874 | AJ10: 12.800937 | AK10: 0 | AM10: 13777.97 | AN10: 13.106286 | AO10: 0 | AQ10: 13815.58 | AR10: 13.100788 | AS10: 0 | AU10: 13840.09 | AV10: 13.096534 | AW10: 0 | AY10: 13871.743 | AZ10: 13.103238 | BA10: 0 | BB10: 0 | BC10: 13871.743 | BD10: 13.073341 | BE10: 0 | BF10: 0 | BG10: 13871.743 | BH10: 13.021577 | BI10: 0 | BJ10: 0 | BK10: 13871.743 | BL10: 12.912451 | BM10: 0 | BN10: 0 | BO10: 13871.743 | BP10: 12.905208 | BQ10: 0 | BR10: 0 | BS10: 13871.743 | BT10: 12.874043 | BU10: 0 | BV10: 0 | BW10: 13871.743 | BX10: 12.843362 | BY10: 0 | BZ10: 0 | CA10: 13871.743 | CB10: 12.817492 | CC10: 0 | CD10: 0 | CE10: 13871.743 | CF10: 12.804666 | CG10: 0 | CH10: 0 | CI10: 13871.743 | CJ10: 12.77148 | CK10: 0 | CL10: 0 | CM10: 13871.743 | CN10: 12.741999 | CO10: 0 | CP10: 0 | CQ10: 13871.743 | CR10: 12.716208 | CS10: 0 | CT10: 0 | CU10: 13871.743 | CV10: 12.685601 | CW10: 0 | CX10: 0 | CY10: 13871.743 | CZ10: 12.633749 | DA10: 0 | DB10: 0 | DC10: 13871.743 | DD10: 12.559786 | DE10: 0 | DF10: 0 | DG10: 13871.743 | DH10: 12.443838 | DI10: 0 | DJ10: 0 | DK10: 14674.198 | DL10: 13.073341 | DM10: 0 | DN10: 0 | DO10: 14768.156 | DP10: 13.073341 | DQ10: 0 | DR10: 0 | DS10: 14858.127 | DT10: 13.073341 | DU10: 0 | DV10: 0 | DW10: 14957.68 | DX10: 13.073341 | DY10: 0 | DZ10: 0 | EA10: 15023.334 | EB10: 13.073341 | EC10: 0 | ED10: 0 | EE10: 15099.578 | EF10: 13.073341 | EG10: 0 | EH10: 0 | EI10: =IF($E10*EI$2/$C$2-EL10>0,$E10*EI$2/$C$2-EL10,0) -> 15284.252 | EJ10: =IFERROR(EI10/EI$2,0) -> 13.073341 | EK10: =IFERROR(EL10/EI$2,0) -> 0 | EM10: =IF($E10*EM$2/$C$2-EP10>0,$E10*EM$2/$C$2-EP10,0) -> 15345.161 | EN10: =IFERROR(EM10/EM$2,0) -> 13.073341 | EO10: =IFERROR(EP10/EM$2,0) -> 0 | EQ10: =IF($E10*EQ$2/$C$2-ET10>0,$E10*EQ$2/$C$2-ET10,0) -> 15405.442 | ER10: =IFERROR(EQ10/EQ$2,0) -> 13.073341 | ES10: =IFERROR(ET10/EQ$2,0) -> 0 | EU10: =IF($E10*EU$2/$C$2-EX10>0,$E10*EU$2/$C$2-EX10,0) -> 15484.876 | EV10: =IFERROR(EU10/EU$2,0) -> 13.073341 | EW10: =IFERROR(EX10/EU$2,0) -> 0 | EY10: =IF($E10*EY$2/$C$2-FB10>0,$E10*EY$2/$C$2-FB10,0) -> 15574.624 | EZ10: =IFERROR(EY10/EY$2,0) -> 13.073341 | FA10: =IFERROR(FB10/EY$2,0) -> 0 | FC10: =IF($E10*FC$2/$C$2-FF10>0,$E10*FC$2/$C$2-FF10,0) -> 15681.59 | FD10: =IFERROR(FC10/FC$2,0) -> 13.073341 | FE10: =IFERROR(FF10/FC$2,0) -> 0 | FG10: =IF($E10*FG$2/$C$2-FJ10>0,$E10*FG$2/$C$2-FJ10,0) -> 15824.9 | FH10: =IFERROR(FG10/FG$2,0) -> 13.073341 | FI10: =IFERROR(FJ10/FG$2,0) -> 0 | FK10: =IF($E10*FK$2/$C$2-FN10>0,$E10*FK$2/$C$2-FN10,0) -> 15906.412 | FL10: =IFERROR(FK10/FK$2,0) -> 13.073341 | FM10: =IFERROR(FN10/FK$2,0) -> 0
A11: 01.01.04.01.007 | B11: ENCARREGADO | C11: 31 | D11: =E11*C11 -> 296054.96 | E11: 9550.16 | F11: =K11*$C$1 -> 264448.59 | G11: =D11/$C$2 -> 306.15723 | H11: =E11/$C$2 -> 9.8760397 | I11: =SUMIFS($S11:$FN11,$S$4:$FN$4,$T$4) -> 98.760397 | J11: =SUMIFS($S11:$FN11,$S$4:$FN$4,$U$4) -> 0 | K11: =G11-I11-J11 -> 207.39683 | L11: 21 | M11: 252149.04 | N11: =M11/L11 -> 12007.097 | O11: 21 | P11: 15128.946 | Q11: =P11/O11 -> 720.426 | R11: =M11-SUMIFS(S11:ET11,$S$4:$ET$4,$V$4) -> 252149.04 | S11: 0 | T11: 0 | U11: 0 | W11: 0 | X11: 0 | Y11: 0 | AA11: 0 | AB11: 0 | AC11: 0 | AE11: 0 | AF11: 0 | AG11: 0 | AI11: 0 | AJ11: 0 | AK11: 0 | AM11: 0 | AN11: 0 | AO11: 0 | AQ11: 0 | AR11: 0 | AS11: 0 | AU11: 0 | AV11: 0 | AW11: 0 | AZ11: 0 | BA11: 0 | BB11: 0 | BD11: 0 | BE11: 0 | BF11: 0 | BH11: 0 | BI11: 0 | BJ11: 0 | BL11: 0 | BM11: 0 | BN11: 0 | BP11: 0 | BQ11: 0 | BR11: 0 | BT11: 0 | BU11: 0 | BV11: 0 | BX11: 0 | BY11: 0 | BZ11: 0 | CB11: 0 | CC11: 0 | CD11: 0 | CF11: 0 | CG11: 0 | CH11: 0 | CJ11: 0 | CK11: 0 | CL11: 0 | CN11: 0 | CO11: 0 | CP11: 0 | CR11: 0 | CS11: 0 | CT11: 0 | CV11: 0 | CW11: 0 | CX11: 0 | CZ11: 0 | DA11: 0 | DB11: 0 | DD11: 0 | DE11: 0 | DF11: 0 | DH11: 0 | DI11: 0 | DJ11: 0 | DL11: 0 | DM11: 0 | DN11: 0 | DP11: 0 | DQ11: 0 | DR11: 0 | DT11: 0 | DU11: 0 | DV11: 0 | DX11: 0 | DY11: 0 | DZ11: 0 | EA11: 11349.13 | EB11: 9.8760397 | EC11: 0 | ED11: 0 | EE11: 11406.727 | EF11: 9.8760397 | EG11: 0 | EH11: 0 | EI11: =IF($E11*EI$2/$C$2-EL11>0,$E11*EI$2/$C$2-EL11,0) -> 11546.236 | EJ11: =IFERROR(EI11/EI$2,0) -> 9.8760397 | EK11: =IFERROR(EL11/EI$2,0) -> 0 | EM11: =IF($E11*EM$2/$C$2-EP11>0,$E11*EM$2/$C$2-EP11,0) -> 11592.248 | EN11: =IFERROR(EM11/EM$2,0) -> 9.8760397 | EO11: =IFERROR(EP11/EM$2,0) -> 0 | EQ11: =IF($E11*EQ$2/$C$2-ET11>0,$E11*EQ$2/$C$2-ET11,0) -> 11637.787 | ER11: =IFERROR(EQ11/EQ$2,0) -> 9.8760397 | ES11: =IFERROR(ET11/EQ$2,0) -> 0 | EU11: =IF($E11*EU$2/$C$2-EX11>0,$E11*EU$2/$C$2-EX11,0) -> 11697.794 | EV11: =IFERROR(EU11/EU$2,0) -> 9.8760397 | EW11: =IFERROR(EX11/EU$2,0) -> 0 | EY11: =IF($E11*EY$2/$C$2-FB11>0,$E11*EY$2/$C$2-FB11,0) -> 11765.593 | EZ11: =IFERROR(EY11/EY$2,0) -> 9.8760397 | FA11: =IFERROR(FB11/EY$2,0) -> 0 | FC11: =IF($E11*FC$2/$C$2-FF11>0,$E11*FC$2/$C$2-FF11,0) -> 11846.398 | FD11: =IFERROR(FC11/FC$2,0) -> 9.8760397 | FE11: =IFERROR(FF11/FC$2,0) -> 0 | FG11: =IF($E11*FG$2/$C$2-FJ11>0,$E11*FG$2/$C$2-FJ11,0) -> 11954.66 | FH11: =IFERROR(FG11/FG$2,0) -> 9.8760397 | FI11: =IFERROR(FJ11/FG$2,0) -> 0 | FK11: =IF($E11*FK$2/$C$2-FN11>0,$E11*FK$2/$C$2-FN11,0) -> 12016.237 | FL11: =IFERROR(FK11/FK$2,0) -> 9.8760397 | FM11: =IFERROR(FN11/FK$2,0) -> 0
A12: 01.01.04.01.008 | B12: ALMOXARIFE | C12: 37 | D12: =E12*C12 -> 176677.96 | E12: 4775.08 | F12: =K12*$C$1 -> -191096.57 | G12: =D12/$C$2 -> 182.70673 | H12: =E12/$C$2 -> 4.9380198 | I12: =SUMIFS($S12:$FN12,$S$4:$FN$4,$T$4) -> 58.86236 | J12: =SUMIFS($S12:$FN12,$S$4:$FN$4,$U$4) -> 273.71404 | K12: =G12-I12-J12 -> -149.86967 | L12: 36 | M12: 432255.5 | N12: =M12/L12 -> 12007.097 | O12: 21 | P12: 18269.21 | Q12: =P12/O12 -> 869.96238 | R12: =M12-SUMIFS(S12:ET12,$S$4:$ET$4,$V$4) -> 137254.95 | S12: 5162.547 | T12: 4.9543218 | U12: 10.207106 | V12: 10636.1 | W12: 0 | X12: 0 | Y12: 7.1214641 | Z12: 7445.27 | AA12: 1568.02 | AB12: 1.4983368 | AC12: 10.163429 | AD12: 10636.1 | AE12: 1586.49 | AF12: 1.5153359 | AG12: 10.159052 | AH12: 10636.08 | AI12: 1587.497 | AJ12: 1.5141674 | AK12: 0 | AM12: 0 | AN12: 0 | AO12: 11.421747 | AP12: 12007.1 | AQ12: 0 | AR12: 0 | AS12: 39.752124 | AT12: 41921.04 | AU12: 0 | AV12: 0 | AW12: 9.0895981 | AX12: 9605.66 | AY12: 0 | AZ12: 0 | BA12: 9.0734993 | BB12: 9605.66 | BC12: 0 | BD12: 0 | BE12: 9.0527967 | BF12: 9605.66 | BG12: 0 | BH12: 0 | BI12: 9.0169522 | BJ12: 9605.66 | BK12: 0 | BL12: 0 | BM12: 8.9413865 | BN12: 9605.66 | BO12: 0 | BP12: 0 | BQ12: 8.9363705 | BR12: 9605.66 | BS12: 0 | BT12: 0 | BU12: 8.9147905 | BV12: 9605.66 | BW12: 0 | BX12: 0 | BY12: 8.893545 | BZ12: 9605.66 | CA12: 0 | CB12: 0 | CC12: 8.8756305 | CD12: 9605.66 | CE12: 0 | CF12: 0 | CG12: 8.8667494 | CH12: 9605.66 | CI12: 0 | CJ12: 0 | CK12: 8.8437693 | CL12: 9605.66 | CM12: 0 | CN12: 0 | CO12: 8.8233549 | CP12: 9605.66 | CQ12: 0 | CR12: 0 | CS12: 8.8054958 | CT12: 9605.66 | CU12: 0 | CV12: 0 | CW12: 8.7843015 | CX12: 9605.66 | CY12: 0 | CZ12: 0 | DA12: 8.7483959 | DB12: 9605.66 | DC12: 0 | DD12: 0 | DE12: 8.6971788 | DF12: 9605.66 | DG12: 0 | DH12: 0 | DI12: 8.6168892 | DJ12: 9605.66 | DK12: 0 | DL12: 0 | DM12: 8.5577468 | DN12: 9605.66 | DO12: 0 | DP12: 0 | DQ12: 8.5033006 | DR12: 9605.66 | DS12: 0 | DT12: 0 | DU12: 8.4518104 | DV12: 9605.66 | DW12: 0 | DX12: 0 | DY12: 8.3955579 | DZ12: 9605.66 | EA12: 5674.565 | EB12: 4.9380198 | EC12: 0 | EE12: 5703.3635 | EF12: 4.9380198 | EG12: 0 | EI12: =IF($E12*EI$2/$C$2-EL12>0,$E12*EI$2/$C$2-EL12,0) -> 5773.118 | EJ12: =IFERROR(EI12/EI$2,0) -> 4.9380198 | EK12: =IFERROR(EL12/EI$2,0) -> 0 | EM12: =IF($E12*EM$2/$C$2-EP12>0,$E12*EM$2/$C$2-EP12,0) -> 5796.1242 | EN12: =IFERROR(EM12/EM$2,0) -> 4.9380198 | EO12: =IFERROR(EP12/EM$2,0) -> 0 | EQ12: =IF($E12*EQ$2/$C$2-ET12>0,$E12*EQ$2/$C$2-ET12,0) -> 5818.8934 | ER12: =IFERROR(EQ12/EQ$2,0) -> 4.9380198 | ES12: =IFERROR(ET12/EQ$2,0) -> 0 | EU12: =IF($E12*EU$2/$C$2-EX12>0,$E12*EU$2/$C$2-EX12,0) -> 5848.8969 | EV12: =IFERROR(EU12/EU$2,0) -> 4.9380198 | EW12: =IFERROR(EX12/EU$2,0) -> 0 | EY12: =IF($E12*EY$2/$C$2-FB12>0,$E12*EY$2/$C$2-FB12,0) -> 5882.7964 | EZ12: =IFERROR(EY12/EY$2,0) -> 4.9380198 | FA12: =IFERROR(FB12/EY$2,0) -> 0 | FC12: =IF($E12*FC$2/$C$2-FF12>0,$E12*FC$2/$C$2-FF12,0) -> 5923.1992 | FD12: =IFERROR(FC12/FC$2,0) -> 4.9380198 | FE12: =IFERROR(FF12/FC$2,0) -> 0 | FG12: =IF($E12*FG$2/$C$2-FJ12>0,$E12*FG$2/$C$2-FJ12,0) -> 5977.3298 | FH12: =IFERROR(FG12/FG$2,0) -> 4.9380198 | FI12: =IFERROR(FJ12/FG$2,0) -> 0 | FK12: =IF($E12*FK$2/$C$2-FN12>0,$E12*FK$2/$C$2-FN12,0) -> 6008.1184 | FL12: =IFERROR(FK12/FK$2,0) -> 4.9380198 | FM12: =IFERROR(FN12/FK$2,0) -> 0
A13: 01.01.04.01.009 | B13: AUXILIAR DE ALMOXARIFE | C13: 37 | D13: =E13*C13 -> 353355.92 | E13: 9550.16 | F13: =K13*$C$1 -> 306538.49 | G13: =D13/$C$2 -> 365.41347 | H13: =E13/$C$2 -> 9.8760397 | I13: =SUMIFS($S13:$FN13,$S$4:$FN$4,$T$4) -> 108.32408 | J13: =SUMIFS($S13:$FN13,$S$4:$FN$4,$U$4) -> 16.683075 | K13: =G13-I13-J13 -> 240.40632 | S13: 0 | T13: 0 | U13: 0 | W13: 0 | X13: 0 | Y13: 0 | AA13: 1568.023 | AB13: 1.4983397 | AC13: 0 | AE13: 0 | AF13: 0 | AG13: 0 | AI13: 0 | AJ13: 0 | AK13: 16.683075 | AL13: 17491.02 | AM13: 0 | AN13: 0 | AO13: 0 | AQ13: 0 | AR13: 0 | AS13: 0 | AU13: 0 | AV13: 0 | AW13: 0 | AZ13: 0 | BA13: 0 | BB13: 0 | BD13: 0 | BE13: 0 | BF13: 0 | BH13: 0 | BI13: 0 | BJ13: 0 | BL13: 0 | BM13: 0 | BN13: 0 | BP13: 0 | BQ13: 0 | BR13: 0 | BT13: 0 | BU13: 0 | BV13: 0 | BX13: 0 | BY13: 0 | BZ13: 0 | CB13: 0 | CC13: 0 | CD13: 0 | CF13: 0 | CG13: 0 | CH13: 0 | CJ13: 0 | CK13: 0 | CL13: 0 | CN13: 0 | CO13: 0 | CP13: 0 | CR13: 0 | CS13: 0 | CT13: 0 | CV13: 0 | CW13: 0 | CX13: 0 | CZ13: 0 | DA13: 0 | DB13: 0 | DD13: 0 | DE13: 0 | DF13: 0 | DH13: 0 | DI13: 0 | DJ13: 0 | DL13: 0 | DM13: 0 | DN13: 0 | DO13: 3056.05 | DP13: 2.7053333 | DQ13: 0 | DR13: 0 | DS13: 3056.05 | DT13: 2.6889516 | DU13: 0 | DV13: 0 | DW13: 3056.05 | DX13: 2.6710548 | DY13: 0 | DZ13: 0 | EA13: 11349.13 | EB13: 9.8760397 | EC13: 0 | ED13: 0 | EE13: 11406.727 | EF13: 9.8760397 | EG13: 0 | EH13: 0 | EI13: =IF($E13*EI$2/$C$2-EL13>0,$E13*EI$2/$C$2-EL13,0) -> 11546.236 | EJ13: =IFERROR(EI13/EI$2,0) -> 9.8760397 | EK13: =IFERROR(EL13/EI$2,0) -> 0 | EM13: =IF($E13*EM$2/$C$2-EP13>0,$E13*EM$2/$C$2-EP13,0) -> 11592.248 | EN13: =IFERROR(EM13/EM$2,0) -> 9.8760397 | EO13: =IFERROR(EP13/EM$2,0) -> 0 | EQ13: =IF($E13*EQ$2/$C$2-ET13>0,$E13*EQ$2/$C$2-ET13,0) -> 11637.787 | ER13: =IFERROR(EQ13/EQ$2,0) -> 9.8760397 | ES13: =IFERROR(ET13/EQ$2,0) -> 0 | EU13: =IF($E13*EU$2/$C$2-EX13>0,$E13*EU$2/$C$2-EX13,0) -> 11697.794 | EV13: =IFERROR(EU13/EU$2,0) -> 9.8760397 | EW13: =IFERROR(EX13/EU$2,0) -> 0 | EY13: =IF($E13*EY$2/$C$2-FB13>0,$E13*EY$2/$C$2-FB13,0) -> 11765.593 | EZ13: =IFERROR(EY13/EY$2,0) -> 9.8760397 | FA13: =IFERROR(FB13/EY$2,0) -> 0 | FC13: =IF($E13*FC$2/$C$2-FF13>0,$E13*FC$2/$C$2-FF13,0) -> 11846.398 | FD13: =IFERROR(FC13/FC$2,0) -> 9.8760397 | FE13: =IFERROR(FF13/FC$2,0) -> 0 | FG13: =IF($E13*FG$2/$C$2-FJ13>0,$E13*FG$2/$C$2-FJ13,0) -> 11954.66 | FH13: =IFERROR(FG13/FG$2,0) -> 9.8760397 | FI13: =IFERROR(FJ13/FG$2,0) -> 0 | FK13: =IF($E13*FK$2/$C$2-FN13>0,$E13*FK$2/$C$2-FN13,0) -> 12016.237 | FL13: =IFERROR(FK13/FK$2,0) -> 9.8760397 | FM13: =IFERROR(FN13/FK$2,0) -> 0
A14: 01.01.04.01.010 | B14: ENGENHEIRO DE SEGURANÇA | C14: 37 | D14: =E14*C14 -> 166500 | E14: 4500 | F14: =K14*$C$1 -> -3937.1825 | G14: =D14/$C$2 -> 172.18147 | H14: =E14/$C$2 -> 4.6535533 | I14: =SUMIFS($S14:$FN14,$S$4:$FN$4,$T$4) -> 175.26925 | J14: =SUMIFS($S14:$FN14,$S$4:$FN$4,$U$4) -> 0 | K14: =G14-I14-J14 -> -3.0877804 | S14: 4865.146 | T14: 4.6689161 | U14: 0 | W14: 4865.146 | X14: 4.6535536 | Y14: 0 | AA14: 4865.146 | AB14: 4.6489378 | AC14: 0 | AE14: 4878.41 | AF14: 4.6596132 | AG14: 0 | AI14: 4777.262 | AJ14: 4.5565909 | AK14: 0 | AM14: 4907.46 | AN14: 4.6682185 | AO14: 0 | AQ14: 4917.76 | AR14: 4.6633244 | AS14: 0 | AU14: 4926.48 | AV14: 4.661806 | AW14: 0 | AY14: 4937.7505 | AZ14: 4.6641954 | BA14: 0 | BB14: 0 | BC14: 4937.7505 | BD14: 4.6535533 | BE14: 0 | BF14: 0 | BG14: 4937.7505 | BH14: 4.6351276 | BI14: 0 | BJ14: 0 | BK14: 4937.7505 | BL14: 4.5962834 | BM14: 0 | BN14: 0 | BO14: 4937.7505 | BP14: 4.5937049 | BQ14: 0 | BR14: 0 | BS14: 4937.7505 | BT14: 4.5826118 | BU14: 0 | BV14: 0 | BW14: 4937.7505 | BX14: 4.5716906 | BY14: 0 | BZ14: 0 | CA14: 4937.7505 | CB14: 4.5624818 | CC14: 0 | CD14: 0 | CE14: 4937.7505 | CF14: 4.5579165 | CG14: 0 | CH14: 0 | CI14: 4937.7505 | CJ14: 4.5461036 | CK14: 0 | CL14: 0 | CM14: 4937.7505 | CN14: 4.5356097 | CO14: 0 | CP14: 0 | CQ14: 4937.7505 | CR14: 4.5264293 | CS14: 0 | CT14: 0 | CU14: 4937.7505 | CV14: 4.5155344 | CW14: 0 | CX14: 0 | CY14: 4937.7505 | CZ14: 4.4970773 | DA14: 0 | DB14: 0 | DC14: 4937.7505 | DD14: 4.4707494 | DE14: 0 | DF14: 0 | DG14: 4937.7505 | DH14: 4.4294768 | DI14: 0 | DJ14: 0 | DK14: 5223.3902 | DL14: 4.6535533 | DM14: 0 | DN14: 0 | DO14: 5256.8353 | DP14: 4.6535533 | DQ14: 0 | DR14: 0 | DS14: 5288.861 | DT14: 4.6535533 | DU14: 0 | DV14: 0 | DW14: 5324.2979 | DX14: 4.6535533 | DY14: 0 | DZ14: 0 | EA14: 5347.668 | EB14: 4.6535533 | EC14: 0 | ED14: 0 | EE14: 5374.8075 | EF14: 4.6535533 | EG14: 0 | EH14: 0 | EI14: =IF($E14*EI$2/$C$2-EL14>0,$E14*EI$2/$C$2-EL14,0) -> 5440.5436 | EJ14: =IFERROR(EI14/EI$2,0) -> 4.6535533 | EK14: =IFERROR(EL14/EI$2,0) -> 0 | EM14: =IF($E14*EM$2/$C$2-EP14>0,$E14*EM$2/$C$2-EP14,0) -> 5462.2245 | EN14: =IFERROR(EM14/EM$2,0) -> 4.6535533 | EO14: =IFERROR(EP14/EM$2,0) -> 0 | EQ14: =IF($E14*EQ$2/$C$2-ET14>0,$E14*EQ$2/$C$2-ET14,0) -> 5483.6821 | ER14: =IFERROR(EQ14/EQ$2,0) -> 4.6535533 | ES14: =IFERROR(ET14/EQ$2,0) -> 0 | EU14: =IF($E14*EU$2/$C$2-EX14>0,$E14*EU$2/$C$2-EX14,0) -> 5511.957 | EV14: =IFERROR(EU14/EU$2,0) -> 4.6535533 | EW14: =IFERROR(EX14/EU$2,0) -> 0 | EY14: =IF($E14*EY$2/$C$2-FB14>0,$E14*EY$2/$C$2-FB14,0) -> 5543.9037 | EZ14: =IFERROR(EY14/EY$2,0) -> 4.6535533 | FA14: =IFERROR(FB14/EY$2,0) -> 0 | FC14: =IF($E14*FC$2/$C$2-FF14>0,$E14*FC$2/$C$2-FF14,0) -> 5581.9791 | FD14: =IFERROR(FC14/FC$2,0) -> 4.6535533 | FE14: =IFERROR(FF14/FC$2,0) -> 0 | FG14: =IF($E14*FG$2/$C$2-FJ14>0,$E14*FG$2/$C$2-FJ14,0) -> 5632.9913 | FH14: =IFERROR(FG14/FG$2,0) -> 4.6535533 | FI14: =IFERROR(FJ14/FG$2,0) -> 0 | FK14: =IF($E14*FK$2/$C$2-FN14>0,$E14*FK$2/$C$2-FN14,0) -> 5662.0062 | FL14: =IFERROR(FK14/FK$2,0) -> 4.6535533 | FM14: =IFERROR(FN14/FK$2,0) -> 0
A15: 01.01.04.01.011 | B15: TECNICO SEGURANCA | C15: 37 | D15: =E15*C15 -> 194151.58 | E15: 5247.34 | F15: =K15*$C$1 -> 2349.8662 | G15: =D15/$C$2 -> 200.77661 | H15: =E15/$C$2 -> 5.4263947 | I15: =SUMIFS($S15:$FN15,$S$4:$FN$4,$T$4) -> 198.9337 | J15: =SUMIFS($S15:$FN15,$S$4:$FN$4,$U$4) -> 0 | K15: =G15-I15-J15 -> 1.8429095 | S15: 5673.127 | T15: 5.4443082 | U15: 0 | W15: 5673.127 | X15: 5.4263943 | Y15: 0 | AA15: 5673.127 | AB15: 5.421012 | AC15: 0 | AE15: 5688.6 | AF15: 5.4334662 | AG15: 0 | AI15: 5570.644 | AJ15: 5.313325 | AK15: 0 | AM15: 0 | AN15: 0 | AO15: 0 | AQ15: 5734.48 | AR15: 5.4377888 | AS15: 0 | AU15: 5744.65 | AV15: 5.43602 | AW15: 0 | AY15: 5757.7901 | AZ15: 5.4388042 | BA15: 0 | BB15: 0 | BC15: 5757.7901 | BD15: 5.4263947 | BE15: 0 | BF15: 0 | BG15: 5757.7901 | BH15: 5.404909 | BI15: 0 | BJ15: 0 | BK15: 5757.7901 | BL15: 5.3596137 | BM15: 0 | BN15: 0 | BO15: 5757.7901 | BP15: 5.356607 | BQ15: 0 | BR15: 0 | BS15: 5757.7901 | BT15: 5.3436716 | BU15: 0 | BV15: 0 | BW15: 5757.7901 | BX15: 5.3309367 | BY15: 0 | BZ15: 0 | CA15: 5757.7901 | CB15: 5.3201985 | CC15: 0 | CD15: 0 | CE15: 5757.7901 | CF15: 5.314875 | CG15: 0 | CH15: 0 | CI15: 5757.7901 | CJ15: 5.3011003 | CK15: 0 | CL15: 0 | CM15: 5757.7901 | CN15: 5.2888636 | CO15: 0 | CP15: 0 | CQ15: 5757.7901 | CR15: 5.2781586 | CS15: 0 | CT15: 0 | CU15: 5757.7901 | CV15: 5.2654543 | CW15: 0 | CX15: 0 | CY15: 5757.7901 | CZ15: 5.243932 | DA15: 0 | DB15: 0 | DC15: 5757.7901 | DD15: 5.2132316 | DE15: 0 | DF15: 0 | DG15: 5757.7901 | DH15: 5.1651047 | DI15: 0 | DJ15: 0 | DK15: 6090.8676 | DL15: 5.4263947 | DM15: 0 | DN15: 0 | DO15: 6129.8671 | DP15: 5.4263947 | DQ15: 0 | DR15: 0 | DS15: 6167.2116 | DT15: 5.4263947 | DU15: 0 | DV15: 0 | DW15: 6208.5336 | DX15: 5.4263947 | DY15: 0 | DZ15: 0 | EA15: 6235.7849 | EB15: 5.4263947 | EC15: 0 | ED15: 0 | EE15: 6267.4317 | EF15: 5.4263947 | EG15: 0 | EH15: 0 | EI15: =IF($E15*EI$2/$C$2-EL15>0,$E15*EI$2/$C$2-EL15,0) -> 6344.0849 | EJ15: =IFERROR(EI15/EI$2,0) -> 5.4263947 | EK15: =IFERROR(EL15/EI$2,0) -> 0 | EM15: =IF($E15*EM$2/$C$2-EP15>0,$E15*EM$2/$C$2-EP15,0) -> 6369.3665 | EN15: =IFERROR(EM15/EM$2,0) -> 5.4263947 | EO15: =IFERROR(EP15/EM$2,0) -> 0 | EQ15: =IF($E15*EQ$2/$C$2-ET15>0,$E15*EQ$2/$C$2-ET15,0) -> 6394.3876 | ER15: =IFERROR(EQ15/EQ$2,0) -> 5.4263947 | ES15: =IFERROR(ET15/EQ$2,0) -> 0 | EU15: =IF($E15*EU$2/$C$2-EX15>0,$E15*EU$2/$C$2-EX15,0) -> 6427.3584 | EV15: =IFERROR(EU15/EU$2,0) -> 5.4263947 | EW15: =IFERROR(EX15/EU$2,0) -> 0 | EY15: =IF($E15*EY$2/$C$2-FB15>0,$E15*EY$2/$C$2-FB15,0) -> 6464.6106 | EZ15: =IFERROR(EY15/EY$2,0) -> 5.4263947 | FA15: =IFERROR(FB15/EY$2,0) -> 0 | FC15: =IF($E15*FC$2/$C$2-FF15>0,$E15*FC$2/$C$2-FF15,0) -> 6509.0093 | FD15: =IFERROR(FC15/FC$2,0) -> 5.4263947 | FE15: =IFERROR(FF15/FC$2,0) -> 0 | FG15: =IF($E15*FG$2/$C$2-FJ15>0,$E15*FG$2/$C$2-FJ15,0) -> 6568.4935 | FH15: =IFERROR(FG15/FG$2,0) -> 5.4263947 | FI15: =IFERROR(FJ15/FG$2,0) -> 0 | FK15: =IF($E15*FK$2/$C$2-FN15>0,$E15*FK$2/$C$2-FN15,0) -> 6602.327 | FL15: =IFERROR(FK15/FK$2,0) -> 5.4263947 | FM15: =IFERROR(FN15/FK$2,0) -> 0
D16: =SUM(D5:D15) -> 4177828.9 | E16: =SUM(E5:E15) -> 114462.97 | F16: =SUM(F5:F15) -> 1242.4779 | G16: =SUM(G5:G15) -> 4320.3888 | H16: =SUM(H5:H15) -> 118.36878 | I16: =SUM(I5:I15) -> 2847.6413 | J16: =SUM(J5:J15) -> 1471.773 | K16: =SUM(K5:K15) -> 0.97442752 | ... FN16: =SUM(FN5:FN15) -> 0

Sheet Unna
A1: INCC M - Vigente | B1: ='IND. FIN.'!V1 -> 46204 | C1: =VLOOKUP(B1,'IND. FIN.'!$J$3:$K$97,2,0) -> 1275.085 | D1: Contrato Piemonte
