Workbook

Sheet INCC - DI
A1: 34547 | B1: 100 | E1: 34547 | H1: 34547
A2: 34578 | B2: 100.381 | E2: 34578 | F2: =B1 -> 100 | H2: 34578
A3: 34608 | B3: 101.71 | E3: 34608 | F3: =B2 -> 100.381 | H3: 34608 | I3: =B1 -> 100
A4: 34639 | B4: 104.11 | E4: 34639 | F4: =B3 -> 101.71 | H4: 34639 | I4: =B2 -> 100.381
A5: 34669 | B5: 105.487 | E5: 34669 | F5: =B4 -> 104.11 | H5: 34669 | I5: =B3 -> 101.71
A6: 34700 | B6: 109.176 | E6: 34700 | F6: =B5 -> 105.487 | H6: 34700 | I6: =B4 -> 104.11
A7: 34731 | B7: 111.453 | E7: 34731 | F7: =B6 -> 109.176 | H7: 34731 | I7: =B5 -> 105.487
A8: 34759 | B8: 115.129 | E8: 34759 | F8: =B7 -> 111.453 | H8: 34759 | I8: =B6 -> 109.176
A9: 34790 | B9: 117.774 | E9: 34790 | F9: =B8 -> 115.129 | H9: 34790 | I9: =B7 -> 111.453
A10: 34820 | B10: 128.098 | E10: 34820 | F10: =B9 -> 117.774 | H10: 34820 | I10: =B8 -> 115.129
A11: 34851 | B11: 132.09 | E11: 34851 | F11: =B10 -> 128.098 | H11: 34851 | I11: =B9 -> 117.774
A12: 34881 | B12: 133.524 | E12: 34881 | F12: =B11 -> 132.09 | H12: 34881 | I12: =B10 -> 128.098
A13: 34912 | B13: 134.353 | E13: 34912 | F13: =B12 -> 133.524 | H13: 34912 | I13: =B11 -> 132.09
A14: 34943 | B14: 135.318 | E14: 34943 | F14: =B13 -> 134.353 | H14: 34943 | I14: =B12 -> 133.524
... A382: 46143 | B382: 1270.695 | E382: 46143 | F382: =B381 -> 1259.652 | H382: 46143 | I382: =B380 -> 1247.181
A383: 46174 | B383: =B382 -> 1270.695 | E383: 46174 | F383: =B382 -> 1270.695 | H383: 46174 | I383: =B381 -> 1259.652
A384: 46204 | B384: =B383 -> 1270.695 | E384: 46204 | F384: =B383 -> 1270.695 | H384: 46204 | I384: =B382 -> 1270.695
A385: 46235 | B385: =B384 -> 1270.695 | E385: 46235 | F385: =B384 -> 1270.695 | H385: 46235 | I385: =B383 -> 1270.695
A386: 46266 | B386: =B385 -> 1270.695 | E386: 46266 | F386: =B385 -> 1270.695 | H386: 46266 | I386: =B384 -> 1270.695
A387: 46296 | B387: =B386 -> 1270.695 | E387: 46296 | F387: =B386 -> 1270.695 | H387: 46296 | I387: =B385 -> 1270.695
A388: 46327 | B388: =B387 -> 1270.695 | E388: 46327 | F388: =B387 -> 1270.695 | H388: 46327 | I388: =B386 -> 1270.695
A389: 46357 | B389: =B388 -> 1270.695 | E389: 46357 | F389: =B388 -> 1270.695 | H389: 46357 | I389: =B387 -> 1270.695
A390: 46388 | B390: =B389 -> 1270.695 | E390: 46388 | F390: =B389 -> 1270.695 | H390: 46388 | I390: =B388 -> 1270.695
A391: 46419 | B391: =B390 -> 1270.695 | E391: 46419 | F391: =B390 -> 1270.695 | H391: 46419 | I391: =B389 -> 1270.695
A392: 46447 | B392: =B391 -> 1270.695 | E392: 46447 | F392: =B391 -> 1270.695 | H392: 46447 | I392: =B390 -> 1270.695
A393: 46478 | B393: =B392 -> 1270.695 | E393: 46478 | F393: =B392 -> 1270.695 | H393: 46478 | I393: =B391 -> 1270.695
A394: 46508 | B394: =B393 -> 1270.695 | E394: 46508 | F394: =B393 -> 1270.695 | H394: 46508 | I394: =B392 -> 1270.695
... A1611: 83551 | B1611: =B1610 -> 1270.695 | E1611: 83551 | F1611: =B1610 -> 1270.695 | H1611: 83551 | I1611: =B1609 -> 1270.695

Sheet INCC - M
A1: 34547 | B1: 100 | E1: 34547 | F1: =B1 -> 100
A2: 34578 | B2: 100.312 | E2: 34578 | F2: =B1 -> 100
A3: 34608 | B3: 101.195 | E3: 34608 | F3: =B2 -> 100.312
A4: 34639 | B4: 102.628 | E4: 34639 | F4: =B3 -> 101.195
A5: 34669 | B5: 105.136 | E5: 34669 | F5: =B4 -> 102.628
A6: 34700 | B6: 106.581 | E6: 34700 | F6: =B5 -> 105.136
A7: 34731 | B7: 110.354 | E7: 34731 | F7: =B6 -> 106.581
A8: 34759 | B8: 113.014 | E8: 34759 | F8: =B7 -> 110.354
A9: 34790 | B9: 116.114 | E9: 34790 | F9: =B8 -> 113.014
A10: 34820 | B10: 118.936 | E10: 34820 | F10: =B9 -> 116.114
A11: 34851 | B11: 130.089 | E11: 34851 | F11: =B10 -> 118.936
A12: 34881 | B12: 133.608 | E12: 34881 | F12: =B11 -> 130.089
A13: 34912 | B13: 134.856 | E13: 34912 | F13: =B12 -> 133.608
... A382: 46143 | B382: 1264.353 | E382: 46143 | F382: =B381 -> 1254.655
A383: 46174 | B383: =B382 -> 1264.353 | E383: 46174 | F383: =B382 -> 1264.353
A384: 46204 | B384: =B383 -> 1264.353 | E384: 46204 | F384: =B383 -> 1264.353
A385: 46235 | B385: =B384 -> 1264.353 | E385: 46235 | F385: =B384 -> 1264.353
A386: 46266 | B386: =B385 -> 1264.353 | E386: 46266 | F386: =B385 -> 1264.353
A387: 46296 | B387: =B386 -> 1264.353 | E387: 46296 | F387: =B386 -> 1264.353
A388: 46327 | B388: =B387 -> 1264.353 | E388: 46327 | F388: =B387 -> 1264.353
A389: 46357 | B389: =B388 -> 1264.353 | E389: 46357 | F389: =B388 -> 1264.353
A390: 46388 | B390: =B389 -> 1264.353 | E390: 46388 | F390: =B389 -> 1264.353
A391: 46419 | B391: =B390 -> 1264.353 | E391: 46419 | F391: =B390 -> 1264.353
A392: 46447 | B392: =B391 -> 1264.353 | E392: 46447 | F392: =B391 -> 1264.353
A393: 46478 | B393: =B392 -> 1264.353 | E393: 46478 | F393: =B392 -> 1264.353
A394: 46508 | B394: =B393 -> 1264.353 | E394: 46508 | F394: =B393 -> 1264.353
... A1611: 83551 | B1611: =B1610 -> 1264.353 | E1611: 83551 | F1611: =B1610 -> 1264.353

Sheet Croma R02
A1: Croma
A2: Data Base | B2: INCC Base | C2: Valor Orçado | D2: Valor da Taxa (Reaj) | G2: Valor Previsto Total | I2: Valor Cobrado
A3: 44562 | B3: =VLOOKUP(A3,'INCC - M'!$A:$F,2,FALSE) -> 967.003 | C3: 7716524.6 | D3: =SUM(D5:D48) -> 9048524.4 | G3: =SUM(G5:G48) -> 9047537.7 | I3: =SUM(I5:I48) -> 9048524.4 | J3: =D3-I3 -> 0
A4: Mês | B4: INCC M | C4: Medição | D4: Valor Reajustado | F4: Medição Prevista | G4: Valor Previsto | I4: Valor Cobrado
A5: 44805 | B5: =VLOOKUP(A5,'INCC - M'!$E:$F,2,FALSE) -> 1045.469 | C5: 0.0088722564 | D5: =(C5*$C$3)*B5/$B$3 -> 74018.311 | F5: 0.0088722564 | G5: =F5*($C$3/$B$3*B5) -> 74018.311 | I5: 65261.141
A6: 44835 | B6: =VLOOKUP(A6,'INCC - M'!$E:$F,2,FALSE) -> 1046.507 | C6: 0.010507913 | D6: =(C6*$C$3)*B6/$B$3 -> 87751.091 | F6: 0.010507913 | G6: =F6*($C$3/$B$3*B6) -> 87751.091 | I6: 76993.481
A7: 44866 | B7: =VLOOKUP(A7,'INCC - M'!$E:$F,2,FALSE) -> 1046.956 | C7: 0.012182026 | D7: =(C7*$C$3)*B7/$B$3 -> 101775.18 | F7: 0.012182026 | G7: =F7*($C$3/$B$3*B7) -> 101775.18 | I7: 89459.092
A8: 44896 | B8: =VLOOKUP(A8,'INCC - M'!$E:$F,2,FALSE) -> 1048.429 | C8: 0.0073798258 | D8: =(C8*$C$3)*B8/$B$3 -> 61741.768 | F8: 0.0073798258 | G8: =F8*($C$3/$B$3*B8) -> 61741.768 | I8: 147746.59
A9: 44927 | B9: =VLOOKUP(A9,'INCC - M'!$E:$F,2,FALSE) -> 1051.249 | C9: 0.0085197165 | D9: =(C9*$C$3)*B9/$B$3 -> 71470.145 | F9: 0.0085197165 | G9: =F9*($C$3/$B$3*B9) -> 71470.145 | I9: 129512.84
A10: 44958 | B10: =VLOOKUP(A10,'INCC - M'!$E:$F,2,FALSE) -> 1054.561 | C10: 0.0080329958 | D10: =(C10*$C$3)*B10/$B$3 -> 67599.451 | F10: 0.0080329958 | G10: =F10*($C$3/$B$3*B10) -> 67599.451 | I10: 148727.02
A11: 44986 | B11: =VLOOKUP(A11,'INCC - M'!$E:$F,2,FALSE) -> 1056.775 | C11: 0.012312466 | D11: =(C11*$C$3)*B11/$B$3 -> 103829.67 | F11: 0.012312466 | G11: =F11*($C$3/$B$3*B11) -> 103829.67 | I11: 161939.65
A12: 45017 | B12: =VLOOKUP(A12,'INCC - M'!$E:$F,2,FALSE) -> 1058.65 | C12: 0.015471498 | D12: =(C12*$C$3)*B12/$B$3 -> 130700.93 | F12: 0.015471498 | G12: =F12*($C$3/$B$3*B12) -> 130700.93 | I12: 227086.8
A13: 45047 | B13: =VLOOKUP(A13,'INCC - M'!$E:$F,2,FALSE) -> 1061.071 | C13: 0.010770974 | D13: =(C13*$C$3)*B13/$B$3 -> 91199.688 | F13: 0.010770974 | G13: =F13*($C$3/$B$3*B13) -> 91199.688 | I13: 260326.74
A14: 45078 | B14: =VLOOKUP(A14,'INCC - M'!$E:$F,2,FALSE) -> 1065.289 | C14: 0.0099065106 | D14: =(C14*$C$3)*B14/$B$3 -> 84213.57 | F14: 0.0099065106 | G14: =F14*($C$3/$B$3*B14) -> 84213.57 | I14: 300590.25
A15: 45108 | B15: =VLOOKUP(A15,'INCC - M'!$E:$F,2,FALSE) -> 1074.292 | C15: 0.0084854621 | D15: =(C15*$C$3)*B15/$B$3 -> 72743.094 | F15: 0.0084854621 | G15: =F15*($C$3/$B$3*B15) -> 72743.094 | I15: 318921.73
A16: 45139 | B16: =VLOOKUP(A16,'INCC - M'!$E:$F,2,FALSE) -> 1074.895 | C16: 0.021512494 | D16: =(C16*$C$3)*B16/$B$3 -> 184523.09 | F16: 0.021512494 | G16: =F16*($C$3/$B$3*B16) -> 184523.09 | I16: 351008.9
... A48: 46113 | B48: =VLOOKUP(A48,'INCC - M'!$E:$F,2,FALSE) -> 1241.721 | C48: 0.00956152 | D48: =(C48*$C$3)*B48/$B$3 -> 94742.511 | F48: 0 | G48: =F48*($C$3/$B$3*B48) -> 0 | I48: 94742.511

Sheet Unna R02
A1: Unna | F1: saldo | G1: =G3-D3 -> 1200662.3 | H1: =G3-I3 -> 1200662.3
A2: Data Base | B2: INCC Base | C2: Valor Orçado c/ Aditivos | D2: Valor da Taxa (Reaj) | G2: Valor Previsto Total | I2: Valor Cobrado
A3: 44805 | B3: =VLOOKUP(A3,'INCC - M'!$E:$F,2,FALSE) -> 1045.469 | C3: 9017791.7 | D3: =SUM(D5:D42) -> 8671856.3 | G3: =SUM(G5:G42) -> 9872518.6 | I3: =SUM(I5:I42) -> 8671856.3 | J3: =D3-I3 -> 0
A4: Mês | B4: INCC M (n-1) | C4: Medição | D4: Valor Reajustado | F4: Medição Prevista | G4: Valor Previsto | I4: Valor Cobrado
A5: 45047 | B5: =VLOOKUP(A5,'INCC - M'!$E:$F,2,FALSE) -> 1061.071 | C5: 0.0089087769 | D5: =(C5*$C$3)*B5/$B$3 -> 81536.406 | F5: 0.0089087769 | G5: =F5*($C$3/$B$3*B5) -> 81536.406 | I5: 120763.23
A6: 45078 | B6: =VLOOKUP(A6,'INCC - M'!$E:$F,2,FALSE) -> 1065.289 | C6: 0.0093150901 | D6: =(C6*$C$3)*B6/$B$3 -> 85594.043 | F6: 0.0093150901 | G6: =F6*($C$3/$B$3*B6) -> 85594.043 | I6: 96629.992
A7: 45108 | B7: =VLOOKUP(A7,'INCC - M'!$E:$F,2,FALSE) -> 1074.292 | C7: 0.0091427032 | D7: =(C7*$C$3)*B7/$B$3 -> 84720.011 | F7: 0.0091427032 | G7: =F7*($C$3/$B$3*B7) -> 84720.011 | I7: 80899.093
A8: 45139 | B8: =VLOOKUP(A8,'INCC - M'!$E:$F,2,FALSE) -> 1074.895 | C8: 0.012304597 | D8: =(C8*$C$3)*B8/$B$3 -> 114083.4 | F8: 0.012304597 | G8: =F8*($C$3/$B$3*B8) -> 114083.4 | I8: 80944.501
A9: 45170 | B9: =VLOOKUP(A9,'INCC - M'!$E:$F,2,FALSE) -> 1077.497 | C9: 0.012658837 | D9: =(C9*$C$3)*B9/$B$3 -> 117651.89 | F9: 0.012658837 | G9: =F9*($C$3/$B$3*B9) -> 117651.89 | I9: 81140.444
A10: 45200 | B10: =VLOOKUP(A10,'INCC - M'!$E:$F,2,FALSE) -> 1080.071 | C10: 0.014858479 | D10: =(C10*$C$3)*B10/$B$3 -> 138425.38 | F10: 0.014858479 | G10: =F10*($C$3/$B$3*B10) -> 138425.38 | I10: 81334.278
A11: 45231 | B11: =VLOOKUP(A11,'INCC - M'!$E:$F,2,FALSE) -> 1082.251 | C11: 0.011469743 | D11: =(C11*$C$3)*B11/$B$3 -> 107070.72 | F11: 0.011469743 | G11: =F11*($C$3/$B$3*B11) -> 107070.72 | I11: 79646.204
A12: 45261 | B12: =VLOOKUP(A12,'INCC - M'!$E:$F,2,FALSE) -> 1083.335 | C12: 0.011616776 | D12: =(C12*$C$3)*B12/$B$3 -> 108551.9 | F12: 0.011616776 | G12: =F12*($C$3/$B$3*B12) -> 108551.9 | I12: 186336.3
A13: 45292 | B13: =VLOOKUP(A13,'INCC - M'!$E:$F,2,FALSE) -> 1086.15 | C13: 0.026287543 | D13: =(C13*$C$3)*B13/$B$3 -> 246279.82 | F13: 0.026287543 | G13: =F13*($C$3/$B$3*B13) -> 246279.82 | I13: 240728.89
A14: 45323 | B14: =VLOOKUP(A14,'INCC - M'!$E:$F,2,FALSE) -> 1088.663 | C14: 0.024278094 | D14: =(C14*$C$3)*B14/$B$3 -> 227980.18 | F14: 0.024278094 | G14: =F14*($C$3/$B$3*B14) -> 227980.18 | I14: 220790.53
A15: 45352 | B15: =VLOOKUP(A15,'INCC - M'!$E:$F,2,FALSE) -> 1090.871 | C15: 0.022869584 | D15: =(C15*$C$3)*B15/$B$3 -> 215189.31 | F15: 0.022869584 | G15: =F15*($C$3/$B$3*B15) -> 215189.31 | I15: 196033.97
A16: 45383 | B16: =VLOOKUP(A16,'INCC - M'!$E:$F,2,FALSE) -> 1093.503 | C16: 0.035019256 | D16: =(C16*$C$3)*B16/$B$3 -> 330305.59 | F16: 0.035019256 | G16: =F16*($C$3/$B$3*B16) -> 330305.59 | I16: 208671.66
... A35: 45962 | B35: =VLOOKUP(A35,'INCC - M'!$E:$F,2,FALSE) -> 1219.407 | C35: 0.024597903 | D35: =(C35*$C$3)*B35/$B$3 -> 258723.46 | F35: 0.02013286 | G35: =F35*($C$3/$B$3*B35) -> 211759.64 | I35: 258723.46
A36: 45992 | B36: =VLOOKUP(A36,'INCC - M'!$E:$F,2,FALSE) -> 1222.865 | D36: =(C36*$C$3)*B36/$B$3 -> 0 | F36: 0.0086789408 | G36: =F36*($C$3/$B$3*B36) -> 91544.926 | H36: =(F36*$G$1/(SUM($F$36:$F$48))) -> 340040.97
A37: 46023 | B37: =VLOOKUP(A37,'INCC - M'!$E:$F,2,FALSE) -> 1225.398 | D37: =(C37*$C$3)*B37/$B$3 -> 0 | F37: 0.0052835025 | G37: =F37*($C$3/$B$3*B37) -> 55845.492 | H37: =(F37*$G$1/(SUM($F$36:$F$48))) -> 207007.67
A38: 46054 | B38: =VLOOKUP(A38,'INCC - M'!$E:$F,2,FALSE) -> 1233.096 | D38: =(C38*$C$3)*B38/$B$3 -> 0 | F38: 0.002565261 | G38: =F38*($C$3/$B$3*B38) -> 27284.594 | H38: =(F38*$G$1/(SUM($F$36:$F$48))) -> 100506.95
A39: 46082 | B39: =VLOOKUP(A39,'INCC - M'!$E:$F,2,FALSE) -> 1237.312 | D39: =(C39*$C$3)*B39/$B$3 -> 0 | F39: 0.0028217872 | G39: =F39*($C$3/$B$3*B39) -> 30115.669 | H39: =(F39*$G$1/(SUM($F$36:$F$48))) -> 110557.64
A40: 46113 | B40: =VLOOKUP(A40,'INCC - M'!$E:$F,2,FALSE) -> 1241.721 | D40: =(C40*$C$3)*B40/$B$3 -> 0 | F40: 0.0028217872 | G40: =F40*($C$3/$B$3*B40) -> 30222.982 | H40: =(F40*$G$1/(SUM($F$36:$F$48))) -> 110557.64
A41: 46143 | B41: =VLOOKUP(A41,'INCC - M'!$E:$F,2,FALSE) -> 1254.655 | D41: =(C41*$C$3)*B41/$B$3 -> 0 | F41: 0.0026935241 | G41: =F41*($C$3/$B$3*B41) -> 29149.709 | H41: =(F41*$G$1/(SUM($F$36:$F$48))) -> 105532.3
A42: =EDATE(A41,1) -> 46174 | B42: =VLOOKUP(A42,'INCC - M'!$E:$F,2,FALSE) -> 1264.353 | D42: =(C42*$C$3)*B42/$B$3 -> 0 | F42: 0.0027762277 | G42: =F42*($C$3/$B$3*B42) -> 30276.974 | H42: =(F42*$G$1/(SUM($F$36:$F$48))) -> 108772.62
A43: =EDATE(A42,1) -> 46204 | B43: =VLOOKUP(A43,'INCC - M'!$E:$F,2,FALSE) -> 1264.353 | D43: =(C43*$C$3)*B43/$B$3 -> 0 | F43: 0.0024261163 | G43: =F43*($C$3/$B$3*B43) -> 26458.73 | H43: =(F43*$G$1/(SUM($F$36:$F$48))) -> 95055.255
A44: =EDATE(A43,1) -> 46235 | B44: =VLOOKUP(A44,'INCC - M'!$E:$F,2,FALSE) -> 1264.353 | D44: =(C44*$C$3)*B44/$B$3 -> 0 | F44: 0.00011552444 | G44: =F44*($C$3/$B$3*B44) -> 1259.886 | H44: =(F44*$G$1/(SUM($F$36:$F$48))) -> 4526.2484
A45: =EDATE(A44,1) -> 46266 | B45: =VLOOKUP(A45,'INCC - M'!$E:$F,2,FALSE) -> 1264.353 | D45: =(C45*$C$3)*B45/$B$3 -> 0 | F45: 0.0001210256 | G45: =F45*($C$3/$B$3*B45) -> 1319.8805 | H45: =(F45*$G$1/(SUM($F$36:$F$48))) -> 4741.784
A46: =EDATE(A45,1) -> 46296 | B46: =VLOOKUP(A46,'INCC - M'!$E:$F,2,FALSE) -> 1264.353 | D46: =(C46*$C$3)*B46/$B$3 -> 0 | F46: 0.0001210256 | G46: =F46*($C$3/$B$3*B46) -> 1319.8805 | H46: =(F46*$G$1/(SUM($F$36:$F$48))) -> 4741.784
A47: =EDATE(A46,1) -> 46327 | B47: =VLOOKUP(A47,'INCC - M'!$E:$F,2,FALSE) -> 1264.353 | D47: =(C47*$C$3)*B47/$B$3 -> 0 | F47: 0.00011552444 | G47: =F47*($C$3/$B$3*B47) -> 1259.886 | H47: =(F47*$G$1/(SUM($F$36:$F$48))) -> 4526.2484
A48: =EDATE(A47,1) -> 46357 | B48: =VLOOKUP(A48,'INCC - M'!$E:$F,2,FALSE) -> 1264.353 | D48: =(C48*$C$3)*B48/$B$3 -> 0 | F48: 0.00010452211 | G48: =F48*($C$3/$B$3*B48) -> 1139.8968 | H48: =(F48*$G$1/(SUM($F$36:$F$48))) -> 4095.1771

Sheet Unna R02 - Reorç
A1: Unna | F1: saldo | G1: =G3-D3 -> 300692.98 | H1: =G3-I3 -> 300692.98
A2: Data Base | B2: INCC Base | C2: Valor Orçado c/ Aditivos | D2: Valor da Taxa (Reaj) | G2: Valor Previsto Total | I2: Valor Cobrado
A3: 44805 | B3: =VLOOKUP(A3,'INCC - M'!$E:$F,2,FALSE) -> 1045.469 | C3: =9300085.301432+K22 -> 9311845.1 | D3: =SUM(D5:D48) -> 9976432.8 | G3: =SUM(G5:G48) -> 10277126 | I3: =SUM(I5:I48) -> 9976432.8 | J3: =D3-I3 -> 0 | K3: Aditivos Incorporação | L3: Data | M3: Descrição
A4: Mês | B4: INCC M (n-1) | C4: Medição | D4: Valor Reajustado | F4: Medição Prevista | G4: Valor Previsto | I4: Valor Cobrado | K4: 3231.9 | L4: 46107 | M4: O aditivo de MO para aplicação de cimento queimado foi necessário devido a modificação de especificação de produto.
A5: 45047 | B5: =VLOOKUP(A5,'INCC - M'!$E:$F,2,FALSE) -> 1061.071 | C5: 0.0089087769 | D5: =(C5*$C$3)*B5/$B$3 -> 84195.157 | F5: 0.0089087769 | G5: =F5*($C$3/$B$3*B5) -> 84195.157 | I5: 120763.23 | K5: 2859.07 | L5: 46104 | M5: O aditivo é referente aos ajustes e solicitações de itens de bancada de interiores não apresentados em projeto.
A6: 45078 | B6: =VLOOKUP(A6,'INCC - M'!$E:$F,2,FALSE) -> 1065.289 | C6: 0.0093150901 | D6: =(C6*$C$3)*B6/$B$3 -> 88385.106 | F6: 0.0093150901 | G6: =F6*($C$3/$B$3*B6) -> 88385.106 | I6: 96629.992 | K6: 5668.85 | L6: 46156 | M6: Aditivo e-mail 14/05
A7: 45108 | B7: =VLOOKUP(A7,'INCC - M'!$E:$F,2,FALSE) -> 1074.292 | C7: 0.0091427032 | D7: =(C7*$C$3)*B7/$B$3 -> 87482.573 | F7: 0.0091427032 | G7: =F7*($C$3/$B$3*B7) -> 87482.573 | I7: 80899.093
A8: 45139 | B8: =VLOOKUP(A8,'INCC - M'!$E:$F,2,FALSE) -> 1074.895 | C8: 0.012304597 | D8: =(C8*$C$3)*B8/$B$3 -> 117803.45 | F8: 0.012304597 | G8: =F8*($C$3/$B$3*B8) -> 117803.45 | I8: 80944.501
A9: 45170 | B9: =VLOOKUP(A9,'INCC - M'!$E:$F,2,FALSE) -> 1077.497 | C9: 0.012658837 | D9: =(C9*$C$3)*B9/$B$3 -> 121488.3 | F9: 0.012658837 | G9: =F9*($C$3/$B$3*B9) -> 121488.3 | I9: 81140.444
A10: 45200 | B10: =VLOOKUP(A10,'INCC - M'!$E:$F,2,FALSE) -> 1080.071 | C10: 0.014858479 | D10: =(C10*$C$3)*B10/$B$3 -> 142939.17 | F10: 0.014858479 | G10: =F10*($C$3/$B$3*B10) -> 142939.17 | I10: 81334.278
A11: 45231 | B11: =VLOOKUP(A11,'INCC - M'!$E:$F,2,FALSE) -> 1082.251 | C11: 0.011469743 | D11: =(C11*$C$3)*B11/$B$3 -> 110562.1 | F11: 0.011469743 | G11: =F11*($C$3/$B$3*B11) -> 110562.1 | I11: 79646.204
A12: 45261 | B12: =VLOOKUP(A12,'INCC - M'!$E:$F,2,FALSE) -> 1083.335 | C12: 0.011616776 | D12: =(C12*$C$3)*B12/$B$3 -> 112091.58 | F12: 0.011616776 | G12: =F12*($C$3/$B$3*B12) -> 112091.58 | I12: 186336.3
A13: 45292 | B13: =VLOOKUP(A13,'INCC - M'!$E:$F,2,FALSE) -> 1086.15 | C13: 0.026287543 | D13: =(C13*$C$3)*B13/$B$3 -> 254310.55 | F13: 0.026287543 | G13: =F13*($C$3/$B$3*B13) -> 254310.55 | I13: 240728.89
A14: 45323 | B14: =VLOOKUP(A14,'INCC - M'!$E:$F,2,FALSE) -> 1088.663 | C14: 0.024278094 | D14: =(C14*$C$3)*B14/$B$3 -> 235414.19 | F14: 0.024278094 | G14: =F14*($C$3/$B$3*B14) -> 235414.19 | I14: 220790.53
A15: 45352 | B15: =VLOOKUP(A15,'INCC - M'!$E:$F,2,FALSE) -> 1090.871 | C15: 0.022869584 | D15: =(C15*$C$3)*B15/$B$3 -> 222206.24 | F15: 0.022869584 | G15: =F15*($C$3/$B$3*B15) -> 222206.24 | I15: 196033.97
A16: 45383 | B16: =VLOOKUP(A16,'INCC - M'!$E:$F,2,FALSE) -> 1093.503 | C16: 0.035019256 | D16: =(C16*$C$3)*B16/$B$3 -> 341076.24 | F16: 0.035019256 | G16: =F16*($C$3/$B$3*B16) -> 341076.24 | I16: 208671.66
A17: 45413 | B17: =VLOOKUP(A17,'INCC - M'!$E:$F,2,FALSE) -> 1097.991 | C17: 0.044570825 | D17: =(C17*$C$3)*B17/$B$3 -> 435887.12 | F17: 0.044570825 | G17: =F17*($C$3/$B$3*B17) -> 435887.12 | I17: 202950.99
A18: 45444 | B18: =VLOOKUP(A18,'INCC - M'!$E:$F,2,FALSE) -> 1104.457 | C18: 0.028628016 | D18: =(C18*$C$3)*B18/$B$3 -> 281620.75 | F18: 0.028628016 | G18: =F18*($C$3/$B$3*B18) -> 281620.75 | I18: 221278.37
... A21: 45536 | B21: =VLOOKUP(A21,'INCC - M'!$E:$F,2,FALSE) -> 1129.639 | C21: 0.042585481 | D21: =(C21*$C$3)*B21/$B$3 -> 428475.33 | F21: 0.042585481 | G21: =F21*($C$3/$B$3*B21) -> 428475.33 | I21: 411661.14
A22: 45566 | B22: =VLOOKUP(A22,'INCC - M'!$E:$F,2,FALSE) -> 1136.521 | C22: 0.056026421 | D22: =(C22*$C$3)*B22/$B$3 -> 567146.07 | F22: 0.056026421 | G22: =F22*($C$3/$B$3*B22) -> 567146.07 | I22: 987706.94 | K22: =SUM(K4:K21) -> 11759.82
A23: 45597 | B23: =VLOOKUP(A23,'INCC - M'!$E:$F,2,FALSE) -> 1144.136 | C23: 0.038731061 | D23: =(C23*$C$3)*B23/$B$3 -> 394695 | F23: 0.038731061 | G23: =F23*($C$3/$B$3*B23) -> 394695 | I23: 382231.54
A24: 45627 | B24: =VLOOKUP(A24,'INCC - M'!$E:$F,2,FALSE) -> 1149.158 | C24: 0.027227772 | D24: =(C24*$C$3)*B24/$B$3 -> 278686.82 | F24: 0.027227772 | G24: =F24*($C$3/$B$3*B24) -> 278686.82 | I24: 295576.59
A25: 45658 | B25: =VLOOKUP(A25,'INCC - M'!$E:$F,2,FALSE) -> 1154.99 | C25: 0.021514779 | D25: =(C25*$C$3)*B25/$B$3 -> 221329.7 | F25: 0.021514779 | G25: =F25*($C$3/$B$3*B25) -> 221329.7 | I25: 214057.93
A26: 45689 | B26: =VLOOKUP(A26,'INCC - M'!$E:$F,2,FALSE) -> 1163.221 | C26: 0.035731168 | D26: =(C26*$C$3)*B26/$B$3 -> 370197.97 | F26: 0.035731168 | G26: =F26*($C$3/$B$3*B26) -> 370197.97 | I26: 358507.7
A27: 45717 | B27: =VLOOKUP(A27,'INCC - M'!$E:$F,2,FALSE) -> 1169.156 | C27: 0.036477711 | D27: =(C27*$C$3)*B27/$B$3 -> 379860.92 | F27: 0.036477711 | G27: =F27*($C$3/$B$3*B27) -> 379860.92 | I27: 367865.51
A28: 45748 | B28: =VLOOKUP(A28,'INCC - M'!$E:$F,2,FALSE) -> 1173.586 | C28: 0.032651479 | D28: =(C28*$C$3)*B28/$B$3 -> 341304.77 | F28: 0.032651479 | G28: =F28*($C$3/$B$3*B28) -> 341304.77 | I28: 330526.9
A29: 45778 | B29: =VLOOKUP(A29,'INCC - M'!$E:$F,2,FALSE) -> 1180.564 | C29: 0.03453947 | D29: =(C29*$C$3)*B29/$B$3 -> 363186.57 | F29: 0.03453947 | G29: =F29*($C$3/$B$3*B29) -> 363186.57 | I29: 351717.71
A30: 45809 | B30: =VLOOKUP(A30,'INCC - M'!$E:$F,2,FALSE) -> 1183.606 | C30: 0.030976831 | D30: =(C30*$C$3)*B30/$B$3 -> 326564.31 | F30: 0.030976831 | G30: =F30*($C$3/$B$3*B30) -> 326564.31 | I30: 316251.93
A31: 45839 | B31: =VLOOKUP(A31,'INCC - M'!$E:$F,2,FALSE) -> 1194.912 | C31: 0.023330078 | D31: =(C31*$C$3)*B31/$B$3 -> 248299.98 | F31: 0.023330078 | G31: =F31*($C$3/$B$3*B31) -> 248299.98 | I31: 240459.06
A32: 45870 | B32: =VLOOKUP(A32,'INCC - M'!$E:$F,2,FALSE) -> 1205.838 | C32: 0.030207081 | D32: =(C32*$C$3)*B32/$B$3 -> 324430.97 | F32: 0.030207081 | G32: =F32*($C$3/$B$3*B32) -> 324430.97 | I32: 314082.43
A33: 45901 | B33: =VLOOKUP(A33,'INCC - M'!$E:$F,2,FALSE) -> 1214.239 | C33: 0.041989093 | D33: =(C33*$C$3)*B33/$B$3 -> 454114.38 | F33: 0.041989093 | G33: =F33*($C$3/$B$3*B33) -> 454114.38 | I33: 330313.63
A34: 45931 | B34: =VLOOKUP(A34,'INCC - M'!$E:$F,2,FALSE) -> 1216.825 | C34: 0.04658823 | D34: =(C34*$C$3)*B34/$B$3 -> 504927.38 | F34: 0.04658823 | G34: =F34*($C$3/$B$3*B34) -> 504927.38 | I34: 598546.62
... A41: 46143 | B41: =VLOOKUP(A41,'INCC - M'!$E:$F,2,FALSE) -> 1254.655 | C41: 0.00467518 | D41: =(C41*$C$3)*B41/$B$3 -> 52245.302 | F41: 0.0088 | G41: =F41*($C$3/$B$3*B41) -> 98340.311 | I41: 58244.656
A42: =EDATE(A41,1) -> 46174 | B42: =VLOOKUP(A42,'INCC - M'!$E:$F,2,FALSE) -> 1264.353 | C42: 0.00616659 | D42: =(C42*$C$3)*B42/$B$3 -> 69444.523 | F42: 0.007728 | G42: =F42*($C$3/$B$3*B42) -> 87028.208 | I42: 69444.523
A43: =EDATE(A42,1) -> 46204 | B43: =VLOOKUP(A43,'INCC - M'!$E:$F,2,FALSE) -> 1264.353 | D43: =(C43*$C$3)*B43/$B$3 -> 0 | F43: 0.006258 | G43: =F43*($C$3/$B$3*B43) -> 70473.929 | H43: =(F43*$G$1/(SUM($F$43:$F$48))) -> 92412.321
A44: =EDATE(A43,1) -> 46235 | B44: =VLOOKUP(A44,'INCC - M'!$E:$F,2,FALSE) -> 1264.353 | D44: =(C44*$C$3)*B44/$B$3 -> 0 | F44: 0.005208 | G44: =F44*($C$3/$B$3*B44) -> 58649.445 | H44: =(F44*$G$1/(SUM($F$43:$F$48))) -> 76906.898
A45: =EDATE(A44,1) -> 46266 | B45: =VLOOKUP(A45,'INCC - M'!$E:$F,2,FALSE) -> 1264.353 | D45: =(C45*$C$3)*B45/$B$3 -> 0 | F45: 0.004137 | G45: =F45*($C$3/$B$3*B45) -> 46588.47 | H45: =(F45*$G$1/(SUM($F$43:$F$48))) -> 61091.366
A46: =EDATE(A45,1) -> 46296 | B46: =VLOOKUP(A46,'INCC - M'!$E:$F,2,FALSE) -> 1264.353 | D46: =(C46*$C$3)*B46/$B$3 -> 0 | F46: 0.002247 | G46: =F46*($C$3/$B$3*B46) -> 25304.397 | H46: =(F46*$G$1/(SUM($F$43:$F$48))) -> 33181.605
A47: =EDATE(A46,1) -> 46327 | B47: =VLOOKUP(A47,'INCC - M'!$E:$F,2,FALSE) -> 1264.353 | D47: =(C47*$C$3)*B47/$B$3 -> 0 | F47: 0.002 | G47: =F47*($C$3/$B$3*B47) -> 22522.828 | H47: =(F47*$G$1/(SUM($F$43:$F$48))) -> 29534.139
A48: =EDATE(A47,1) -> 46357 | B48: =VLOOKUP(A48,'INCC - M'!$E:$F,2,FALSE) -> 1264.353 | D48: =(C48*$C$3)*B48/$B$3 -> 0 | F48: 0.0005124 | G48: =F48*($C$3/$B$3*B48) -> 5770.3486 | H48: =(F48*$G$1/(SUM($F$43:$F$48))) -> 7566.6464
...

Sheet Qoya R01
A1: Qoya | F1: saldo | G1: =G3-D3 -> 3639935.1 | H1: =G3-I3 -> 3639935.1
A2: Data Base | B2: INCC Base | C2: Valor Orçado | D2: Valor da Taxa (Reaj) | G2: Valor Previsto Total | I2: Valor Cobrado
A3: 45170 | B3: =VLOOKUP(A3,'INCC - DI'!$E:$F,2,FALSE) -> 1078.412 | C3: 5245908.3 | D3: =SUM(D5:D45) -> 2395147.1 | G3: =SUM(G5:G45) -> 6035082.2 | I3: =SUM(I5:I45) -> 2395147.1 | J3: =D3-I3 -> 0
A4: Mês | B4: INCC DI (n-1) | C4: Medição | D4: Valor da Taxa (Reaj) | F4: Medição Prevista | G4: Valor Previsto | I4: Valor Cobrado
A5: 45413 | B5: =VLOOKUP(A5,'INCC - DI'!$E:$F,2,FALSE) -> 1101.389 | C5: 0.011376964 | D5: =(C5*$C$3)*B5/$B$3 -> 60954.127 | F5: 0.0112 | G5: =F5*($C$3/$B$3*B5) -> 60006.009 | I5: 40749.62
A6: 45444 | B6: =VLOOKUP(A6,'INCC - DI'!$E:$F,2,FALSE) -> 1110.887 | C6: 0.020986748 | D6: =(C6*$C$3)*B6/$B$3 -> 113409.91 | F6: 0.011 | G6: =F6*($C$3/$B$3*B6) -> 59442.704 | I6: 60954.13
A7: 45474 | B7: =VLOOKUP(A7,'INCC - DI'!$E:$F,2,FALSE) -> 1118.827 | C7: 0.020545121 | D7: =(C7*$C$3)*B7/$B$3 -> 111816.95 | F7: 0.0326 | G7: =F7*($C$3/$B$3*B7) -> 177425.7 | I7: 111023.41
A8: 45505 | B8: =VLOOKUP(A8,'INCC - DI'!$E:$F,2,FALSE) -> 1126.916 | C8: 0.017857073 | D8: =(C8*$C$3)*B8/$B$3 -> 97889.884 | F8: 0.0231 | G8: =F8*($C$3/$B$3*B8) -> 126630.85 | I8: 97187.23
A9: 45536 | B9: =VLOOKUP(A9,'INCC - DI'!$E:$F,2,FALSE) -> 1134.775 | C9: 0.0091972732 | D9: =(C9*$C$3)*B9/$B$3 -> 50769.727 | F9: 0.0116 | G9: =F9*($C$3/$B$3*B9) -> 64032.983 | I9: 50771.049
A10: 45566 | B10: =VLOOKUP(A10,'INCC - DI'!$E:$F,2,FALSE) -> 1141.398 | C10: 0.010291113 | D10: =(C10*$C$3)*B10/$B$3 -> 57139.371 | F10: 0.0082 | G10: =F10*($C$3/$B$3*B10) -> 45528.878 | I10: 93646.551
A11: 45597 | B11: =VLOOKUP(A11,'INCC - DI'!$E:$F,2,FALSE) -> 1149.17 | C11: 0.0087224533 | D11: =(C11*$C$3)*B11/$B$3 -> 48759.464 | F11: 0.0085 | G11: =F11*($C$3/$B$3*B11) -> 47515.925 | I11: 98510.99
A12: 45627 | B12: =VLOOKUP(A12,'INCC - DI'!$E:$F,2,FALSE) -> 1153.725 | C12: 0.0071784377 | D12: =(C12*$C$3)*B12/$B$3 -> 40287.306 | F12: 0.0049 | G12: =F12*($C$3/$B$3*B12) -> 27500.106 | I12: 50161.357
A13: 45658 | B13: =VLOOKUP(A13,'INCC - DI'!$E:$F,2,FALSE) -> 1159.536 | C13: 0.018751261 | D13: =(C13*$C$3)*B13/$B$3 -> 105767.13 | F13: 0.0121 | G13: =F13*($C$3/$B$3*B13) -> 68250.461 | I13: 85841.407
A14: 45689 | B14: =VLOOKUP(A14,'INCC - DI'!$E:$F,2,FALSE) -> 1169.116 | C14: 0.012703958 | D14: =(C14*$C$3)*B14/$B$3 -> 72249.131 | F14: 0.0213 | G14: =F14*($C$3/$B$3*B14) -> 121135.99 | I14: 72249.131
A15: 45717 | B15: =VLOOKUP(A15,'INCC - DI'!$E:$F,2,FALSE) -> 1173.775 | C15: 0.012229501 | D15: =(C15*$C$3)*B15/$B$3 -> 69827.993 | F15: 0.013 | G15: =F15*($C$3/$B$3*B15) -> 74227.39 | I15: 67776.115
A16: 45748 | B16: =VLOOKUP(A16,'INCC - DI'!$E:$F,2,FALSE) -> 1178.386 | C16: 0.012810321 | D16: =(C16*$C$3)*B16/$B$3 -> 73431.699 | F16: 0.0111 | G16: =F16*($C$3/$B$3*B16) -> 63627.746 | I16: 73144.363
... A30: 46174 | B30: =VLOOKUP(A30,'INCC - DI'!$E:$F,2,FALSE) -> 1270.695 | C30: 0.03908218 | D30: =(C30*$C$3)*B30/$B$3 -> 241577.28 | F30: 0.0412 | G30: =F30*($C$3/$B$3*B30) -> 254668.08 | I30: 243242.47
A31: 46204 | B31: =VLOOKUP(A31,'INCC - DI'!$E:$F,2,FALSE) -> 1270.695 | D31: =(C31*$C$3)*B31/$B$3 -> 0 | F31: 0.0427 | G31: =F31*($C$3/$B$3*B31) -> 263939.98 | H31: =(F31*$G$1/(SUM($F$31:$F$45))) -> 262542.61
A32: 46235 | B32: =VLOOKUP(A32,'INCC - DI'!$E:$F,2,FALSE) -> 1270.695 | D32: =(C32*$C$3)*B32/$B$3 -> 0 | F32: 0.0407 | G32: =F32*($C$3/$B$3*B32) -> 251577.45 | H32: =(F32*$G$1/(SUM($F$31:$F$45))) -> 250245.54
A33: 46266 | B33: =VLOOKUP(A33,'INCC - DI'!$E:$F,2,FALSE) -> 1270.695 | D33: =(C33*$C$3)*B33/$B$3 -> 0 | F33: 0.042 | G33: =F33*($C$3/$B$3*B33) -> 259613.1 | H33: =(F33*$G$1/(SUM($F$31:$F$45))) -> 258238.64
A34: 46296 | B34: =VLOOKUP(A34,'INCC - DI'!$E:$F,2,FALSE) -> 1270.695 | D34: =(C34*$C$3)*B34/$B$3 -> 0 | F34: 0.0454 | G34: =F34*($C$3/$B$3*B34) -> 280629.39 | H34: =(F34*$G$1/(SUM($F$31:$F$45))) -> 279143.67
A35: 46327 | B35: =VLOOKUP(A35,'INCC - DI'!$E:$F,2,FALSE) -> 1270.695 | D35: =(C35*$C$3)*B35/$B$3 -> 0 | F35: 0.0451 | G35: =F35*($C$3/$B$3*B35) -> 278775.02 | H35: =(F35*$G$1/(SUM($F$31:$F$45))) -> 277299.11
A36: 46357 | B36: =VLOOKUP(A36,'INCC - DI'!$E:$F,2,FALSE) -> 1270.695 | D36: =(C36*$C$3)*B36/$B$3 -> 0 | F36: 0.0333 | G36: =F36*($C$3/$B$3*B36) -> 205836.1 | H36: =(F36*$G$1/(SUM($F$31:$F$45))) -> 204746.35
A37: 46388 | B37: =VLOOKUP(A37,'INCC - DI'!$E:$F,2,FALSE) -> 1270.695 | D37: =(C37*$C$3)*B37/$B$3 -> 0 | F37: 0.0505 | G37: =F37*($C$3/$B$3*B37) -> 312153.84 | H37: =(F37*$G$1/(SUM($F$31:$F$45))) -> 310501.22
A38: 46419 | B38: =VLOOKUP(A38,'INCC - DI'!$E:$F,2,FALSE) -> 1270.695 | D38: =(C38*$C$3)*B38/$B$3 -> 0 | F38: 0.0577 | G38: =F38*($C$3/$B$3*B38) -> 356658.94 | H38: =(F38*$G$1/(SUM($F$31:$F$45))) -> 354770.7
A39: 46447 | B39: =VLOOKUP(A39,'INCC - DI'!$E:$F,2,FALSE) -> 1270.695 | D39: =(C39*$C$3)*B39/$B$3 -> 0 | F39: 0.0611 | G39: =F39*($C$3/$B$3*B39) -> 377675.24 | H39: =(F39*$G$1/(SUM($F$31:$F$45))) -> 375675.73
A40: 46478 | B40: =VLOOKUP(A40,'INCC - DI'!$E:$F,2,FALSE) -> 1270.695 | D40: =(C40*$C$3)*B40/$B$3 -> 0 | F40: 0.0576 | G40: =F40*($C$3/$B$3*B40) -> 356040.82 | H40: =(F40*$G$1/(SUM($F$31:$F$45))) -> 354155.85
A41: 46508 | B41: =VLOOKUP(A41,'INCC - DI'!$E:$F,2,FALSE) -> 1270.695 | D41: =(C41*$C$3)*B41/$B$3 -> 0 | F41: 0.0389 | G41: =F41*($C$3/$B$3*B41) -> 240451.18 | H41: =(F41*$G$1/(SUM($F$31:$F$45))) -> 239178.17
A42: 46539 | B42: =VLOOKUP(A42,'INCC - DI'!$E:$F,2,FALSE) -> 1270.695 | D42: =(C42*$C$3)*B42/$B$3 -> 0 | F42: 0.0355 | G42: =F42*($C$3/$B$3*B42) -> 219434.88 | H42: =(F42*$G$1/(SUM($F$31:$F$45))) -> 218273.13
... A45: 46631 | B45: =VLOOKUP(A45,'INCC - DI'!$E:$F,2,FALSE) -> 1270.695 | D45: =(C45*$C$3)*B45/$B$3 -> 0 | F45: 0.0006 | G45: =F45*($C$3/$B$3*B45) -> 3708.7585 | H45: =(F45*$G$1/(SUM($F$31:$F$45))) -> 3689.1234
C46: =SUM(C5:C45) -> 0.41102786
C47: 0.41102786
C48: =C47-C46 -> 0

Sheet Nizza
A1: Nizza | F1: saldo | G1: =G3-D3 -> 915103.41 | H1: =G3-I3 -> 915103.41
A2: Data Base | B2: INCC Base | C2: Valor Orçado | D2: Valor da Taxa (Reaj) | G2: Valor Previsto Total | I2: Valor Cobrado
A3: 45323 | B3: =VLOOKUP(A3,'INCC - DI'!$E:$F,2,FALSE) -> 1091.25 | C3: =2391293.1+K22 -> 2389464.3 | D3: =SUM(D5:D34) -> 1777550.8 | G3: =SUM(G5:G34) -> 2692654.2 | I3: =SUM(I5:I34) -> 1777550.8 | J3: =D3-I3 -> 0 | K3: Aditivos Incorporação | L3: Data | M3: Descrição
A4: Mês | B4: INCC DI (n-1) | C4: Medição | D4: Valor da Taxa (Reaj) | F4: Medição Prevista | G4: Valor Previsto | I4: Valor Cobrado | K4: -2855.41 | L4: 46139 | M4: Mudança banheira duplex
A5: 45536 | B5: =VLOOKUP(A5,'INCC - DI'!$E:$F,2,FALSE) -> 1134.775 | C5: 0.022264524 | D5: =(C5*$C$3)*B5/$B$3 -> 55322.202 | F5: 0.022264524 | G5: =F5*($C$3/$B$3*B5) -> 55322.202 | I5: 55364.544 | K5: 1026.58 | L5: 46174 | M5: Quebra duto chaminé
A6: =EDATE(A5,1) -> 45566 | B6: =VLOOKUP(A6,'INCC - DI'!$E:$F,2,FALSE) -> 1141.398 | C6: 0.023718825 | D6: =(C6*$C$3)*B6/$B$3 -> 59279.778 | F6: 0.023718825 | G6: =F6*($C$3/$B$3*B6) -> 59279.778 | I6: 59325.149
A7: =EDATE(A6,1) -> 45597 | B7: =VLOOKUP(A7,'INCC - DI'!$E:$F,2,FALSE) -> 1149.17 | C7: 0.01849369 | D7: =(C7*$C$3)*B7/$B$3 -> 46535.472 | F7: 0.01849369 | G7: =F7*($C$3/$B$3*B7) -> 46535.472 | I7: 47127.893
A8: =EDATE(A7,1) -> 45627 | B8: =VLOOKUP(A8,'INCC - DI'!$E:$F,2,FALSE) -> 1153.725 | C8: 0.0076900948 | D8: =(C8*$C$3)*B8/$B$3 -> 19427.203 | F8: 0.0076900948 | G8: =F8*($C$3/$B$3*B8) -> 19427.203 | I8: 26536.03
A9: =EDATE(A8,1) -> 45658 | B9: =VLOOKUP(A9,'INCC - DI'!$E:$F,2,FALSE) -> 1159.536 | C9: 0.019149474 | D9: =(C9*$C$3)*B9/$B$3 -> 48620.269 | F9: 0.019149474 | G9: =F9*($C$3/$B$3*B9) -> 48620.269 | I9: 41006.72
A10: =EDATE(A9,1) -> 45689 | B10: =VLOOKUP(A10,'INCC - DI'!$E:$F,2,FALSE) -> 1169.116 | C10: 0.011845312 | D10: =(C10*$C$3)*B10/$B$3 -> 30323.575 | F10: 0.011845312 | G10: =F10*($C$3/$B$3*B10) -> 30323.575 | I10: 30345.78
A11: =EDATE(A10,1) -> 45717 | B11: =VLOOKUP(A11,'INCC - DI'!$E:$F,2,FALSE) -> 1173.775 | C11: 0.01745414 | D11: =(C11*$C$3)*B11/$B$3 -> 44860.035 | F11: 0.01745414 | G11: =F11*($C$3/$B$3*B11) -> 44860.035 | I11: 44895.373
A12: =EDATE(A11,1) -> 45748 | B12: =VLOOKUP(A12,'INCC - DI'!$E:$F,2,FALSE) -> 1178.386 | C12: 0.030645598 | D12: =(C12*$C$3)*B12/$B$3 -> 79073.682 | F12: 0.030645598 | G12: =F12*($C$3/$B$3*B12) -> 79073.682 | I12: 78824.553
A13: =EDATE(A12,1) -> 45778 | B13: =VLOOKUP(A13,'INCC - DI'!$E:$F,2,FALSE) -> 1184.462 | C13: 0.042340208 | D13: =(C13*$C$3)*B13/$B$3 -> 109812.15 | F13: 0.042340208 | G13: =F13*($C$3/$B$3*B13) -> 109812.15 | I13: 110205.85
A14: =EDATE(A13,1) -> 45809 | B14: =VLOOKUP(A14,'INCC - DI'!$E:$F,2,FALSE) -> 1191.327 | C14: 0.027457723 | D14: =(C14*$C$3)*B14/$B$3 -> 71626.181 | F14: 0.027457723 | G14: =F14*($C$3/$B$3*B14) -> 71626.181 | I14: 71681.001
A15: =EDATE(A14,1) -> 45839 | B15: =VLOOKUP(A15,'INCC - DI'!$E:$F,2,FALSE) -> 1199.509 | C15: 0.042386792 | D15: =(C15*$C$3)*B15/$B$3 -> 111329.52 | F15: 0.042386792 | G15: =F15*($C$3/$B$3*B15) -> 111329.52 | I15: 111414.73
A16: =EDATE(A15,1) -> 45870 | B16: =VLOOKUP(A16,'INCC - DI'!$E:$F,2,FALSE) -> 1210.471 | C16: 0.042077977 | D16: =(C16*$C$3)*B16/$B$3 -> 111528.41 | F16: 0.042077977 | G16: =F16*($C$3/$B$3*B16) -> 111528.41 | I16: 111613.77
A17: =EDATE(A16,1) -> 45901 | B17: =VLOOKUP(A17,'INCC - DI'!$E:$F,2,FALSE) -> 1216.706 | C17: 0.040976342 | D17: =(C17*$C$3)*B17/$B$3 -> 109167.94 | F17: 0.040976342 | G17: =F17*($C$3/$B$3*B17) -> 109167.94 | I17: 109251.5
... A21: =EDATE(A20,1) -> 46023 | B21: =VLOOKUP(A21,'INCC - DI'!$E:$F,2,FALSE) -> 1228.161 | C21: 0.037622097 | D21: =(C21*$C$3)*B21/$B$3 -> 101175.32 | F21: 0.037622101 | G21: =F21*($C$3/$B$3*B21) -> 101175.33 | I21: 101252.76
A22: =EDATE(A21,1) -> 46054 | B22: =VLOOKUP(A22,'INCC - DI'!$E:$F,2,FALSE) -> 1237.036 | C22: 0.02499087 | D22: =(C22*$C$3)*B22/$B$3 -> 67692.413 | F22: 0.024797362 | G22: =F22*($C$3/$B$3*B22) -> 67168.261 | I22: 67744.223 | K22: =SUM(K4:K21) -> -1828.83
A23: =EDATE(A22,1) -> 46082 | B23: =VLOOKUP(A23,'INCC - DI'!$E:$F,2,FALSE) -> 1240.481 | C23: 0.03404703 | D23: =(C23*$C$3)*B23/$B$3 -> 92479.534 | F23: 0.041409091 | G23: =F23*($C$3/$B$3*B23) -> 112476.58 | I23: 92550.316
A24: =EDATE(A23,1) -> 46113 | B24: =VLOOKUP(A24,'INCC - DI'!$E:$F,2,FALSE) -> 1247.181 | C24: 0.05008716 | D24: =(C24*$C$3)*B24/$B$3 -> 136783.02 | F24: 0.056998845 | G24: =F24*($C$3/$B$3*B24) -> 155658.14 | I24: 136887.71
A25: =EDATE(A24,1) -> 46143 | B25: =VLOOKUP(A25,'INCC - DI'!$E:$F,2,FALSE) -> 1259.652 | C25: 0.022935 | D25: =(C25*$C$3)*B25/$B$3 -> 63259.479 | F25: 0.06491391 | G25: =F25*($C$3/$B$3*B25) -> 179046 | I25: 60757.706
A26: =EDATE(A25,1) -> 46174 | B26: =VLOOKUP(A26,'INCC - DI'!$E:$F,2,FALSE) -> 1270.695 | C26: 0.06015269 | D26: =(C26*$C$3)*B26/$B$3 -> 167368.09 | F26: 0.08785178 | G26: =F26*($C$3/$B$3*B26) -> 244437.69 | I26: 168685.89
A27: =EDATE(A26,1) -> 46204 | B27: =VLOOKUP(A27,'INCC - DI'!$E:$F,2,FALSE) -> 1270.695 | D27: =(C27*$C$3)*B27/$B$3 -> 0 | F27: 0.084873137 | G27: =F27*($C$3/$B$3*B27) -> 236149.95 | H27: =(F27*$G$1/(SUM($F$27:$F$46))) -> 315976.27
A28: =EDATE(A27,1) -> 46235 | B28: =VLOOKUP(A28,'INCC - DI'!$E:$F,2,FALSE) -> 1270.695 | D28: =(C28*$C$3)*B28/$B$3 -> 0 | F28: 0.067938376 | G28: =F28*($C$3/$B$3*B28) -> 189030.89 | H28: =(F28*$G$1/(SUM($F$27:$F$46))) -> 252929.44
A29: =EDATE(A28,1) -> 46266 | B29: =VLOOKUP(A29,'INCC - DI'!$E:$F,2,FALSE) -> 1270.695 | D29: =(C29*$C$3)*B29/$B$3 -> 0 | F29: 0.052792493 | G29: =F29*($C$3/$B$3*B29) -> 146889.17 | H29: =(F29*$G$1/(SUM($F$27:$F$46))) -> 196542.46
A30: =EDATE(A29,1) -> 46296 | B30: =VLOOKUP(A30,'INCC - DI'!$E:$F,2,FALSE) -> 1270.695 | D30: =(C30*$C$3)*B30/$B$3 -> 0 | F30: 0.027591773 | G30: =F30*($C$3/$B$3*B30) -> 76771.003 | H30: =(F30*$G$1/(SUM($F$27:$F$46))) -> 102722.08
A31: =EDATE(A30,1) -> 46327 | B31: =VLOOKUP(A31,'INCC - DI'!$E:$F,2,FALSE) -> 1270.695 | D31: =(C31*$C$3)*B31/$B$3 -> 0 | F31: 0.010680477 | G31: =F31*($C$3/$B$3*B31) -> 29717.224 | H31: =(F31*$G$1/(SUM($F$27:$F$46))) -> 39762.607
A32: =EDATE(A31,1) -> 46357 | B32: =VLOOKUP(A32,'INCC - DI'!$E:$F,2,FALSE) -> 1270.695 | D32: =(C32*$C$3)*B32/$B$3 -> 0 | F32: 0.00059921697 | G32: =F32*($C$3/$B$3*B32) -> 1667.2538 | H32: =(F32*$G$1/(SUM($F$27:$F$46))) -> 2230.8395
A33: =EDATE(A32,1) -> 46388 | B33: =VLOOKUP(A33,'INCC - DI'!$E:$F,2,FALSE) -> 1270.695 | D33: =(C33*$C$3)*B33/$B$3 -> 0 | F33: 0.00089882546 | G33: =F33*($C$3/$B$3*B33) -> 2500.8807 | H33: =(F33*$G$1/(SUM($F$27:$F$46))) -> 3346.2592
A34: =EDATE(A33,1) -> 46419 | B34: =VLOOKUP(A34,'INCC - DI'!$E:$F,2,FALSE) -> 1270.695 | D34: =(C34*$C$3)*B34/$B$3 -> 0 | F34: 0.00042801212 | G34: =F34*($C$3/$B$3*B34) -> 1190.8956 | H34: =(F34*$G$1/(SUM($F$27:$F$46))) -> 1593.4568
C35: =SUM(C5:C34) -> 0.6704879
C36: 0.6704879
C37: =C36-C35 -> 0

Sheet Lior
A1: Lior | F1: saldo | G1: =G3-D3 -> 251027.91 | H1: =G3-I3 -> 251027.91
A2: Data Base | B2: INCC Base | C2: Valor Orçado | D2: Valor da Taxa (Reaj) | G2: Valor Previsto Total | I2: Valor Cobrado
A3: 45231 | B3: =VLOOKUP(A3,'INCC - DI'!$E:$F,2,FALSE) -> 1084.242 | C3: =1789232.84+K22 -> 1789587.7 | D3: =SUM(D5:D34) -> 1740917.9 | G3: =SUM(G5:G34) -> 1991945.8 | I3: =SUM(I5:I34) -> 1740917.9 | J3: =D3-I3 -> 0 | K3: Aditivos Incorporação | L3: Data | M3: Descrição
A4: Mês | B4: INCC DI (n-1) | C4: Medição | D4: Valor da Taxa (Reaj) | F4: Medição Prevista | G4: Valor Previsto | I4: Valor Cobrado | K4: =2895.64*8% -> 231.6512 | L4: 46050 | M4: Execução em forro (material + mão de obra)
A5: 45444 | B5: =VLOOKUP(A5,'INCC - DI'!$E:$F,2,FALSE) -> 1110.887 | C5: 0.039456415 | D5: =(C5*$C$3)*B5/$B$3 -> 72345.956 | F5: 0.039456415 | G5: =F5*($C$3/$B$3*B5) -> 72345.956 | I5: 44403.901 | K5: =1539.63*8% -> 123.1704 | L5: 46050 | M5: Execução em textura rolada (material + mão de obra)
A6: 45474 | B6: =VLOOKUP(A6,'INCC - DI'!$E:$F,2,FALSE) -> 1118.827 | C6: 0.018879538 | D6: =(C6*$C$3)*B6/$B$3 -> 34864.308 | F6: 0.018879538 | G6: =F6*($C$3/$B$3*B6) -> 34864.308 | I6: 38627.574
A7: 45505 | B7: =VLOOKUP(A7,'INCC - DI'!$E:$F,2,FALSE) -> 1126.916 | C7: 0.020100982 | D7: =(C7*$C$3)*B7/$B$3 -> 37388.288 | F7: 0.020100982 | G7: =F7*($C$3/$B$3*B7) -> 37388.288 | I7: 36383.376
A8: 45536 | B8: =VLOOKUP(A8,'INCC - DI'!$E:$F,2,FALSE) -> 1134.775 | C8: 0.028013435 | D8: =(C8*$C$3)*B8/$B$3 -> 52469.011 | F8: 0.028013435 | G8: =F8*($C$3/$B$3*B8) -> 52469.011 | I8: 51058.763
A9: 45566 | B9: =VLOOKUP(A9,'INCC - DI'!$E:$F,2,FALSE) -> 1141.398 | C9: 0.022520492 | D9: =(C9*$C$3)*B9/$B$3 -> 42426.942 | F9: 0.022520492 | G9: =F9*($C$3/$B$3*B9) -> 42426.942 | I9: 67284.162
A10: 45597 | B10: =VLOOKUP(A10,'INCC - DI'!$E:$F,2,FALSE) -> 1149.17 | C10: 0.028623755 | D10: =(C10*$C$3)*B10/$B$3 -> 54292.224 | F10: 0.028623755 | G10: =F10*($C$3/$B$3*B10) -> 54292.224 | I10: 71309.804
A11: 45627 | B11: =VLOOKUP(A11,'INCC - DI'!$E:$F,2,FALSE) -> 1153.725 | C11: 0.031255531 | D11: =(C11*$C$3)*B11/$B$3 -> 59519.042 | F11: 0.031255531 | G11: =F11*($C$3/$B$3*B11) -> 59519.042 | I11: 34522.29
A12: 45658 | B12: =VLOOKUP(A12,'INCC - DI'!$E:$F,2,FALSE) -> 1159.536 | C12: 0.016029647 | D12: =(C12*$C$3)*B12/$B$3 -> 30678.559 | F12: 0.016029647 | G12: =F12*($C$3/$B$3*B12) -> 30678.559 | I12: 30073.834
A13: 45689 | B13: =VLOOKUP(A13,'INCC - DI'!$E:$F,2,FALSE) -> 1169.116 | C13: 0.026916266 | D13: =(C13*$C$3)*B13/$B$3 -> 51939.668 | F13: 0.026916266 | G13: =F13*($C$3/$B$3*B13) -> 51939.668 | I13: 53881.226
A14: 45717 | B14: =VLOOKUP(A14,'INCC - DI'!$E:$F,2,FALSE) -> 1173.775 | C14: 0.032724423 | D14: =(C14*$C$3)*B14/$B$3 -> 63399.174 | F14: 0.032724423 | G14: =F14*($C$3/$B$3*B14) -> 63399.174 | I14: 62717.953
A15: 45748 | B15: =VLOOKUP(A15,'INCC - DI'!$E:$F,2,FALSE) -> 1178.386 | C15: 0.034862822 | D15: =(C15*$C$3)*B15/$B$3 -> 67807.364 | F15: 0.034862822 | G15: =F15*($C$3/$B$3*B15) -> 67807.364 | I15: 66316.475
A16: 45778 | B16: =VLOOKUP(A16,'INCC - DI'!$E:$F,2,FALSE) -> 1184.462 | C16: 0.050790044 | D16: =(C16*$C$3)*B16/$B$3 -> 99294.793 | F16: 0.050790044 | G16: =F16*($C$3/$B$3*B16) -> 99294.793 | I16: 97753.589
A17: 45809 | B17: =VLOOKUP(A17,'INCC - DI'!$E:$F,2,FALSE) -> 1191.327 | C17: 0.043122788 | D17: =(C17*$C$3)*B17/$B$3 -> 84793.892 | F17: 0.043122788 | G17: =F17*($C$3/$B$3*B17) -> 84793.892 | I17: 85255.29
... A21: 45931 | B21: =VLOOKUP(A21,'INCC - DI'!$E:$F,2,FALSE) -> 1218.747 | C21: 0.053776678 | D21: =(C21*$C$3)*B21/$B$3 -> 108176.84 | F21: 0.053776679 | G21: =F21*($C$3/$B$3*B21) -> 108176.84 | I21: 106213.95
A22: 45962 | B22: =VLOOKUP(A22,'INCC - DI'!$E:$F,2,FALSE) -> 1222.356 | C22: 0.04465394 | D22: =(C22*$C$3)*B22/$B$3 -> 90091.588 | F22: 0.044653942 | G22: =F22*($C$3/$B$3*B22) -> 90091.592 | I22: 88456.864 | K22: =SUM(K4:K21) -> 354.8216
A23: 45992 | B23: =VLOOKUP(A23,'INCC - DI'!$E:$F,2,FALSE) -> 1225.633 | C23: 0.02926921 | D23: =(C23*$C$3)*B23/$B$3 -> 59210.428 | F23: 0.029269212 | G23: =F23*($C$3/$B$3*B23) -> 59210.432 | I23: 58136.046
A24: 46023 | B24: =VLOOKUP(A24,'INCC - DI'!$E:$F,2,FALSE) -> 1228.161 | C24: 0.0306 | D24: =(C24*$C$3)*B24/$B$3 -> 62030.243 | F24: 0.027149354 | G24: =F24*($C$3/$B$3*B24) -> 55035.327 | I24: 84936
A25: 46054 | B25: =VLOOKUP(A25,'INCC - DI'!$E:$F,2,FALSE) -> 1237.036 | C25: 0.02405107 | D25: =(C25*$C$3)*B25/$B$3 -> 49107.01 | F25: 0.027501714 | G25: =F25*($C$3/$B$3*B25) -> 56152.469 | I25: 49365.726
A26: 46082 | B26: =VLOOKUP(A26,'INCC - DI'!$E:$F,2,FALSE) -> 1240.481 | C26: 0.03721484 | D26: =(C26*$C$3)*B26/$B$3 -> 76196.149 | F26: 0.03258823 | G26: =F26*($C$3/$B$3*B26) -> 66723.319 | I26: 76474.34
A27: 46113 | B27: =VLOOKUP(A27,'INCC - DI'!$E:$F,2,FALSE) -> 1247.181 | C27: 0.029946162 | D27: =(C27*$C$3)*B27/$B$3 -> 61644.935 | F27: 0.022074526 | G27: =F27*($C$3/$B$3*B27) -> 45440.972 | I27: 61644.935
A28: 46143 | B28: =VLOOKUP(A28,'INCC - DI'!$E:$F,2,FALSE) -> 1259.652 | C28: 0.037260638 | D28: =(C28*$C$3)*B28/$B$3 -> 77468.942 | F28: 0.053621649 | G28: =F28*($C$3/$B$3*B28) -> 111485.27 | I28: 76701.972
A29: 46174 | B29: =VLOOKUP(A29,'INCC - DI'!$E:$F,2,FALSE) -> 1270.695 | C29: 0.05841594 | D29: =(C29*$C$3)*B29/$B$3 -> 122517.87 | F29: 0.062794275 | G29: =F29*($C$3/$B$3*B29) -> 131700.71 | I29: 123284.84
A30: 46204 | B30: =VLOOKUP(A30,'INCC - DI'!$E:$F,2,FALSE) -> 1270.695 | D30: =(C30*$C$3)*B30/$B$3 -> 0 | F30: 0.0517883 | G30: =F30*($C$3/$B$3*B30) -> 108617.48 | H30: =(F30*$G$1/(SUM($F$30:$F$46))) -> 116793.48
A31: 46235 | B31: =VLOOKUP(A31,'INCC - DI'!$E:$F,2,FALSE) -> 1270.695 | D31: =(C31*$C$3)*B31/$B$3 -> 0 | F31: 0.039085453 | G31: =F31*($C$3/$B$3*B31) -> 81975.339 | H31: =(F31*$G$1/(SUM($F$30:$F$46))) -> 88145.895
A32: 46266 | B32: =VLOOKUP(A32,'INCC - DI'!$E:$F,2,FALSE) -> 1270.695 | D32: =(C32*$C$3)*B32/$B$3 -> 0 | F32: 0.01633659 | G32: =F32*($C$3/$B$3*B32) -> 34263.323 | H32: =(F32*$G$1/(SUM($F$30:$F$46))) -> 36842.437
A33: 46296 | B33: =VLOOKUP(A33,'INCC - DI'!$E:$F,2,FALSE) -> 1270.695 | D33: =(C33*$C$3)*B33/$B$3 -> 0 | F33: 0.0020499421 | G33: =F33*($C$3/$B$3*B33) -> 4299.4179 | H33: =(F33*$G$1/(SUM($F$30:$F$46))) -> 4623.0494
A34: 46327 | B34: =VLOOKUP(A34,'INCC - DI'!$E:$F,2,FALSE) -> 1270.695 | D34: =(C34*$C$3)*B34/$B$3 -> 0 | F34: 0.0020499421 | G34: =F34*($C$3/$B$3*B34) -> 4299.4179 | H34: =(F34*$G$1/(SUM($F$30:$F$46))) -> 4623.0494
C35: =SUM(C5:C34) -> 0.88044899
C36: 0.88044899
C37: =C36-C35 -> 0

Sheet Amíz
A1: Amíz | F1: saldo | G1: =G3-D3 -> 2900498 | H1: =G3-I3 -> 2900498
A2: Data Base | B2: INCC Base | C2: Valor Orçado | D2: Valor da Taxa (Reaj) | G2: Valor Previsto Total | I2: Valor Cobrado
A3: 45444 | B3: =VLOOKUP(A3,'INCC - DI'!$E:$F,2,FALSE) -> 1110.887 | C3: =4387275.530048+K22 -> 4384297 | D3: =SUM(D5:D48) -> 2022858.9 | G3: =SUM(G5:G48) -> 4923356.9 | I3: =SUM(I5:I48) -> 2022858.9 | J3: =D3-I3 -> 0 | K3: Aditivos Incorporação | L3: Data | M3: Descrição
A4: Mês | B4: INCC DI (n-1) | C4: Medição | D4: Valor da Taxa (Reaj) | F4: Medição Prevista | G4: Valor Previsto | I4: Valor Cobrado | K4: -2978.52 | L4: 46124 | M4: DISTRATO REFERENTE AOS 32 MISTURADORES DA COZINHA
A5: 45597 | B5: =VLOOKUP(A5,'INCC - DI'!$E:$F,2,FALSE) -> 1149.17 | C5: 0.011380828 | D5: =(C5*$C$3)*B5/$B$3 -> 51616.459 | F5: 0.011380828 | G5: =F5*($C$3/$B$3*B5) -> 51616.459 | I5: 38437.81
A6: =EDATE(A5,1) -> 45627 | B6: =VLOOKUP(A6,'INCC - DI'!$E:$F,2,FALSE) -> 1153.725 | C6: 0.015123664 | D6: =(C6*$C$3)*B6/$B$3 -> 68863.55 | F6: 0.015123664 | G6: =F6*($C$3/$B$3*B6) -> 68863.55 | I6: 81848.039
A7: =EDATE(A6,1) -> 45658 | B7: =VLOOKUP(A7,'INCC - DI'!$E:$F,2,FALSE) -> 1159.536 | C7: 0.014536546 | D7: =(C7*$C$3)*B7/$B$3 -> 66523.569 | F7: 0.014536546 | G7: =F7*($C$3/$B$3*B7) -> 66523.569 | I7: 66335.944
A8: =EDATE(A7,1) -> 45689 | B8: =VLOOKUP(A8,'INCC - DI'!$E:$F,2,FALSE) -> 1169.116 | C8: 0.011429841 | D8: =(C8*$C$3)*B8/$B$3 -> 52738.512 | F8: 0.011429841 | G8: =F8*($C$3/$B$3*B8) -> 52738.512 | I8: 53208.476
A9: =EDATE(A8,1) -> 45717 | B9: =VLOOKUP(A9,'INCC - DI'!$E:$F,2,FALSE) -> 1173.775 | C9: 0.0090041098 | D9: =(C9*$C$3)*B9/$B$3 -> 41711.491 | F9: 0.0090041098 | G9: =F9*($C$3/$B$3*B9) -> 41711.491 | I9: 41726.833
A10: =EDATE(A9,1) -> 45748 | B10: =VLOOKUP(A10,'INCC - DI'!$E:$F,2,FALSE) -> 1178.386 | C10: 0.014780327 | D10: =(C10*$C$3)*B10/$B$3 -> 68738.763 | F10: 0.014780327 | G10: =F10*($C$3/$B$3*B10) -> 68738.763 | I10: 68494.973
A11: =EDATE(A10,1) -> 45778 | B11: =VLOOKUP(A11,'INCC - DI'!$E:$F,2,FALSE) -> 1184.462 | C11: 0.012970405 | D11: =(C11*$C$3)*B11/$B$3 -> 60632.401 | F11: 0.012970405 | G11: =F11*($C$3/$B$3*B11) -> 60632.401 | I11: 73417.827
A12: =EDATE(A11,1) -> 45809 | B12: =VLOOKUP(A12,'INCC - DI'!$E:$F,2,FALSE) -> 1191.327 | C12: 0.010041688 | D12: =(C12*$C$3)*B12/$B$3 -> 47213.672 | F12: 0.010275945 | G12: =F12*($C$3/$B$3*B12) -> 48315.094 | I12: 34736.985
A13: =EDATE(A12,1) -> 45839 | B13: =VLOOKUP(A13,'INCC - DI'!$E:$F,2,FALSE) -> 1199.509 | C13: 0.022967134 | D13: =(C13*$C$3)*B13/$B$3 -> 108727.75 | F13: 0.022967134 | G13: =F13*($C$3/$B$3*B13) -> 108727.75 | I13: 108767.74
A14: =EDATE(A13,1) -> 45870 | B14: =VLOOKUP(A14,'INCC - DI'!$E:$F,2,FALSE) -> 1210.471 | C14: 0.028324889 | D14: =(C14*$C$3)*B14/$B$3 -> 135317.1 | F14: 0.028324889 | G14: =F14*($C$3/$B$3*B14) -> 135317.1 | I14: 135366.87
A15: =EDATE(A14,1) -> 45901 | B15: =VLOOKUP(A15,'INCC - DI'!$E:$F,2,FALSE) -> 1216.706 | C15: 0.030828737 | D15: =(C15*$C$3)*B15/$B$3 -> 148037.41 | F15: 0.030828737 | G15: =F15*($C$3/$B$3*B15) -> 148037.41 | I15: 148091.86
A16: =EDATE(A15,1) -> 45931 | B16: =VLOOKUP(A16,'INCC - DI'!$E:$F,2,FALSE) -> 1218.747 | C16: 0.034398532 | D16: =(C16*$C$3)*B16/$B$3 -> 165456.39 | F16: 0.034398532 | G16: =F16*($C$3/$B$3*B16) -> 165456.39 | I16: 165517.25
A17: =EDATE(A16,1) -> 45962 | B17: =VLOOKUP(A17,'INCC - DI'!$E:$F,2,FALSE) -> 1222.356 | C17: 0.034189799 | D17: =(C17*$C$3)*B17/$B$3 -> 164939.38 | F17: 0.033955543 | G17: =F17*($C$3/$B$3*B17) -> 163809.27 | I17: 165000.04
... A21: =EDATE(A20,1) -> 46082 | B21: =VLOOKUP(A21,'INCC - DI'!$E:$F,2,FALSE) -> 1240.481 | C21: 0.02215241 | D21: =(C21*$C$3)*B21/$B$3 -> 108452.9 | F21: 0.022356243 | G21: =F21*($C$3/$B$3*B21) -> 109450.82 | I21: 108526.58
A22: =EDATE(A21,1) -> 46113 | B22: =VLOOKUP(A22,'INCC - DI'!$E:$F,2,FALSE) -> 1247.181 | C22: 0.023216832 | D22: =(C22*$C$3)*B22/$B$3 -> 114277.97 | F22: 0.023210595 | G22: =F22*($C$3/$B$3*B22) -> 114247.27 | I22: 114277.97 | K22: =SUM(K4:K21) -> -2978.52
A23: =EDATE(A22,1) -> 46143 | B23: =VLOOKUP(A23,'INCC - DI'!$E:$F,2,FALSE) -> 1259.652 | C23: 0.024085158 | D23: =(C23*$C$3)*B23/$B$3 -> 119737.49 | F23: 0.023550681 | G23: =F23*($C$3/$B$3*B23) -> 117080.38 | I23: 117414.45
A24: =EDATE(A23,1) -> 46174 | B24: =VLOOKUP(A24,'INCC - DI'!$E:$F,2,FALSE) -> 1270.695 | C24: 0.02279752 | D24: =(C24*$C$3)*B24/$B$3 -> 114329.69 | F24: 0.022938596 | G24: =F24*($C$3/$B$3*B24) -> 115037.18 | I24: 115515.13
A25: =EDATE(A24,1) -> 46204 | B25: =VLOOKUP(A25,'INCC - DI'!$E:$F,2,FALSE) -> 1270.695 | D25: =(C25*$C$3)*B25/$B$3 -> 0 | F25: 0.029805661 | G25: =F25*($C$3/$B$3*B25) -> 149475.55 | H25: =(F25*$G$1/(SUM($F$25:$F$48))) -> 149201.4
A26: =EDATE(A25,1) -> 46235 | B26: =VLOOKUP(A26,'INCC - DI'!$E:$F,2,FALSE) -> 1270.695 | D26: =(C26*$C$3)*B26/$B$3 -> 0 | F26: 0.029223208 | G26: =F26*($C$3/$B$3*B26) -> 146554.55 | H26: =(F26*$G$1/(SUM($F$25:$F$48))) -> 146285.75
A27: =EDATE(A26,1) -> 46266 | B27: =VLOOKUP(A27,'INCC - DI'!$E:$F,2,FALSE) -> 1270.695 | D27: =(C27*$C$3)*B27/$B$3 -> 0 | F27: 0.034226589 | G27: =F27*($C$3/$B$3*B27) -> 171646.53 | H27: =(F27*$G$1/(SUM($F$25:$F$48))) -> 171331.71
A28: =EDATE(A27,1) -> 46296 | B28: =VLOOKUP(A28,'INCC - DI'!$E:$F,2,FALSE) -> 1270.695 | D28: =(C28*$C$3)*B28/$B$3 -> 0 | F28: 0.037919847 | G28: =F28*($C$3/$B$3*B28) -> 190168.23 | H28: =(F28*$G$1/(SUM($F$25:$F$48))) -> 189819.44
A29: =EDATE(A28,1) -> 46327 | B29: =VLOOKUP(A29,'INCC - DI'!$E:$F,2,FALSE) -> 1270.695 | D29: =(C29*$C$3)*B29/$B$3 -> 0 | F29: 0.032884256 | G29: =F29*($C$3/$B$3*B29) -> 164914.72 | H29: =(F29*$G$1/(SUM($F$25:$F$48))) -> 164612.25
A30: =EDATE(A29,1) -> 46357 | B30: =VLOOKUP(A30,'INCC - DI'!$E:$F,2,FALSE) -> 1270.695 | D30: =(C30*$C$3)*B30/$B$3 -> 0 | F30: 0.017387386 | G30: =F30*($C$3/$B$3*B30) -> 87197.837 | H30: =(F30*$G$1/(SUM($F$25:$F$48))) -> 87037.906
A31: =EDATE(A30,1) -> 46388 | B31: =VLOOKUP(A31,'INCC - DI'!$E:$F,2,FALSE) -> 1270.695 | D31: =(C31*$C$3)*B31/$B$3 -> 0 | F31: 0.027509189 | G31: =F31*($C$3/$B$3*B31) -> 137958.73 | H31: =(F31*$G$1/(SUM($F$25:$F$48))) -> 137705.7
A32: =EDATE(A31,1) -> 46419 | B32: =VLOOKUP(A32,'INCC - DI'!$E:$F,2,FALSE) -> 1270.695 | D32: =(C32*$C$3)*B32/$B$3 -> 0 | F32: 0.033696962 | G32: =F32*($C$3/$B$3*B32) -> 168990.45 | H32: =(F32*$G$1/(SUM($F$25:$F$48))) -> 168680.5
A33: =EDATE(A32,1) -> 46447 | B33: =VLOOKUP(A33,'INCC - DI'!$E:$F,2,FALSE) -> 1270.695 | D33: =(C33*$C$3)*B33/$B$3 -> 0 | F33: 0.033557992 | G33: =F33*($C$3/$B$3*B33) -> 168293.51 | H33: =(F33*$G$1/(SUM($F$25:$F$48))) -> 167984.84
A34: =EDATE(A33,1) -> 46478 | B34: =VLOOKUP(A34,'INCC - DI'!$E:$F,2,FALSE) -> 1270.695 | D34: =(C34*$C$3)*B34/$B$3 -> 0 | F34: 0.055079113 | G34: =F34*($C$3/$B$3*B34) -> 276222.05 | H34: =(F34*$G$1/(SUM($F$25:$F$48))) -> 275715.43
A35: =EDATE(A34,1) -> 46508 | B35: =VLOOKUP(A35,'INCC - DI'!$E:$F,2,FALSE) -> 1270.695 | D35: =(C35*$C$3)*B35/$B$3 -> 0 | F35: 0.042880096 | G35: =F35*($C$3/$B$3*B35) -> 215043.91 | H35: =(F35*$G$1/(SUM($F$25:$F$48))) -> 214649.5
A36: =EDATE(A35,1) -> 46539 | B36: =VLOOKUP(A36,'INCC - DI'!$E:$F,2,FALSE) -> 1270.695 | D36: =(C36*$C$3)*B36/$B$3 -> 0 | F36: 0.060063165 | G36: =F36*($C$3/$B$3*B36) -> 301217.1 | H36: =(F36*$G$1/(SUM($F$25:$F$48))) -> 300664.63
... A48: =EDATE(A47,1) -> 46905 | B48: =VLOOKUP(A48,'INCC - DI'!$E:$F,2,FALSE) -> 1270.695 | D48: =(C48*$C$3)*B48/$B$3 -> 0 | F48: 0.0015 | G48: =F48*($C$3/$B$3*B48) -> 7522.5081 | H48: =(F48*$G$1/(SUM($F$25:$F$48))) -> 7508.7109
C49: =SUM(C5:C48) -> 0.4217
C50: 0.4217
C51: =C50-C49 -> 0

Sheet Poty
A1: Poty | F1: saldo | G1: =G3-D3 -> 3373721.1 | H1: =G3-I3 -> 3373721.1
A2: Data Base | B2: INCC Base | C2: Valor Orçado c/ Aditivos | D2: Valor da Taxa (Reaj) | G2: Valor Previsto Total | I2: Valor Cobrado
A3: 45413 | B3: =VLOOKUP(A3,'INCC - DI'!$E:$F,2,FALSE) -> 1101.389 | C3: 5840925.2 | D3: =SUM(D5:D45) -> 3203905.4 | G3: =SUM(G5:G45) -> 6577626.4 | I3: =SUM(I5:I45) -> 3203905.4 | J3: =D3-I3 -> 0 | K3: Aditivos Incorporação
A4: Mês | B4: INCC DI (n-1) | C4: Medição | D4: Valor da Taxa (Reaj) | F4: Medição Prevista | G4: Valor Previsto | I4: Valor Cobrado | K4: 17094.189
A5: 45474 | B5: =VLOOKUP(A5,'INCC - DI'!$E:$F,2,FALSE) -> 1118.827 | C5: 0.013032977 | D5: =(C5*$C$3)*B5/$B$3 -> 77329.905 | F5: 0.013032977 | G5: =F5*($C$3/$B$3*B5) -> 77329.905 | I5: 77343.145
A6: 45505 | B6: =VLOOKUP(A6,'INCC - DI'!$E:$F,2,FALSE) -> 1126.916 | C6: 0.015319593 | D6: =(C6*$C$3)*B6/$B$3 -> 91554.495 | F6: 0.015319593 | G6: =F6*($C$3/$B$3*B6) -> 91554.495 | I6: 91570.17
A7: 45536 | B7: =VLOOKUP(A7,'INCC - DI'!$E:$F,2,FALSE) -> 1134.775 | C7: 0.0098844824 | D7: =(C7*$C$3)*B7/$B$3 -> 59484.608 | F7: 0.0098844824 | G7: =F7*($C$3/$B$3*B7) -> 59484.608 | I7: 59494.792
A8: 45566 | B8: =VLOOKUP(A8,'INCC - DI'!$E:$F,2,FALSE) -> 1141.398 | C8: 0.013244555 | D8: =(C8*$C$3)*B8/$B$3 -> 80170.648 | F8: 0.013244878 | G8: =F8*($C$3/$B$3*B8) -> 80172.605 | I8: 80184.374
A9: 45597 | B9: =VLOOKUP(A9,'INCC - DI'!$E:$F,2,FALSE) -> 1149.17 | C9: 0.015527905 | D9: =(C9*$C$3)*B9/$B$3 -> 94632.009 | F9: 0.015527905 | G9: =F9*($C$3/$B$3*B9) -> 94632.009 | I9: 95096.189
A10: 45627 | B10: =VLOOKUP(A10,'INCC - DI'!$E:$F,2,FALSE) -> 1153.725 | C10: 0.0064818876 | D10: =(C10*$C$3)*B10/$B$3 -> 39659.27 | F10: 0.0064818876 | G10: =F10*($C$3/$B$3*B10) -> 39659.27 | I10: 43321.344
A11: 45658 | B11: =VLOOKUP(A11,'INCC - DI'!$E:$F,2,FALSE) -> 1159.536 | C11: 0.011316621 | D11: =(C11*$C$3)*B11/$B$3 -> 69589.214 | F11: 0.011316621 | G11: =F11*($C$3/$B$3*B11) -> 69589.214 | I11: 65453.892
A12: 45689 | B12: =VLOOKUP(A12,'INCC - DI'!$E:$F,2,FALSE) -> 1169.116 | C12: 0.017449319 | D12: =(C12*$C$3)*B12/$B$3 -> 108187.48 | F12: 0.017449219 | G12: =F12*($C$3/$B$3*B12) -> 108186.86 | I12: 108099.76
A13: 45717 | B13: =VLOOKUP(A13,'INCC - DI'!$E:$F,2,FALSE) -> 1173.775 | C13: 0.019519456 | D13: =(C13*$C$3)*B13/$B$3 -> 121504.81 | F13: 0.019519456 | G13: =F13*($C$3/$B$3*B13) -> 121504.81 | I13: 121504.81
A14: 45748 | B14: =VLOOKUP(A14,'INCC - DI'!$E:$F,2,FALSE) -> 1178.386 | C14: 0.021740683 | D14: =(C14*$C$3)*B14/$B$3 -> 135863.14 | F14: 0.021740683 | G14: =F14*($C$3/$B$3*B14) -> 135863.14 | I14: 135331.51
A15: 45778 | B15: =VLOOKUP(A15,'INCC - DI'!$E:$F,2,FALSE) -> 1184.462 | C15: 0.018877389 | D15: =(C15*$C$3)*B15/$B$3 -> 118577.96 | F15: 0.018877389 | G15: =F15*($C$3/$B$3*B15) -> 118577.96 | I15: 119109.59
A16: 45809 | B16: =VLOOKUP(A16,'INCC - DI'!$E:$F,2,FALSE) -> 1191.327 | C16: 0.017460095 | D16: =(C16*$C$3)*B16/$B$3 -> 110310.92 | F16: 0.017460095 | G16: =F16*($C$3/$B$3*B16) -> 110310.92 | I16: 110354.88
... A28: 46174 | B28: =VLOOKUP(A28,'INCC - DI'!$E:$F,2,FALSE) -> 1270.695 | C28: 0.0466934 | D28: =(C28*$C$3)*B28/$B$3 -> 314657.24 | F28: 0.041634208 | G28: =F28*($C$3/$B$3*B28) -> 280564.38 | I28: 317044.68
A29: 46204 | B29: =VLOOKUP(A29,'INCC - DI'!$E:$F,2,FALSE) -> 1270.695 | D29: =(C29*$C$3)*B29/$B$3 -> 0 | F29: 0.049093952 | G29: =F29*($C$3/$B$3*B29) -> 330834.07 | H29: =(F29*$G$1/(SUM($F$29:$F$46))) -> 340384.81
A30: 46235 | B30: =VLOOKUP(A30,'INCC - DI'!$E:$F,2,FALSE) -> 1270.695 | D30: =(C30*$C$3)*B30/$B$3 -> 0 | F30: 0.042424645 | G30: =F30*($C$3/$B$3*B30) -> 285890.98 | H30: =(F30*$G$1/(SUM($F$29:$F$46))) -> 294144.26
A31: 46266 | B31: =VLOOKUP(A31,'INCC - DI'!$E:$F,2,FALSE) -> 1270.695 | D31: =(C31*$C$3)*B31/$B$3 -> 0 | F31: 0.053209253 | G31: =F31*($C$3/$B$3*B31) -> 358566.24 | H31: =(F31*$G$1/(SUM($F$29:$F$46))) -> 368917.57
A32: 46296 | B32: =VLOOKUP(A32,'INCC - DI'!$E:$F,2,FALSE) -> 1270.695 | D32: =(C32*$C$3)*B32/$B$3 -> 0 | F32: 0.065214167 | G32: =F32*($C$3/$B$3*B32) -> 439464.89 | H32: =(F32*$G$1/(SUM($F$29:$F$46))) -> 452151.65
A33: 46327 | B33: =VLOOKUP(A33,'INCC - DI'!$E:$F,2,FALSE) -> 1270.695 | D33: =(C33*$C$3)*B33/$B$3 -> 0 | F33: 0.056950243 | G33: =F33*($C$3/$B$3*B33) -> 383776.01 | H33: =(F33*$G$1/(SUM($F$29:$F$46))) -> 394855.1
A34: 46357 | B34: =VLOOKUP(A34,'INCC - DI'!$E:$F,2,FALSE) -> 1270.695 | D34: =(C34*$C$3)*B34/$B$3 -> 0 | F34: 0.04010913 | G34: =F34*($C$3/$B$3*B34) -> 270287.2 | H34: =(F34*$G$1/(SUM($F$29:$F$46))) -> 278090.03
A35: 46388 | B35: =VLOOKUP(A35,'INCC - DI'!$E:$F,2,FALSE) -> 1270.695 | D35: =(C35*$C$3)*B35/$B$3 -> 0 | F35: 0.061220117 | G35: =F35*($C$3/$B$3*B35) -> 412549.81 | H35: =(F35*$G$1/(SUM($F$29:$F$46))) -> 424459.56
A36: 46419 | B36: =VLOOKUP(A36,'INCC - DI'!$E:$F,2,FALSE) -> 1270.695 | D36: =(C36*$C$3)*B36/$B$3 -> 0 | F36: 0.04859789 | G36: =F36*($C$3/$B$3*B36) -> 327491.21 | H36: =(F36*$G$1/(SUM($F$29:$F$46))) -> 336945.44
A37: 46447 | B37: =VLOOKUP(A37,'INCC - DI'!$E:$F,2,FALSE) -> 1270.695 | D37: =(C37*$C$3)*B37/$B$3 -> 0 | F37: 0.025858355 | G37: =F37*($C$3/$B$3*B37) -> 174254.15 | H37: =(F37*$G$1/(SUM($F$29:$F$46))) -> 179284.63
A38: 46478 | B38: =VLOOKUP(A38,'INCC - DI'!$E:$F,2,FALSE) -> 1270.695 | D38: =(C38*$C$3)*B38/$B$3 -> 0 | F38: 0.016471322 | G38: =F38*($C$3/$B$3*B38) -> 110996.86 | H38: =(F38*$G$1/(SUM($F$29:$F$46))) -> 114201.19
A39: 46508 | B39: =VLOOKUP(A39,'INCC - DI'!$E:$F,2,FALSE) -> 1270.695 | D39: =(C39*$C$3)*B39/$B$3 -> 0 | F39: 0.012132055 | G39: =F39*($C$3/$B$3*B39) -> 81755.428 | H39: =(F39*$G$1/(SUM($F$29:$F$46))) -> 84115.597
A40: 46539 | B40: =VLOOKUP(A40,'INCC - DI'!$E:$F,2,FALSE) -> 1270.695 | D40: =(C40*$C$3)*B40/$B$3 -> 0 | F40: 0.0069608481 | G40: =F40*($C$3/$B$3*B40) -> 46907.727 | H40: =(F40*$G$1/(SUM($F$29:$F$46))) -> 48261.89
... A45: 46692 | B45: =VLOOKUP(A45,'INCC - DI'!$E:$F,2,FALSE) -> 1270.695 | D45: =(C45*$C$3)*B45/$B$3 -> 0 | F45: 0.00051456484 | G45: =F45*($C$3/$B$3*B45) -> 3467.5469 | H45: =(F45*$G$1/(SUM($F$29:$F$46))) -> 3567.6503
C46: =SUM(C5:C45) -> 0.49906522
C47: 0.49906522
C48: =C47-C46 -> 0

Sheet Qoya
A1: Qoya
A2: Data Base | B2: INCC Base | D2: Valor da Taxa (Orç) | E2: Valor da Taxa (Reaj) | F2: Diferença
A3: 45170 | B3: 1078.412 | D3: =SUM(D7:D42) -> 5245908.3 | E3: =SUM(E7:E42) -> 5771767.4 | F3: =SUM(F7:F42) -> 525859.05
A4: Mês | B4: INCC | C4: INCC (Calc) | D4: Valor Base | E4: Valor Reajustado (Cobrado) | F4: Diferença
A5: 45352 | B5: =VLOOKUP(A5,'INCC - DI'!$A:$B,2,0) -> 1095.738
A6: 45383 | B6: =VLOOKUP(A6,'INCC - DI'!$A:$B,2,0) -> 1101.389
A7: 45413 | B7: =VLOOKUP(A7,'INCC - DI'!$A:$B,2,0) -> 1110.887 | C7: =B6 -> 1101.389 | D7: 40749.62 | E7: =D7 -> 40749.62 | F7: =E7-D7 -> 0
A8: 45444 | B8: =VLOOKUP(A8,'INCC - DI'!$A:$B,2,0) -> 1118.827 | C8: =B7 -> 1110.887 | D8: 62408.31 | E8: =D8*C8/$B$8 -> 61965.416 | F8: =E8-D8 -> -442.89419 | G8: Nova curva
A9: 45474 | B9: =VLOOKUP(A9,'INCC - DI'!$A:$B,2,0) -> 1126.916 | C9: =B8 -> 1118.827 | D9: 160279.44 | E9: =D9*C9/$B$8 -> 160279.44 | F9: =E9-D9 -> 0
A10: 45505 | B10: =VLOOKUP(A10,'INCC - DI'!$A:$B,2,0) -> 1134.775 | C10: =B9 -> 1126.916 | D10: 141857.8 | E10: =D10*C10/$B$8 -> 142883.42 | F10: =E10-D10 -> 1025.6168
A11: 45536 | B11: =VLOOKUP(A11,'INCC - DI'!$A:$B,2,0) -> 1141.398 | C11: =B10 -> 1134.775 | D11: 55955.58 | E11: =D11*C11/$B$8 -> 56753.183 | F11: =E11-D11 -> 797.60284
A12: 45566 | B12: =VLOOKUP(A12,'INCC - DI'!$A:$B,2,0) -> 1149.17 | C12: =B11 -> 1141.398 | D12: 38395.8 | E12: =D12*C12/$B$8 -> 39170.389 | F12: =E12-D12 -> 774.58946
A13: 45597 | B13: =VLOOKUP(A13,'INCC - DI'!$A:$B,2,0) -> 1153.725 | C13: =B12 -> 1149.17 | D13: 65574.31 | E13: =D13*C13/$B$8 -> 67352.709 | F13: =E13-D13 -> 1778.3994
A14: 45627 | B14: =VLOOKUP(A14,'INCC - DI'!$A:$B,2,0) -> 1159.536 | C14: =B13 -> 1153.725 | D14: 102291.57 | E14: =D14*C14/$B$8 -> 105482.21 | F14: =E14-D14 -> 3190.6373
A15: 45658 | B15: =VLOOKUP(A15,'INCC - DI'!$A:$B,2,0) -> 1169.116 | C15: =B14 -> 1159.536 | D15: 140682.99 | E15: =D15*C15/$B$8 -> 145801.8 | F15: =E15-D15 -> 5118.8109
A16: 45689 | B16: =VLOOKUP(A16,'INCC - DI'!$A:$B,2,0) -> 1173.775 | C16: =B15 -> 1169.116 | D16: 147575.79 | E16: =D16*C16/$B$8 -> 154209.02 | F16: =E16-D16 -> 6633.2319
A17: 45717 | B17: =VLOOKUP(A17,'INCC - DI'!$A:$B,2,0) -> 1178.386 | C17: =B16 -> 1173.775 | D17: 107920.65 | E17: =D17*C17/$B$8 -> 113220.87 | F17: =E17-D17 -> 5300.2152
A18: 45748 | B18: =VLOOKUP(A18,'INCC - DI'!$A:$B,2,0) -> 1184.462 | C18: =B17 -> 1178.386 | D18: 57327.63 | E18: =D18*C18/$B$8 -> 60379.376 | F18: =E18-D18 -> 3051.7464
A19: 45778 | B19: =VLOOKUP(A19,'INCC - DI'!$A:$B,2,0) -> 1191.327 | C19: =B18 -> 1184.462 | D19: 60057.52 | E19: =D19*C19/$B$8 -> 63580.741 | F19: =E19-D19 -> 3523.2215
A20: 45809 | B20: =VLOOKUP(A20,'INCC - DI'!$A:$B,2,0) -> 1199.509 | C20: =B19 -> 1191.327 | D20: 57327.63 | E20: =D20*C20/$B$8 -> 61042.461 | F20: =E20-D20 -> 3714.831
... A42: 46478 | B42: =VLOOKUP(A42,'INCC - DI'!$A:$B,2,0) -> 1270.695 | C42: =B41 -> 1270.695 | D42: 28086.91 | E42: =D42*C42/$B$8 -> 31899.388 | F42: =E42-D42 -> 3812.4776

Sheet Unna
A1: Unna | H1: OBS: - INCC MÊS ANTERIOR; - EMITE ND NO MÊS; - PAGAMENTO PRÓXIMO MÊS.
A2: Data Base | B2: INCC Base | D2: Valor da Taxa (Orç) | E2: Valor da Taxa (Reaj) | F2: Diferença
A3: 44774 | B3: =VLOOKUP(A3,'INCC - M'!$A:$F,2,FALSE) -> 1045.469 | D3: =SUM(D6:D39) -> 8946430.6 | E3: =SUM(E6:E39) -> 9991775.6 | F3: =SUM(F6:F39) -> 1045345
A4: Mês | B4: INCC | C4: INCC (Calc) | D4: Valor Base | E4: Valor Reajustado (Cobrado) | F4: Diferença
A5: 45017 | B5: =VLOOKUP(A5,'INCC - M'!$A:$F,2,FALSE) -> 1061.071
A6: 45047 | B6: =VLOOKUP(A6,'INCC - M'!$A:$F,2,FALSE) -> 1065.289 | C6: =B5 -> 1061.071 | D6: 118987.53 | E6: =D6*C6/$B$3 -> 120763.23 | F6: =E6-D6 -> 1775.7039
A7: 45078 | B7: =VLOOKUP(A7,'INCC - M'!$A:$F,2,FALSE) -> 1074.292 | C7: =B6 -> 1065.289 | D7: 94832.164 | E7: =D7*C7/$B$3 -> 96629.992 | F7: =E7-D7 -> 1797.828
A8: 45108 | B8: =VLOOKUP(A8,'INCC - M'!$A:$F,2,FALSE) -> 1074.895 | C8: =B7 -> 1074.292 | D8: 78728.589 | E8: =D8*C8/$B$3 -> 80899.093 | F8: =E8-D8 -> 2170.5035
A9: 45139 | B9: =VLOOKUP(A9,'INCC - M'!$A:$F,2,FALSE) -> 1077.497 | C9: =B8 -> 1074.895 | D9: 78728.589 | E9: =D9*C9/$B$3 -> 80944.501 | F9: =E9-D9 -> 2215.9122
A10: 45170 | B10: =VLOOKUP(A10,'INCC - M'!$A:$F,2,FALSE) -> 1080.071 | C10: =B9 -> 1077.497 | D10: 78728.589 | E10: =D10*C10/$B$3 -> 81140.444 | F10: =E10-D10 -> 2411.8546
A11: 45200 | B11: =VLOOKUP(A11,'INCC - M'!$A:$F,2,FALSE) -> 1082.251 | C11: =B10 -> 1080.071 | D11: 78728.589 | E11: =D11*C11/$B$3 -> 81334.278 | F11: =E11-D11 -> 2605.6886
A12: 45231 | B12: =VLOOKUP(A12,'INCC - M'!$A:$F,2,FALSE) -> 1083.335 | C12: =B11 -> 1082.251 | D12: 76939.303 | E12: =D12*C12/$B$3 -> 79646.204 | F12: =E12-D12 -> 2706.9013
A13: 45261 | B13: =VLOOKUP(A13,'INCC - M'!$A:$F,2,FALSE) -> 1086.15 | C13: =B12 -> 1083.335 | D13: 179823.25 | E13: =D13*C13/$B$3 -> 186336.3 | F13: =E13-D13 -> 6513.0457
